2022-11-24 06:44:09,168 INFO org.apache.hadoop.yarn.server.resourcemanager.ResourceManager: STARTUP_MSG: 
/************************************************************
STARTUP_MSG: Starting ResourceManager
STARTUP_MSG:   host = adh-hack-02-mnode1.ru-central1.internal/10.129.0.153
STARTUP_MSG:   args = []
STARTUP_MSG:   version = 3.1.2
STARTUP_MSG:   build = git@ssh.gitlab.adsw.io:arenadata/infrastructure/code/ci/prj_adh.git -r 15525ac41ebda8bc83c285e9b6ea7fb9921fd7fd; compiled by 'jenkins' on 2022-09-08T14:33Z
STARTUP_MSG:   java = 1.8.0_352
************************************************************/
2022-11-24 06:44:09,175 INFO org.apache.hadoop.yarn.server.resourcemanager.ResourceManager: registered UNIX signal handlers for [TERM, HUP, INT]
2022-11-24 06:44:09,327 INFO org.apache.hadoop.conf.Configuration: found resource core-site.xml at file:/etc/hadoop/conf/core-site.xml
2022-11-24 06:44:09,434 INFO org.apache.hadoop.conf.Configuration: resource-types.xml not found
2022-11-24 06:44:09,435 INFO org.apache.hadoop.yarn.util.resource.ResourceUtils: Unable to find 'resource-types.xml'.
2022-11-24 06:44:09,522 INFO org.apache.hadoop.conf.Configuration: found resource yarn-site.xml at file:/etc/hadoop/conf/yarn-site.xml
2022-11-24 06:44:09,562 INFO org.apache.hadoop.yarn.event.AsyncDispatcher: Registering class org.apache.hadoop.yarn.server.resourcemanager.RMFatalEventType for class org.apache.hadoop.yarn.server.resourcemanager.ResourceManager$RMFatalEventDispatcher
2022-11-24 06:44:09,594 INFO org.apache.hadoop.yarn.server.resourcemanager.security.NMTokenSecretManagerInRM: NMTokenKeyRollingInterval: 86400000ms and NMTokenKeyActivationDelay: 900000ms
2022-11-24 06:44:09,598 INFO org.apache.hadoop.yarn.server.resourcemanager.security.RMContainerTokenSecretManager: ContainerTokenKeyRollingInterval: 86400000ms and ContainerTokenKeyActivationDelay: 900000ms
2022-11-24 06:44:09,604 INFO org.apache.hadoop.yarn.server.resourcemanager.security.AMRMTokenSecretManager: AMRMTokenKeyRollingInterval: 86400000ms and AMRMTokenKeyActivationDelay: 900000 ms
2022-11-24 06:44:09,660 INFO org.apache.hadoop.yarn.server.resourcemanager.recovery.RMStateStoreFactory: Using RMStateStore implementation - class org.apache.hadoop.yarn.server.resourcemanager.recovery.LeveldbRMStateStore
2022-11-24 06:44:09,661 INFO org.apache.hadoop.yarn.event.AsyncDispatcher: Registering class org.apache.hadoop.yarn.server.resourcemanager.recovery.RMStateStoreEventType for class org.apache.hadoop.yarn.server.resourcemanager.recovery.RMStateStore$ForwardingEventHandler
2022-11-24 06:44:09,665 INFO org.apache.hadoop.yarn.event.AsyncDispatcher: Registering class org.apache.hadoop.yarn.server.resourcemanager.NodesListManagerEventType for class org.apache.hadoop.yarn.server.resourcemanager.NodesListManager
2022-11-24 06:44:09,665 INFO org.apache.hadoop.yarn.server.resourcemanager.ResourceManager: Using Scheduler: org.apache.hadoop.yarn.server.resourcemanager.scheduler.capacity.CapacityScheduler
2022-11-24 06:44:09,701 INFO org.apache.hadoop.yarn.event.AsyncDispatcher: Registering class org.apache.hadoop.yarn.server.resourcemanager.scheduler.event.SchedulerEventType for class org.apache.hadoop.yarn.event.EventDispatcher
2022-11-24 06:44:09,701 INFO org.apache.hadoop.yarn.event.AsyncDispatcher: Registering class org.apache.hadoop.yarn.server.resourcemanager.rmapp.RMAppEventType for class org.apache.hadoop.yarn.server.resourcemanager.ResourceManager$ApplicationEventDispatcher
2022-11-24 06:44:09,702 INFO org.apache.hadoop.yarn.event.AsyncDispatcher: Registering class org.apache.hadoop.yarn.server.resourcemanager.rmapp.attempt.RMAppAttemptEventType for class org.apache.hadoop.yarn.server.resourcemanager.ResourceManager$ApplicationAttemptEventDispatcher
2022-11-24 06:44:09,703 INFO org.apache.hadoop.yarn.event.AsyncDispatcher: Registering class org.apache.hadoop.yarn.server.resourcemanager.rmnode.RMNodeEventType for class org.apache.hadoop.yarn.server.resourcemanager.ResourceManager$NodeEventDispatcher
2022-11-24 06:44:09,804 WARN org.apache.hadoop.metrics2.impl.MetricsConfig: Cannot locate configuration: tried hadoop-metrics2-resourcemanager.properties,hadoop-metrics2.properties
2022-11-24 06:44:09,821 INFO org.apache.hadoop.metrics2.impl.MetricsSystemImpl: Scheduled Metric snapshot period at 10 second(s).
2022-11-24 06:44:09,821 INFO org.apache.hadoop.metrics2.impl.MetricsSystemImpl: ResourceManager metrics system started
2022-11-24 06:44:09,834 INFO org.apache.hadoop.yarn.security.YarnAuthorizationProvider: org.apache.hadoop.yarn.security.ConfiguredYarnAuthorizer is instantiated.
2022-11-24 06:44:09,837 INFO org.apache.hadoop.yarn.event.AsyncDispatcher: Registering class org.apache.hadoop.yarn.server.resourcemanager.RMAppManagerEventType for class org.apache.hadoop.yarn.server.resourcemanager.RMAppManager
2022-11-24 06:44:09,844 INFO org.apache.hadoop.yarn.event.AsyncDispatcher: Registering class org.apache.hadoop.yarn.server.resourcemanager.amlauncher.AMLauncherEventType for class org.apache.hadoop.yarn.server.resourcemanager.amlauncher.ApplicationMasterLauncher
2022-11-24 06:44:09,845 INFO org.apache.hadoop.yarn.server.resourcemanager.RMNMInfo: Registered RMNMInfo MBean
2022-11-24 06:44:09,846 INFO org.apache.hadoop.yarn.server.resourcemanager.rmapp.monitor.RMAppLifetimeMonitor: Application lifelime monitor interval set to 3000 ms.
2022-11-24 06:44:09,851 INFO org.apache.hadoop.util.HostsFileReader: Refreshing hosts (include/exclude) list
2022-11-24 06:44:09,851 INFO org.apache.hadoop.util.HostsFileReader: Adding a node "adh-hack-02-mnode1.ru-central1.internal" to the list of included hosts from /etc/hadoop/conf/include-path
2022-11-24 06:44:09,851 INFO org.apache.hadoop.util.HostsFileReader: Adding a node "adh-hack-02-mnode2.ru-central1.internal" to the list of included hosts from /etc/hadoop/conf/include-path
2022-11-24 06:44:09,851 INFO org.apache.hadoop.util.HostsFileReader: Adding a node "adh-hack-02-mnode3.ru-central1.internal" to the list of included hosts from /etc/hadoop/conf/include-path
2022-11-24 06:44:09,877 INFO org.apache.hadoop.conf.Configuration: found resource capacity-scheduler.xml at file:/etc/hadoop/conf/capacity-scheduler.xml
2022-11-24 06:44:09,891 INFO org.apache.hadoop.yarn.server.resourcemanager.scheduler.AbstractYarnScheduler: Minimum allocation = <memory:1024, vCores:1>
2022-11-24 06:44:09,891 INFO org.apache.hadoop.yarn.server.resourcemanager.scheduler.AbstractYarnScheduler: Maximum allocation = <memory:4096, vCores:2>
2022-11-24 06:44:09,928 INFO org.apache.hadoop.yarn.server.resourcemanager.scheduler.capacity.CapacitySchedulerConfiguration: max alloc mb per queue for root is undefined
2022-11-24 06:44:09,928 INFO org.apache.hadoop.yarn.server.resourcemanager.scheduler.capacity.CapacitySchedulerConfiguration: max alloc vcore per queue for root is undefined
2022-11-24 06:44:09,940 INFO org.apache.hadoop.yarn.server.resourcemanager.scheduler.capacity.ParentQueue: root, capacity=1.0, absoluteCapacity=1.0, maxCapacity=1.0, absoluteMaxCapacity=1.0, state=RUNNING, acls=ADMINISTER_QUEUE:*SUBMIT_APP:*, labels=*,
, reservationsContinueLooking=true, orderingPolicy=utilization, priority=0
2022-11-24 06:44:09,940 INFO org.apache.hadoop.yarn.server.resourcemanager.scheduler.capacity.ParentQueue: Initialized parent-queue root name=root, fullname=root
2022-11-24 06:44:09,954 INFO org.apache.hadoop.yarn.server.resourcemanager.scheduler.capacity.CapacitySchedulerConfiguration: max alloc mb per queue for root.default is undefined
2022-11-24 06:44:09,954 INFO org.apache.hadoop.yarn.server.resourcemanager.scheduler.capacity.CapacitySchedulerConfiguration: max alloc vcore per queue for root.default is undefined
2022-11-24 06:44:09,958 INFO org.apache.hadoop.yarn.server.resourcemanager.scheduler.capacity.LeafQueue: Initializing default
capacity = 1.0 [= (float) configuredCapacity / 100 ]
absoluteCapacity = 1.0 [= parentAbsoluteCapacity * capacity ]
maxCapacity = 1.0 [= configuredMaxCapacity ]
absoluteMaxCapacity = 1.0 [= 1.0 maximumCapacity undefined, (parentAbsoluteMaxCapacity * maximumCapacity) / 100 otherwise ]
effectiveMinResource=<memory:0, vCores:0>
 , effectiveMaxResource=<memory:0, vCores:0>
userLimit = 100 [= configuredUserLimit ]
userLimitFactor = 1.0 [= configuredUserLimitFactor ]
maxApplications = 10000 [= configuredMaximumSystemApplicationsPerQueue or (int)(configuredMaximumSystemApplications * absoluteCapacity)]
maxApplicationsPerUser = 10000 [= (int)(maxApplications * (userLimit / 100.0f) * userLimitFactor) ]
usedCapacity = 0.0 [= usedResourcesMemory / (clusterResourceMemory * absoluteCapacity)]
absoluteUsedCapacity = 0.0 [= usedResourcesMemory / clusterResourceMemory]
maxAMResourcePerQueuePercent = 0.2 [= configuredMaximumAMResourcePercent ]
minimumAllocationFactor = 0.75 [= (float)(maximumAllocationMemory - minimumAllocationMemory) / maximumAllocationMemory ]
maximumAllocation = <memory:4096, vCores:2> [= configuredMaxAllocation ]
numContainers = 0 [= currentNumContainers ]
state = RUNNING [= configuredState ]
acls = ADMINISTER_QUEUE:*SUBMIT_APP:* [= configuredAcls ]
nodeLocalityDelay = 40
rackLocalityAdditionalDelay = -1
labels=*,
reservationsContinueLooking = true
preemptionDisabled = true
defaultAppPriorityPerQueue = 0
priority = 0
maxLifetime = -1 seconds
defaultLifetime = -1 seconds
2022-11-24 06:44:09,958 INFO org.apache.hadoop.yarn.server.resourcemanager.scheduler.capacity.CapacitySchedulerQueueManager: Initialized queue: default: capacity=1.0, absoluteCapacity=1.0, usedResources=<memory:0, vCores:0>, usedCapacity=0.0, absoluteUsedCapacity=0.0, numApps=0, numContainers=0, effectiveMinResource=<memory:0, vCores:0> , effectiveMaxResource=<memory:0, vCores:0>
2022-11-24 06:44:09,958 INFO org.apache.hadoop.yarn.server.resourcemanager.scheduler.capacity.CapacitySchedulerQueueManager: Initialized queue: root: numChildQueue= 1, capacity=1.0, absoluteCapacity=1.0, usedResources=<memory:0, vCores:0>usedCapacity=0.0, numApps=0, numContainers=0
2022-11-24 06:44:09,960 INFO org.apache.hadoop.yarn.server.resourcemanager.scheduler.capacity.CapacitySchedulerQueueManager: Initialized root queue root: numChildQueue= 1, capacity=1.0, absoluteCapacity=1.0, usedResources=<memory:0, vCores:0>usedCapacity=0.0, numApps=0, numContainers=0
2022-11-24 06:44:09,960 INFO org.apache.hadoop.yarn.server.resourcemanager.placement.UserGroupMappingPlacementRule: Initialized queue mappings, override: false
2022-11-24 06:44:09,961 INFO org.apache.hadoop.yarn.server.resourcemanager.scheduler.capacity.CapacityScheduler: Initialized CapacityScheduler with calculator=class org.apache.hadoop.yarn.util.resource.DefaultResourceCalculator, minimumAllocation=<<memory:1024, vCores:1>>, maximumAllocation=<<memory:4096, vCores:2>>, asynchronousScheduling=false, asyncScheduleInterval=5ms
2022-11-24 06:44:09,964 INFO org.apache.hadoop.conf.Configuration: dynamic-resources.xml not found
2022-11-24 06:44:09,966 INFO org.apache.hadoop.yarn.server.resourcemanager.AMSProcessingChain: Initializing AMS Processing chain. Root Processor=[org.apache.hadoop.yarn.server.resourcemanager.DefaultAMSProcessor].
2022-11-24 06:44:09,966 INFO org.apache.hadoop.yarn.server.resourcemanager.ApplicationMasterService: disabled placement handler will be used, all scheduling requests will be rejected.
2022-11-24 06:44:09,969 INFO org.apache.hadoop.yarn.server.resourcemanager.AMSProcessingChain: Adding [org.apache.hadoop.yarn.server.resourcemanager.scheduler.constraint.processor.DisabledPlacementProcessor] tp top of AMS Processing chain. 
2022-11-24 06:44:10,162 INFO org.apache.hadoop.yarn.client.api.impl.TimelineClientImpl: Timeline service address: adh-hack-02-mnode2.ru-central1.internal:8188
2022-11-24 06:44:10,409 INFO org.apache.hadoop.yarn.event.AsyncDispatcher: Registering class org.apache.hadoop.yarn.server.resourcemanager.metrics.AbstractSystemMetricsPublisher$SystemMetricsEventType for class org.apache.hadoop.yarn.server.resourcemanager.metrics.TimelineServiceV1Publisher$TimelineV1EventHandler
2022-11-24 06:44:10,409 INFO org.apache.hadoop.yarn.event.AsyncDispatcher: Registering class org.apache.hadoop.yarn.server.resourcemanager.metrics.AbstractSystemMetricsPublisher$SystemMetricsEventType for class org.apache.hadoop.yarn.server.resourcemanager.metrics.TimelineServiceV1Publisher$TimelineV1EventHandler
2022-11-24 06:44:10,409 INFO org.apache.hadoop.yarn.event.AsyncDispatcher: Registering class org.apache.hadoop.yarn.server.resourcemanager.metrics.AbstractSystemMetricsPublisher$SystemMetricsEventType for class org.apache.hadoop.yarn.server.resourcemanager.metrics.TimelineServiceV1Publisher$TimelineV1EventHandler
2022-11-24 06:44:10,409 INFO org.apache.hadoop.yarn.event.AsyncDispatcher: Registering class org.apache.hadoop.yarn.server.resourcemanager.metrics.AbstractSystemMetricsPublisher$SystemMetricsEventType for class org.apache.hadoop.yarn.server.resourcemanager.metrics.TimelineServiceV1Publisher$TimelineV1EventHandler
2022-11-24 06:44:10,409 INFO org.apache.hadoop.yarn.event.AsyncDispatcher: Registering class org.apache.hadoop.yarn.server.resourcemanager.metrics.AbstractSystemMetricsPublisher$SystemMetricsEventType for class org.apache.hadoop.yarn.server.resourcemanager.metrics.TimelineServiceV1Publisher$TimelineV1EventHandler
2022-11-24 06:44:10,409 INFO org.apache.hadoop.yarn.event.AsyncDispatcher: Registering class org.apache.hadoop.yarn.server.resourcemanager.metrics.AbstractSystemMetricsPublisher$SystemMetricsEventType for class org.apache.hadoop.yarn.server.resourcemanager.metrics.TimelineServiceV1Publisher$TimelineV1EventHandler
2022-11-24 06:44:10,409 INFO org.apache.hadoop.yarn.event.AsyncDispatcher: Registering class org.apache.hadoop.yarn.server.resourcemanager.metrics.AbstractSystemMetricsPublisher$SystemMetricsEventType for class org.apache.hadoop.yarn.server.resourcemanager.metrics.TimelineServiceV1Publisher$TimelineV1EventHandler
2022-11-24 06:44:10,409 INFO org.apache.hadoop.yarn.event.AsyncDispatcher: Registering class org.apache.hadoop.yarn.server.resourcemanager.metrics.AbstractSystemMetricsPublisher$SystemMetricsEventType for class org.apache.hadoop.yarn.server.resourcemanager.metrics.TimelineServiceV1Publisher$TimelineV1EventHandler
2022-11-24 06:44:10,409 INFO org.apache.hadoop.yarn.event.AsyncDispatcher: Registering class org.apache.hadoop.yarn.server.resourcemanager.metrics.AbstractSystemMetricsPublisher$SystemMetricsEventType for class org.apache.hadoop.yarn.server.resourcemanager.metrics.TimelineServiceV1Publisher$TimelineV1EventHandler
2022-11-24 06:44:10,409 INFO org.apache.hadoop.yarn.event.AsyncDispatcher: Registering class org.apache.hadoop.yarn.server.resourcemanager.metrics.AbstractSystemMetricsPublisher$SystemMetricsEventType for class org.apache.hadoop.yarn.server.resourcemanager.metrics.TimelineServiceV1Publisher$TimelineV1EventHandler
2022-11-24 06:44:10,460 INFO org.eclipse.jetty.util.log: Logging initialized @1771ms
2022-11-24 06:44:10,508 INFO org.apache.hadoop.yarn.server.resourcemanager.ResourceManager: Using webapps at: file:/usr/lib/hadoop-yarn/webapps/ui2
2022-11-24 06:44:10,552 INFO org.apache.hadoop.security.authentication.server.AuthenticationFilter: Unable to initialize FileSignerSecretProvider, falling back to use random secrets.
2022-11-24 06:44:10,555 INFO org.apache.hadoop.http.HttpRequestLog: Http request log for http.requests.resourcemanager is not defined
2022-11-24 06:44:10,559 INFO org.apache.hadoop.http.HttpServer2: Added global filter 'safety' (class=org.apache.hadoop.http.HttpServer2$QuotingInputFilter)
2022-11-24 06:44:10,563 INFO org.apache.hadoop.http.HttpServer2: Added filter RMAuthenticationFilter (class=org.apache.hadoop.yarn.server.security.http.RMAuthenticationFilter) to context cluster
2022-11-24 06:44:10,563 INFO org.apache.hadoop.http.HttpServer2: Added filter RMAuthenticationFilter (class=org.apache.hadoop.yarn.server.security.http.RMAuthenticationFilter) to context logs
2022-11-24 06:44:10,563 INFO org.apache.hadoop.http.HttpServer2: Added filter RMAuthenticationFilter (class=org.apache.hadoop.yarn.server.security.http.RMAuthenticationFilter) to context static
2022-11-24 06:44:10,563 INFO org.apache.hadoop.http.HttpServer2: Added filter static_user_filter (class=org.apache.hadoop.http.lib.StaticUserWebFilter$StaticUserFilter) to context cluster
2022-11-24 06:44:10,563 INFO org.apache.hadoop.http.HttpServer2: Added filter static_user_filter (class=org.apache.hadoop.http.lib.StaticUserWebFilter$StaticUserFilter) to context logs
2022-11-24 06:44:10,563 INFO org.apache.hadoop.http.HttpServer2: Added filter static_user_filter (class=org.apache.hadoop.http.lib.StaticUserWebFilter$StaticUserFilter) to context static
2022-11-24 06:44:10,566 INFO org.apache.hadoop.http.HttpServer2: adding path spec: /cluster/*
2022-11-24 06:44:10,566 INFO org.apache.hadoop.http.HttpServer2: adding path spec: /ws/*
2022-11-24 06:44:10,566 INFO org.apache.hadoop.http.HttpServer2: adding path spec: /app/*
2022-11-24 06:44:10,968 INFO org.apache.hadoop.yarn.webapp.WebApps: Registered webapp guice modules
2022-11-24 06:44:10,975 INFO org.apache.hadoop.http.HttpServer2: Jetty bound to port 8088
2022-11-24 06:44:10,977 INFO org.eclipse.jetty.server.Server: jetty-9.3.24.v20180605, build timestamp: 2018-06-05T17:11:56Z, git hash: 84205aa28f11a4f31f2a3b86d1bba2cc8ab69827
2022-11-24 06:44:11,008 INFO org.apache.hadoop.security.authentication.server.AuthenticationFilter: Unable to initialize FileSignerSecretProvider, falling back to use random secrets.
2022-11-24 06:44:11,018 INFO org.apache.hadoop.security.token.delegation.AbstractDelegationTokenSecretManager: Updating the current master key for generating delegation tokens
2022-11-24 06:44:11,020 INFO org.apache.hadoop.security.token.delegation.AbstractDelegationTokenSecretManager: Starting expired delegation token remover thread, tokenRemoverScanInterval=60 min(s)
2022-11-24 06:44:11,020 INFO org.apache.hadoop.security.token.delegation.AbstractDelegationTokenSecretManager: Updating the current master key for generating delegation tokens
2022-11-24 06:44:11,022 INFO org.eclipse.jetty.server.handler.ContextHandler: Started o.e.j.s.ServletContextHandler@61526469{/logs,file:///var/log/hadoop-yarn/,AVAILABLE}
2022-11-24 06:44:11,022 INFO org.eclipse.jetty.server.handler.ContextHandler: Started o.e.j.s.ServletContextHandler@7c351808{/static,jar:file:/usr/lib/hadoop-yarn/hadoop-yarn-common-3.1.2.jar!/webapps/static,AVAILABLE}
2022-11-24 06:44:11,872 INFO org.eclipse.jetty.server.handler.ContextHandler: Started o.e.j.w.WebAppContext@16c587de{/,file:///var/tmp/jetty-0.0.0.0-8088-cluster-_-any-4095242372116986703.dir/webapp/,AVAILABLE}{/cluster}
2022-11-24 06:44:11,908 INFO org.eclipse.jetty.webapp.StandardDescriptorProcessor: NO JSP Support for /ui2, did not find org.eclipse.jetty.jsp.JettyJspServlet
2022-11-24 06:44:11,915 INFO org.eclipse.jetty.server.handler.ContextHandler: Started o.e.j.w.WebAppContext@3b1ed14b{/ui2,file:///usr/lib/hadoop-yarn/webapps/ui2/,AVAILABLE}
2022-11-24 06:44:11,919 INFO org.eclipse.jetty.server.AbstractConnector: Started ServerConnector@13741d5a{HTTP/1.1,[http/1.1]}{0.0.0.0:8088}
2022-11-24 06:44:11,919 INFO org.eclipse.jetty.server.Server: Started @3232ms
2022-11-24 06:44:11,920 INFO org.apache.hadoop.yarn.webapp.WebApps: Web app cluster started at 8088
2022-11-24 06:44:12,057 INFO org.apache.hadoop.ipc.CallQueueManager: Using callQueue: class java.util.concurrent.LinkedBlockingQueue queueCapacity: 100 scheduler: class org.apache.hadoop.ipc.DefaultRpcScheduler
2022-11-24 06:44:12,064 INFO org.apache.hadoop.ipc.Server: Starting Socket Reader #1 for port 8033
2022-11-24 06:44:12,086 INFO org.apache.hadoop.yarn.factories.impl.pb.RpcServerFactoryPBImpl: Adding protocol org.apache.hadoop.yarn.server.api.ResourceManagerAdministrationProtocolPB to the server
2022-11-24 06:44:12,086 INFO org.apache.hadoop.ipc.Server: IPC Server Responder: starting
2022-11-24 06:44:12,087 INFO org.apache.hadoop.ipc.Server: IPC Server listener on 8033: starting
2022-11-24 06:44:12,090 INFO org.apache.hadoop.yarn.server.resourcemanager.ResourceManager: Transitioning to active state
2022-11-24 06:44:12,174 INFO org.apache.hadoop.yarn.server.resourcemanager.recovery.LeveldbRMStateStore: Using state database at /srv/hadoop-yarn/leveldb-state-store/yarn-rm-state for recovery
2022-11-24 06:44:12,192 INFO org.apache.hadoop.yarn.server.resourcemanager.recovery.LeveldbRMStateStore: Creating state database at /srv/hadoop-yarn/leveldb-state-store/yarn-rm-state
2022-11-24 06:44:12,209 INFO org.apache.hadoop.yarn.server.resourcemanager.ResourceManager: Recovery started
2022-11-24 06:44:12,211 INFO org.apache.hadoop.yarn.server.resourcemanager.recovery.RMStateStore: Loaded RM state version info 1.1
2022-11-24 06:44:12,217 INFO org.apache.hadoop.yarn.server.resourcemanager.recovery.LeveldbRMStateStore: Recovered 0 RM delegation token master keys
2022-11-24 06:44:12,218 INFO org.apache.hadoop.yarn.server.resourcemanager.recovery.LeveldbRMStateStore: Recovered 0 RM delegation tokens
2022-11-24 06:44:12,218 INFO org.apache.hadoop.yarn.server.resourcemanager.recovery.LeveldbRMStateStore: Recovered 0 applications and 0 application attempts
2022-11-24 06:44:12,218 INFO org.apache.hadoop.yarn.server.resourcemanager.recovery.LeveldbRMStateStore: Recovered 0 reservations
2022-11-24 06:44:12,218 INFO org.apache.hadoop.yarn.server.resourcemanager.security.RMDelegationTokenSecretManager: recovering RMDelegationTokenSecretManager.
2022-11-24 06:44:12,218 INFO org.apache.hadoop.yarn.server.resourcemanager.RMAppManager: Recovering 0 applications
2022-11-24 06:44:12,218 INFO org.apache.hadoop.yarn.server.resourcemanager.RMAppManager: Successfully recovered 0 out of 0 applications
2022-11-24 06:44:12,218 INFO org.apache.hadoop.yarn.server.resourcemanager.ResourceManager: Recovery ended
2022-11-24 06:44:12,228 INFO org.apache.hadoop.yarn.server.resourcemanager.recovery.RMStateStore: Updating AMRMToken
2022-11-24 06:44:12,228 INFO org.apache.hadoop.yarn.server.resourcemanager.security.RMContainerTokenSecretManager: Rolling master-key for container-tokens
2022-11-24 06:44:12,228 INFO org.apache.hadoop.yarn.server.resourcemanager.security.NMTokenSecretManagerInRM: Rolling master-key for nm-tokens
2022-11-24 06:44:12,228 INFO org.apache.hadoop.security.token.delegation.AbstractDelegationTokenSecretManager: Updating the current master key for generating delegation tokens
2022-11-24 06:44:12,228 INFO org.apache.hadoop.yarn.server.resourcemanager.security.RMDelegationTokenSecretManager: storing master key with keyID 1
2022-11-24 06:44:12,228 INFO org.apache.hadoop.yarn.server.resourcemanager.recovery.RMStateStore: Storing RMDTMasterKey.
2022-11-24 06:44:12,230 INFO org.apache.hadoop.security.token.delegation.AbstractDelegationTokenSecretManager: Starting expired delegation token remover thread, tokenRemoverScanInterval=60 min(s)
2022-11-24 06:44:12,230 INFO org.apache.hadoop.security.token.delegation.AbstractDelegationTokenSecretManager: Updating the current master key for generating delegation tokens
2022-11-24 06:44:12,230 INFO org.apache.hadoop.yarn.server.resourcemanager.security.RMDelegationTokenSecretManager: storing master key with keyID 2
2022-11-24 06:44:12,230 INFO org.apache.hadoop.yarn.server.resourcemanager.recovery.RMStateStore: Storing RMDTMasterKey.
2022-11-24 06:44:12,821 INFO org.apache.hadoop.yarn.nodelabels.FileSystemNodeLabelsStore: Finished write mirror at:hdfs:/system/yarn/node-labels/nodelabel.mirror
2022-11-24 06:44:12,821 INFO org.apache.hadoop.yarn.nodelabels.FileSystemNodeLabelsStore: Finished create editlog file at:hdfs:/system/yarn/node-labels/nodelabel.editlog
2022-11-24 06:44:12,822 INFO org.apache.hadoop.yarn.event.AsyncDispatcher: Registering class org.apache.hadoop.yarn.nodelabels.event.NodeLabelsStoreEventType for class org.apache.hadoop.yarn.nodelabels.CommonNodeLabelsManager$ForwardingEventHandler
2022-11-24 06:44:12,834 INFO org.apache.hadoop.ipc.CallQueueManager: Using callQueue: class java.util.concurrent.LinkedBlockingQueue queueCapacity: 5000 scheduler: class org.apache.hadoop.ipc.DefaultRpcScheduler
2022-11-24 06:44:12,835 INFO org.apache.hadoop.ipc.Server: Starting Socket Reader #1 for port 8031
2022-11-24 06:44:12,837 INFO org.apache.hadoop.yarn.factories.impl.pb.RpcServerFactoryPBImpl: Adding protocol org.apache.hadoop.yarn.server.api.ResourceTrackerPB to the server
2022-11-24 06:44:12,838 INFO org.apache.hadoop.ipc.Server: IPC Server Responder: starting
2022-11-24 06:44:12,838 INFO org.apache.hadoop.ipc.Server: IPC Server listener on 8031: starting
2022-11-24 06:44:12,850 INFO org.apache.hadoop.util.JvmPauseMonitor: Starting JVM pause monitor
2022-11-24 06:44:12,860 INFO org.apache.hadoop.ipc.CallQueueManager: Using callQueue: class java.util.concurrent.LinkedBlockingQueue queueCapacity: 5000 scheduler: class org.apache.hadoop.ipc.DefaultRpcScheduler
2022-11-24 06:44:12,867 INFO org.apache.hadoop.ipc.Server: Starting Socket Reader #1 for port 8030
2022-11-24 06:44:12,871 INFO org.apache.hadoop.yarn.factories.impl.pb.RpcServerFactoryPBImpl: Adding protocol org.apache.hadoop.yarn.api.ApplicationMasterProtocolPB to the server
2022-11-24 06:44:12,873 INFO org.apache.hadoop.ipc.Server: IPC Server Responder: starting
2022-11-24 06:44:12,874 INFO org.apache.hadoop.ipc.Server: IPC Server listener on 8030: starting
2022-11-24 06:44:13,004 INFO org.apache.hadoop.ipc.CallQueueManager: Using callQueue: class java.util.concurrent.LinkedBlockingQueue queueCapacity: 5000 scheduler: class org.apache.hadoop.ipc.DefaultRpcScheduler
2022-11-24 06:44:13,004 INFO org.apache.hadoop.ipc.Server: Starting Socket Reader #1 for port 8032
2022-11-24 06:44:13,007 INFO org.apache.hadoop.yarn.factories.impl.pb.RpcServerFactoryPBImpl: Adding protocol org.apache.hadoop.yarn.api.ApplicationClientProtocolPB to the server
2022-11-24 06:44:13,007 INFO org.apache.hadoop.ipc.Server: IPC Server Responder: starting
2022-11-24 06:44:13,007 INFO org.apache.hadoop.ipc.Server: IPC Server listener on 8032: starting
2022-11-24 06:44:13,014 INFO org.apache.hadoop.yarn.server.resourcemanager.ResourceManager: Transitioned to active state
2022-11-24 06:44:46,931 INFO org.apache.hadoop.yarn.server.resourcemanager.ResourceTrackerService: NodeManager from node adh-hack-02-mnode2.ru-central1.internal(cmPort: 8041 httpPort: 8042) registered with capability: <memory:7057, vCores:2>, assigned nodeId adh-hack-02-mnode2.ru-central1.internal:8041
2022-11-24 06:44:46,936 INFO org.apache.hadoop.yarn.server.resourcemanager.rmnode.RMNodeImpl: adh-hack-02-mnode2.ru-central1.internal:8041 Node Transitioned from NEW to RUNNING
2022-11-24 06:44:46,959 INFO org.apache.hadoop.yarn.server.resourcemanager.ResourceTrackerService: NodeManager from node adh-hack-02-mnode1.ru-central1.internal(cmPort: 8041 httpPort: 8042) registered with capability: <memory:7057, vCores:2>, assigned nodeId adh-hack-02-mnode1.ru-central1.internal:8041
2022-11-24 06:44:46,959 INFO org.apache.hadoop.yarn.server.resourcemanager.rmnode.RMNodeImpl: adh-hack-02-mnode1.ru-central1.internal:8041 Node Transitioned from NEW to RUNNING
2022-11-24 06:44:46,962 INFO org.apache.hadoop.yarn.server.resourcemanager.scheduler.capacity.CapacityScheduler: Added node adh-hack-02-mnode2.ru-central1.internal:8041 clusterResource: <memory:7057, vCores:2>
2022-11-24 06:44:46,966 INFO org.apache.hadoop.yarn.server.resourcemanager.scheduler.capacity.CapacityScheduler: Added node adh-hack-02-mnode1.ru-central1.internal:8041 clusterResource: <memory:14114, vCores:4>
2022-11-24 06:44:47,013 INFO org.apache.hadoop.yarn.server.resourcemanager.RMActiveServiceContext: Scheduler recovery is done. Start allocating new containers.
2022-11-24 06:44:47,040 INFO org.apache.hadoop.yarn.server.resourcemanager.ResourceTrackerService: NodeManager from node adh-hack-02-mnode3.ru-central1.internal(cmPort: 8041 httpPort: 8042) registered with capability: <memory:7057, vCores:2>, assigned nodeId adh-hack-02-mnode3.ru-central1.internal:8041
2022-11-24 06:44:47,040 INFO org.apache.hadoop.yarn.server.resourcemanager.rmnode.RMNodeImpl: adh-hack-02-mnode3.ru-central1.internal:8041 Node Transitioned from NEW to RUNNING
2022-11-24 06:44:47,042 INFO org.apache.hadoop.yarn.server.resourcemanager.scheduler.capacity.CapacityScheduler: Added node adh-hack-02-mnode3.ru-central1.internal:8041 clusterResource: <memory:21171, vCores:6>
2022-11-24 06:47:44,851 INFO org.apache.hadoop.yarn.server.resourcemanager.ClientRMService: Allocated new applicationId: 1
2022-11-24 06:47:45,733 INFO org.apache.hadoop.yarn.server.resourcemanager.scheduler.capacity.CapacityScheduler: Application 'application_1669272252091_0001' is submitted without priority hence considering default queue/cluster priority: 0
2022-11-24 06:47:45,733 INFO org.apache.hadoop.yarn.server.resourcemanager.scheduler.capacity.CapacityScheduler: Priority '0' is acceptable in queue : default for application: application_1669272252091_0001
2022-11-24 06:47:45,752 INFO org.apache.hadoop.yarn.server.resourcemanager.ClientRMService: Application with id 1 submitted by user yarn
2022-11-24 06:47:45,752 INFO org.apache.hadoop.yarn.server.resourcemanager.rmapp.RMAppImpl: Storing application with id application_1669272252091_0001
2022-11-24 06:47:45,754 INFO org.apache.hadoop.yarn.server.resourcemanager.RMAuditLogger: USER=yarn	IP=10.129.0.153	OPERATION=Submit Application Request	TARGET=ClientRMService	RESULT=SUCCESS	APPID=application_1669272252091_0001	CALLERCONTEXT=CLI	QUEUENAME=default
2022-11-24 06:47:45,762 INFO org.apache.hadoop.yarn.server.resourcemanager.recovery.RMStateStore: Storing info for app: application_1669272252091_0001
2022-11-24 06:47:45,762 INFO org.apache.hadoop.yarn.server.resourcemanager.rmapp.RMAppImpl: application_1669272252091_0001 State change from NEW to NEW_SAVING on event = START
2022-11-24 06:47:45,812 INFO org.apache.hadoop.yarn.server.resourcemanager.rmapp.RMAppImpl: application_1669272252091_0001 State change from NEW_SAVING to SUBMITTED on event = APP_NEW_SAVED
2022-11-24 06:47:45,821 INFO org.apache.hadoop.yarn.server.resourcemanager.scheduler.capacity.ParentQueue: Application added - appId: application_1669272252091_0001 user: yarn leaf-queue of parent: root #applications: 1
2022-11-24 06:47:45,822 INFO org.apache.hadoop.yarn.server.resourcemanager.scheduler.capacity.CapacityScheduler: Accepted application application_1669272252091_0001 from user: yarn, in queue: default
2022-11-24 06:47:45,835 INFO org.apache.hadoop.yarn.server.resourcemanager.rmapp.RMAppImpl: application_1669272252091_0001 State change from SUBMITTED to ACCEPTED on event = APP_ACCEPTED
2022-11-24 06:47:45,866 INFO org.apache.hadoop.yarn.server.resourcemanager.ApplicationMasterService: Registering app attempt : appattempt_1669272252091_0001_000001
2022-11-24 06:47:45,867 INFO org.apache.hadoop.yarn.server.resourcemanager.rmapp.attempt.RMAppAttemptImpl: appattempt_1669272252091_0001_000001 State change from NEW to SUBMITTED on event = START
2022-11-24 06:47:45,886 INFO org.apache.hadoop.yarn.server.resourcemanager.scheduler.capacity.LeafQueue: Application application_1669272252091_0001 from user: yarn activated in queue: default
2022-11-24 06:47:45,886 INFO org.apache.hadoop.yarn.server.resourcemanager.scheduler.capacity.LeafQueue: Application added - appId: application_1669272252091_0001 user: yarn, leaf-queue: default #user-pending-applications: 0 #user-active-applications: 1 #queue-pending-applications: 0 #queue-active-applications: 1
2022-11-24 06:47:45,886 INFO org.apache.hadoop.yarn.server.resourcemanager.scheduler.capacity.CapacityScheduler: Added Application Attempt appattempt_1669272252091_0001_000001 to scheduler from user yarn in queue default
2022-11-24 06:47:45,894 INFO org.apache.hadoop.yarn.server.resourcemanager.rmapp.attempt.RMAppAttemptImpl: appattempt_1669272252091_0001_000001 State change from SUBMITTED to SCHEDULED on event = ATTEMPT_ADDED
2022-11-24 06:47:46,405 INFO org.apache.hadoop.yarn.server.resourcemanager.scheduler.capacity.allocator.AbstractContainerAllocator: assignedContainer application attempt=appattempt_1669272252091_0001_000001 container=null queue=default clusterResource=<memory:21171, vCores:6> type=OFF_SWITCH requestedPartition=
2022-11-24 06:47:46,409 INFO org.apache.hadoop.yarn.server.resourcemanager.rmcontainer.RMContainerImpl: container_1669272252091_0001_01_000001 Container Transitioned from NEW to ALLOCATED
2022-11-24 06:47:46,409 INFO org.apache.hadoop.yarn.server.resourcemanager.scheduler.common.fica.FiCaSchedulerNode: Assigned container container_1669272252091_0001_01_000001 of capacity <memory:2048, vCores:1> on host adh-hack-02-mnode1.ru-central1.internal:8041, which has 1 containers, <memory:2048, vCores:1> used and <memory:5009, vCores:1> available after allocation
2022-11-24 06:47:46,410 INFO org.apache.hadoop.yarn.server.resourcemanager.RMAuditLogger: USER=yarn	OPERATION=AM Allocated Container	TARGET=SchedulerApp	RESULT=SUCCESS	APPID=application_1669272252091_0001	CONTAINERID=container_1669272252091_0001_01_000001	RESOURCE=<memory:2048, vCores:1>	QUEUENAME=default
2022-11-24 06:47:46,433 INFO org.apache.hadoop.yarn.server.resourcemanager.security.NMTokenSecretManagerInRM: Sending NMToken for nodeId : adh-hack-02-mnode1.ru-central1.internal:8041 for container : container_1669272252091_0001_01_000001
2022-11-24 06:47:46,441 INFO org.apache.hadoop.yarn.server.resourcemanager.rmcontainer.RMContainerImpl: container_1669272252091_0001_01_000001 Container Transitioned from ALLOCATED to ACQUIRED
2022-11-24 06:47:46,442 INFO org.apache.hadoop.yarn.server.resourcemanager.security.NMTokenSecretManagerInRM: Clear node set for appattempt_1669272252091_0001_000001
2022-11-24 06:47:46,442 INFO org.apache.hadoop.yarn.server.resourcemanager.rmapp.attempt.RMAppAttemptImpl: Storing attempt: AppId: application_1669272252091_0001 AttemptId: appattempt_1669272252091_0001_000001 MasterContainer: Container: [ContainerId: container_1669272252091_0001_01_000001, AllocationRequestId: -1, Version: 0, NodeId: adh-hack-02-mnode1.ru-central1.internal:8041, NodeHttpAddress: adh-hack-02-mnode1.ru-central1.internal:8042, Resource: <memory:2048, vCores:1>, Priority: 0, Token: Token { kind: ContainerToken, service: 10.129.0.153:8041 }, ExecutionType: GUARANTEED, ]
2022-11-24 06:47:46,442 INFO org.apache.hadoop.yarn.server.resourcemanager.scheduler.capacity.ParentQueue: assignedContainer queue=root usedCapacity=0.0967361 absoluteUsedCapacity=0.0967361 used=<memory:2048, vCores:1> cluster=<memory:21171, vCores:6>
2022-11-24 06:47:46,442 INFO org.apache.hadoop.yarn.server.resourcemanager.scheduler.capacity.CapacityScheduler: Allocation proposal accepted
2022-11-24 06:47:46,451 INFO org.apache.hadoop.yarn.server.resourcemanager.rmapp.attempt.RMAppAttemptImpl: appattempt_1669272252091_0001_000001 State change from SCHEDULED to ALLOCATED_SAVING on event = CONTAINER_ALLOCATED
2022-11-24 06:47:46,458 INFO org.apache.hadoop.yarn.server.resourcemanager.rmapp.attempt.RMAppAttemptImpl: appattempt_1669272252091_0001_000001 State change from ALLOCATED_SAVING to ALLOCATED on event = ATTEMPT_NEW_SAVED
2022-11-24 06:47:46,462 INFO org.apache.hadoop.yarn.server.resourcemanager.amlauncher.AMLauncher: Launching masterappattempt_1669272252091_0001_000001
2022-11-24 06:47:46,672 INFO org.apache.hadoop.yarn.server.resourcemanager.amlauncher.AMLauncher: Setting up container Container: [ContainerId: container_1669272252091_0001_01_000001, AllocationRequestId: -1, Version: 0, NodeId: adh-hack-02-mnode1.ru-central1.internal:8041, NodeHttpAddress: adh-hack-02-mnode1.ru-central1.internal:8042, Resource: <memory:2048, vCores:1>, Priority: 0, Token: Token { kind: ContainerToken, service: 10.129.0.153:8041 }, ExecutionType: GUARANTEED, ] for AM appattempt_1669272252091_0001_000001
2022-11-24 06:47:46,673 INFO org.apache.hadoop.yarn.server.resourcemanager.security.AMRMTokenSecretManager: Create AMRMToken for ApplicationAttempt: appattempt_1669272252091_0001_000001
2022-11-24 06:47:46,676 INFO org.apache.hadoop.yarn.server.resourcemanager.security.AMRMTokenSecretManager: Creating password for appattempt_1669272252091_0001_000001
2022-11-24 06:47:46,954 INFO org.apache.hadoop.yarn.server.resourcemanager.amlauncher.AMLauncher: Done launching container Container: [ContainerId: container_1669272252091_0001_01_000001, AllocationRequestId: -1, Version: 0, NodeId: adh-hack-02-mnode1.ru-central1.internal:8041, NodeHttpAddress: adh-hack-02-mnode1.ru-central1.internal:8042, Resource: <memory:2048, vCores:1>, Priority: 0, Token: Token { kind: ContainerToken, service: 10.129.0.153:8041 }, ExecutionType: GUARANTEED, ] for AM appattempt_1669272252091_0001_000001
2022-11-24 06:47:46,954 INFO org.apache.hadoop.yarn.server.resourcemanager.rmapp.attempt.RMAppAttemptImpl: appattempt_1669272252091_0001_000001 State change from ALLOCATED to LAUNCHED on event = LAUNCHED
2022-11-24 06:47:47,407 INFO org.apache.hadoop.yarn.server.resourcemanager.rmcontainer.RMContainerImpl: container_1669272252091_0001_01_000001 Container Transitioned from ACQUIRED to RUNNING
2022-11-24 06:47:51,844 INFO SecurityLogger.org.apache.hadoop.ipc.Server: Auth successful for appattempt_1669272252091_0001_000001 (auth:SIMPLE)
2022-11-24 06:47:51,864 INFO org.apache.hadoop.yarn.server.resourcemanager.DefaultAMSProcessor: AM registration appattempt_1669272252091_0001_000001
2022-11-24 06:47:51,865 INFO org.apache.hadoop.yarn.server.resourcemanager.RMAuditLogger: USER=yarn	IP=10.129.0.153	OPERATION=Register App Master	TARGET=ApplicationMasterService	RESULT=SUCCESS	APPID=application_1669272252091_0001	APPATTEMPTID=appattempt_1669272252091_0001_000001
2022-11-24 06:47:51,865 INFO org.apache.hadoop.yarn.server.resourcemanager.rmapp.attempt.RMAppAttemptImpl: appattempt_1669272252091_0001_000001 State change from LAUNCHED to RUNNING on event = REGISTERED
2022-11-24 06:47:51,865 INFO org.apache.hadoop.yarn.server.resourcemanager.rmapp.RMAppImpl: application_1669272252091_0001 State change from ACCEPTED to RUNNING on event = ATTEMPT_REGISTERED
2022-11-24 06:47:53,424 INFO org.apache.hadoop.yarn.server.resourcemanager.scheduler.capacity.allocator.AbstractContainerAllocator: assignedContainer application attempt=appattempt_1669272252091_0001_000001 container=null queue=default clusterResource=<memory:21171, vCores:6> type=NODE_LOCAL requestedPartition=
2022-11-24 06:47:53,425 INFO org.apache.hadoop.yarn.server.resourcemanager.rmcontainer.RMContainerImpl: container_1669272252091_0001_01_000002 Container Transitioned from NEW to ALLOCATED
2022-11-24 06:47:53,425 INFO org.apache.hadoop.yarn.server.resourcemanager.scheduler.common.fica.FiCaSchedulerNode: Assigned container container_1669272252091_0001_01_000002 of capacity <memory:1024, vCores:1> on host adh-hack-02-mnode1.ru-central1.internal:8041, which has 2 containers, <memory:3072, vCores:2> used and <memory:3985, vCores:0> available after allocation
2022-11-24 06:47:53,425 INFO org.apache.hadoop.yarn.server.resourcemanager.RMAuditLogger: USER=yarn	OPERATION=AM Allocated Container	TARGET=SchedulerApp	RESULT=SUCCESS	APPID=application_1669272252091_0001	CONTAINERID=container_1669272252091_0001_01_000002	RESOURCE=<memory:1024, vCores:1>	QUEUENAME=default
2022-11-24 06:47:53,425 INFO org.apache.hadoop.yarn.server.resourcemanager.scheduler.capacity.ParentQueue: assignedContainer queue=root usedCapacity=0.14510415 absoluteUsedCapacity=0.14510415 used=<memory:3072, vCores:2> cluster=<memory:21171, vCores:6>
2022-11-24 06:47:53,425 INFO org.apache.hadoop.yarn.server.resourcemanager.scheduler.capacity.CapacityScheduler: Allocation proposal accepted
2022-11-24 06:47:53,425 INFO org.apache.hadoop.yarn.server.resourcemanager.scheduler.capacity.allocator.AbstractContainerAllocator: assignedContainer application attempt=appattempt_1669272252091_0001_000001 container=null queue=default clusterResource=<memory:21171, vCores:6> type=NODE_LOCAL requestedPartition=
2022-11-24 06:47:53,426 INFO org.apache.hadoop.yarn.server.resourcemanager.rmcontainer.RMContainerImpl: container_1669272252091_0001_01_000003 Container Transitioned from NEW to ALLOCATED
2022-11-24 06:47:53,426 INFO org.apache.hadoop.yarn.server.resourcemanager.scheduler.common.fica.FiCaSchedulerNode: Assigned container container_1669272252091_0001_01_000003 of capacity <memory:1024, vCores:1> on host adh-hack-02-mnode1.ru-central1.internal:8041, which has 3 containers, <memory:4096, vCores:3> used and <memory:2961, vCores:-1> available after allocation
2022-11-24 06:47:53,426 INFO org.apache.hadoop.yarn.server.resourcemanager.RMAuditLogger: USER=yarn	OPERATION=AM Allocated Container	TARGET=SchedulerApp	RESULT=SUCCESS	APPID=application_1669272252091_0001	CONTAINERID=container_1669272252091_0001_01_000003	RESOURCE=<memory:1024, vCores:1>	QUEUENAME=default
2022-11-24 06:47:53,426 INFO org.apache.hadoop.yarn.server.resourcemanager.scheduler.capacity.ParentQueue: assignedContainer queue=root usedCapacity=0.1934722 absoluteUsedCapacity=0.1934722 used=<memory:4096, vCores:3> cluster=<memory:21171, vCores:6>
2022-11-24 06:47:53,426 INFO org.apache.hadoop.yarn.server.resourcemanager.scheduler.capacity.CapacityScheduler: Allocation proposal accepted
2022-11-24 06:47:53,426 INFO org.apache.hadoop.yarn.server.resourcemanager.scheduler.capacity.allocator.AbstractContainerAllocator: assignedContainer application attempt=appattempt_1669272252091_0001_000001 container=null queue=default clusterResource=<memory:21171, vCores:6> type=NODE_LOCAL requestedPartition=
2022-11-24 06:47:53,426 INFO org.apache.hadoop.yarn.server.resourcemanager.rmcontainer.RMContainerImpl: container_1669272252091_0001_01_000004 Container Transitioned from NEW to ALLOCATED
2022-11-24 06:47:53,427 INFO org.apache.hadoop.yarn.server.resourcemanager.scheduler.common.fica.FiCaSchedulerNode: Assigned container container_1669272252091_0001_01_000004 of capacity <memory:1024, vCores:1> on host adh-hack-02-mnode1.ru-central1.internal:8041, which has 4 containers, <memory:5120, vCores:4> used and <memory:1937, vCores:-2> available after allocation
2022-11-24 06:47:53,427 INFO org.apache.hadoop.yarn.server.resourcemanager.RMAuditLogger: USER=yarn	OPERATION=AM Allocated Container	TARGET=SchedulerApp	RESULT=SUCCESS	APPID=application_1669272252091_0001	CONTAINERID=container_1669272252091_0001_01_000004	RESOURCE=<memory:1024, vCores:1>	QUEUENAME=default
2022-11-24 06:47:53,427 INFO org.apache.hadoop.yarn.server.resourcemanager.scheduler.capacity.ParentQueue: assignedContainer queue=root usedCapacity=0.24184026 absoluteUsedCapacity=0.24184026 used=<memory:5120, vCores:4> cluster=<memory:21171, vCores:6>
2022-11-24 06:47:53,427 INFO org.apache.hadoop.yarn.server.resourcemanager.scheduler.capacity.CapacityScheduler: Allocation proposal accepted
2022-11-24 06:47:53,427 INFO org.apache.hadoop.yarn.server.resourcemanager.scheduler.capacity.allocator.AbstractContainerAllocator: assignedContainer application attempt=appattempt_1669272252091_0001_000001 container=null queue=default clusterResource=<memory:21171, vCores:6> type=NODE_LOCAL requestedPartition=
2022-11-24 06:47:53,428 INFO org.apache.hadoop.yarn.server.resourcemanager.rmcontainer.RMContainerImpl: container_1669272252091_0001_01_000005 Container Transitioned from NEW to ALLOCATED
2022-11-24 06:47:53,428 INFO org.apache.hadoop.yarn.server.resourcemanager.scheduler.common.fica.FiCaSchedulerNode: Assigned container container_1669272252091_0001_01_000005 of capacity <memory:1024, vCores:1> on host adh-hack-02-mnode1.ru-central1.internal:8041, which has 5 containers, <memory:6144, vCores:5> used and <memory:913, vCores:-3> available after allocation
2022-11-24 06:47:53,428 INFO org.apache.hadoop.yarn.server.resourcemanager.RMAuditLogger: USER=yarn	OPERATION=AM Allocated Container	TARGET=SchedulerApp	RESULT=SUCCESS	APPID=application_1669272252091_0001	CONTAINERID=container_1669272252091_0001_01_000005	RESOURCE=<memory:1024, vCores:1>	QUEUENAME=default
2022-11-24 06:47:53,428 INFO org.apache.hadoop.yarn.server.resourcemanager.scheduler.capacity.ParentQueue: assignedContainer queue=root usedCapacity=0.2902083 absoluteUsedCapacity=0.2902083 used=<memory:6144, vCores:5> cluster=<memory:21171, vCores:6>
2022-11-24 06:47:53,428 INFO org.apache.hadoop.yarn.server.resourcemanager.scheduler.capacity.CapacityScheduler: Allocation proposal accepted
2022-11-24 06:47:53,676 INFO org.apache.hadoop.yarn.server.resourcemanager.scheduler.capacity.allocator.AbstractContainerAllocator: assignedContainer application attempt=appattempt_1669272252091_0001_000001 container=null queue=default clusterResource=<memory:21171, vCores:6> type=NODE_LOCAL requestedPartition=
2022-11-24 06:47:53,677 INFO org.apache.hadoop.yarn.server.resourcemanager.rmcontainer.RMContainerImpl: container_1669272252091_0001_01_000006 Container Transitioned from NEW to ALLOCATED
2022-11-24 06:47:53,677 INFO org.apache.hadoop.yarn.server.resourcemanager.scheduler.common.fica.FiCaSchedulerNode: Assigned container container_1669272252091_0001_01_000006 of capacity <memory:1024, vCores:1> on host adh-hack-02-mnode2.ru-central1.internal:8041, which has 1 containers, <memory:1024, vCores:1> used and <memory:6033, vCores:1> available after allocation
2022-11-24 06:47:53,677 INFO org.apache.hadoop.yarn.server.resourcemanager.RMAuditLogger: USER=yarn	OPERATION=AM Allocated Container	TARGET=SchedulerApp	RESULT=SUCCESS	APPID=application_1669272252091_0001	CONTAINERID=container_1669272252091_0001_01_000006	RESOURCE=<memory:1024, vCores:1>	QUEUENAME=default
2022-11-24 06:47:53,677 INFO org.apache.hadoop.yarn.server.resourcemanager.scheduler.capacity.ParentQueue: assignedContainer queue=root usedCapacity=0.33857635 absoluteUsedCapacity=0.33857635 used=<memory:7168, vCores:6> cluster=<memory:21171, vCores:6>
2022-11-24 06:47:53,677 INFO org.apache.hadoop.yarn.server.resourcemanager.scheduler.capacity.CapacityScheduler: Allocation proposal accepted
2022-11-24 06:47:53,678 INFO org.apache.hadoop.yarn.server.resourcemanager.scheduler.capacity.allocator.AbstractContainerAllocator: assignedContainer application attempt=appattempt_1669272252091_0001_000001 container=null queue=default clusterResource=<memory:21171, vCores:6> type=NODE_LOCAL requestedPartition=
2022-11-24 06:47:53,678 INFO org.apache.hadoop.yarn.server.resourcemanager.rmcontainer.RMContainerImpl: container_1669272252091_0001_01_000007 Container Transitioned from NEW to ALLOCATED
2022-11-24 06:47:53,678 INFO org.apache.hadoop.yarn.server.resourcemanager.scheduler.common.fica.FiCaSchedulerNode: Assigned container container_1669272252091_0001_01_000007 of capacity <memory:1024, vCores:1> on host adh-hack-02-mnode2.ru-central1.internal:8041, which has 2 containers, <memory:2048, vCores:2> used and <memory:5009, vCores:0> available after allocation
2022-11-24 06:47:53,678 INFO org.apache.hadoop.yarn.server.resourcemanager.RMAuditLogger: USER=yarn	OPERATION=AM Allocated Container	TARGET=SchedulerApp	RESULT=SUCCESS	APPID=application_1669272252091_0001	CONTAINERID=container_1669272252091_0001_01_000007	RESOURCE=<memory:1024, vCores:1>	QUEUENAME=default
2022-11-24 06:47:53,678 INFO org.apache.hadoop.yarn.server.resourcemanager.scheduler.capacity.ParentQueue: assignedContainer queue=root usedCapacity=0.3869444 absoluteUsedCapacity=0.3869444 used=<memory:8192, vCores:7> cluster=<memory:21171, vCores:6>
2022-11-24 06:47:53,679 INFO org.apache.hadoop.yarn.server.resourcemanager.scheduler.capacity.CapacityScheduler: Allocation proposal accepted
2022-11-24 06:47:53,679 INFO org.apache.hadoop.yarn.server.resourcemanager.scheduler.capacity.allocator.AbstractContainerAllocator: assignedContainer application attempt=appattempt_1669272252091_0001_000001 container=null queue=default clusterResource=<memory:21171, vCores:6> type=NODE_LOCAL requestedPartition=
2022-11-24 06:47:53,679 INFO org.apache.hadoop.yarn.server.resourcemanager.rmcontainer.RMContainerImpl: container_1669272252091_0001_01_000008 Container Transitioned from NEW to ALLOCATED
2022-11-24 06:47:53,679 INFO org.apache.hadoop.yarn.server.resourcemanager.scheduler.common.fica.FiCaSchedulerNode: Assigned container container_1669272252091_0001_01_000008 of capacity <memory:1024, vCores:1> on host adh-hack-02-mnode2.ru-central1.internal:8041, which has 3 containers, <memory:3072, vCores:3> used and <memory:3985, vCores:-1> available after allocation
2022-11-24 06:47:53,679 INFO org.apache.hadoop.yarn.server.resourcemanager.RMAuditLogger: USER=yarn	OPERATION=AM Allocated Container	TARGET=SchedulerApp	RESULT=SUCCESS	APPID=application_1669272252091_0001	CONTAINERID=container_1669272252091_0001_01_000008	RESOURCE=<memory:1024, vCores:1>	QUEUENAME=default
2022-11-24 06:47:53,679 INFO org.apache.hadoop.yarn.server.resourcemanager.scheduler.capacity.ParentQueue: assignedContainer queue=root usedCapacity=0.43531245 absoluteUsedCapacity=0.43531245 used=<memory:9216, vCores:8> cluster=<memory:21171, vCores:6>
2022-11-24 06:47:53,679 INFO org.apache.hadoop.yarn.server.resourcemanager.scheduler.capacity.CapacityScheduler: Allocation proposal accepted
2022-11-24 06:47:53,680 INFO org.apache.hadoop.yarn.server.resourcemanager.scheduler.capacity.allocator.AbstractContainerAllocator: assignedContainer application attempt=appattempt_1669272252091_0001_000001 container=null queue=default clusterResource=<memory:21171, vCores:6> type=NODE_LOCAL requestedPartition=
2022-11-24 06:47:53,680 INFO org.apache.hadoop.yarn.server.resourcemanager.rmcontainer.RMContainerImpl: container_1669272252091_0001_01_000009 Container Transitioned from NEW to ALLOCATED
2022-11-24 06:47:53,680 INFO org.apache.hadoop.yarn.server.resourcemanager.scheduler.common.fica.FiCaSchedulerNode: Assigned container container_1669272252091_0001_01_000009 of capacity <memory:1024, vCores:1> on host adh-hack-02-mnode2.ru-central1.internal:8041, which has 4 containers, <memory:4096, vCores:4> used and <memory:2961, vCores:-2> available after allocation
2022-11-24 06:47:53,680 INFO org.apache.hadoop.yarn.server.resourcemanager.RMAuditLogger: USER=yarn	OPERATION=AM Allocated Container	TARGET=SchedulerApp	RESULT=SUCCESS	APPID=application_1669272252091_0001	CONTAINERID=container_1669272252091_0001_01_000009	RESOURCE=<memory:1024, vCores:1>	QUEUENAME=default
2022-11-24 06:47:53,680 INFO org.apache.hadoop.yarn.server.resourcemanager.scheduler.capacity.ParentQueue: assignedContainer queue=root usedCapacity=0.48368052 absoluteUsedCapacity=0.48368052 used=<memory:10240, vCores:9> cluster=<memory:21171, vCores:6>
2022-11-24 06:47:53,680 INFO org.apache.hadoop.yarn.server.resourcemanager.scheduler.capacity.CapacityScheduler: Allocation proposal accepted
2022-11-24 06:47:53,681 INFO org.apache.hadoop.yarn.server.resourcemanager.scheduler.capacity.allocator.AbstractContainerAllocator: assignedContainer application attempt=appattempt_1669272252091_0001_000001 container=null queue=default clusterResource=<memory:21171, vCores:6> type=NODE_LOCAL requestedPartition=
2022-11-24 06:47:53,681 INFO org.apache.hadoop.yarn.server.resourcemanager.rmcontainer.RMContainerImpl: container_1669272252091_0001_01_000010 Container Transitioned from NEW to ALLOCATED
2022-11-24 06:47:53,681 INFO org.apache.hadoop.yarn.server.resourcemanager.scheduler.common.fica.FiCaSchedulerNode: Assigned container container_1669272252091_0001_01_000010 of capacity <memory:1024, vCores:1> on host adh-hack-02-mnode2.ru-central1.internal:8041, which has 5 containers, <memory:5120, vCores:5> used and <memory:1937, vCores:-3> available after allocation
2022-11-24 06:47:53,681 INFO org.apache.hadoop.yarn.server.resourcemanager.RMAuditLogger: USER=yarn	OPERATION=AM Allocated Container	TARGET=SchedulerApp	RESULT=SUCCESS	APPID=application_1669272252091_0001	CONTAINERID=container_1669272252091_0001_01_000010	RESOURCE=<memory:1024, vCores:1>	QUEUENAME=default
2022-11-24 06:47:53,681 INFO org.apache.hadoop.yarn.server.resourcemanager.scheduler.capacity.ParentQueue: assignedContainer queue=root usedCapacity=0.5320486 absoluteUsedCapacity=0.5320486 used=<memory:11264, vCores:10> cluster=<memory:21171, vCores:6>
2022-11-24 06:47:53,681 INFO org.apache.hadoop.yarn.server.resourcemanager.scheduler.capacity.CapacityScheduler: Allocation proposal accepted
2022-11-24 06:47:53,681 INFO org.apache.hadoop.yarn.server.resourcemanager.scheduler.capacity.allocator.AbstractContainerAllocator: assignedContainer application attempt=appattempt_1669272252091_0001_000001 container=null queue=default clusterResource=<memory:21171, vCores:6> type=NODE_LOCAL requestedPartition=
2022-11-24 06:47:53,682 INFO org.apache.hadoop.yarn.server.resourcemanager.rmcontainer.RMContainerImpl: container_1669272252091_0001_01_000011 Container Transitioned from NEW to ALLOCATED
2022-11-24 06:47:53,682 INFO org.apache.hadoop.yarn.server.resourcemanager.scheduler.common.fica.FiCaSchedulerNode: Assigned container container_1669272252091_0001_01_000011 of capacity <memory:1024, vCores:1> on host adh-hack-02-mnode2.ru-central1.internal:8041, which has 6 containers, <memory:6144, vCores:6> used and <memory:913, vCores:-4> available after allocation
2022-11-24 06:47:53,682 INFO org.apache.hadoop.yarn.server.resourcemanager.RMAuditLogger: USER=yarn	OPERATION=AM Allocated Container	TARGET=SchedulerApp	RESULT=SUCCESS	APPID=application_1669272252091_0001	CONTAINERID=container_1669272252091_0001_01_000011	RESOURCE=<memory:1024, vCores:1>	QUEUENAME=default
2022-11-24 06:47:53,682 INFO org.apache.hadoop.yarn.server.resourcemanager.scheduler.capacity.ParentQueue: assignedContainer queue=root usedCapacity=0.5804166 absoluteUsedCapacity=0.5804166 used=<memory:12288, vCores:11> cluster=<memory:21171, vCores:6>
2022-11-24 06:47:53,682 INFO org.apache.hadoop.yarn.server.resourcemanager.scheduler.capacity.CapacityScheduler: Allocation proposal accepted
2022-11-24 06:47:53,682 INFO org.apache.hadoop.yarn.server.resourcemanager.scheduler.capacity.allocator.AbstractContainerAllocator: assignedContainer application attempt=appattempt_1669272252091_0001_000001 container=null queue=default clusterResource=<memory:21171, vCores:6> type=NODE_LOCAL requestedPartition=
2022-11-24 06:47:53,682 INFO org.apache.hadoop.yarn.server.resourcemanager.rmcontainer.RMContainerImpl: container_1669272252091_0001_01_000012 Container Transitioned from NEW to ALLOCATED
2022-11-24 06:47:53,682 INFO org.apache.hadoop.yarn.server.resourcemanager.scheduler.common.fica.FiCaSchedulerNode: Assigned container container_1669272252091_0001_01_000012 of capacity <memory:1024, vCores:1> on host adh-hack-02-mnode3.ru-central1.internal:8041, which has 1 containers, <memory:1024, vCores:1> used and <memory:6033, vCores:1> available after allocation
2022-11-24 06:47:53,683 INFO org.apache.hadoop.yarn.server.resourcemanager.RMAuditLogger: USER=yarn	OPERATION=AM Allocated Container	TARGET=SchedulerApp	RESULT=SUCCESS	APPID=application_1669272252091_0001	CONTAINERID=container_1669272252091_0001_01_000012	RESOURCE=<memory:1024, vCores:1>	QUEUENAME=default
2022-11-24 06:47:53,683 INFO org.apache.hadoop.yarn.server.resourcemanager.scheduler.capacity.ParentQueue: assignedContainer queue=root usedCapacity=0.62878466 absoluteUsedCapacity=0.62878466 used=<memory:13312, vCores:12> cluster=<memory:21171, vCores:6>
2022-11-24 06:47:53,683 INFO org.apache.hadoop.yarn.server.resourcemanager.scheduler.capacity.CapacityScheduler: Allocation proposal accepted
2022-11-24 06:47:53,683 INFO org.apache.hadoop.yarn.server.resourcemanager.scheduler.capacity.allocator.AbstractContainerAllocator: assignedContainer application attempt=appattempt_1669272252091_0001_000001 container=null queue=default clusterResource=<memory:21171, vCores:6> type=NODE_LOCAL requestedPartition=
2022-11-24 06:47:53,683 INFO org.apache.hadoop.yarn.server.resourcemanager.rmcontainer.RMContainerImpl: container_1669272252091_0001_01_000013 Container Transitioned from NEW to ALLOCATED
2022-11-24 06:47:53,683 INFO org.apache.hadoop.yarn.server.resourcemanager.scheduler.common.fica.FiCaSchedulerNode: Assigned container container_1669272252091_0001_01_000013 of capacity <memory:1024, vCores:1> on host adh-hack-02-mnode3.ru-central1.internal:8041, which has 2 containers, <memory:2048, vCores:2> used and <memory:5009, vCores:0> available after allocation
2022-11-24 06:47:53,683 INFO org.apache.hadoop.yarn.server.resourcemanager.RMAuditLogger: USER=yarn	OPERATION=AM Allocated Container	TARGET=SchedulerApp	RESULT=SUCCESS	APPID=application_1669272252091_0001	CONTAINERID=container_1669272252091_0001_01_000013	RESOURCE=<memory:1024, vCores:1>	QUEUENAME=default
2022-11-24 06:47:53,684 INFO org.apache.hadoop.yarn.server.resourcemanager.scheduler.capacity.ParentQueue: assignedContainer queue=root usedCapacity=0.6771527 absoluteUsedCapacity=0.6771527 used=<memory:14336, vCores:13> cluster=<memory:21171, vCores:6>
2022-11-24 06:47:53,684 INFO org.apache.hadoop.yarn.server.resourcemanager.scheduler.capacity.CapacityScheduler: Allocation proposal accepted
2022-11-24 06:47:53,684 INFO org.apache.hadoop.yarn.server.resourcemanager.scheduler.capacity.allocator.AbstractContainerAllocator: assignedContainer application attempt=appattempt_1669272252091_0001_000001 container=null queue=default clusterResource=<memory:21171, vCores:6> type=NODE_LOCAL requestedPartition=
2022-11-24 06:47:53,684 INFO org.apache.hadoop.yarn.server.resourcemanager.rmcontainer.RMContainerImpl: container_1669272252091_0001_01_000014 Container Transitioned from NEW to ALLOCATED
2022-11-24 06:47:53,684 INFO org.apache.hadoop.yarn.server.resourcemanager.scheduler.common.fica.FiCaSchedulerNode: Assigned container container_1669272252091_0001_01_000014 of capacity <memory:1024, vCores:1> on host adh-hack-02-mnode3.ru-central1.internal:8041, which has 3 containers, <memory:3072, vCores:3> used and <memory:3985, vCores:-1> available after allocation
2022-11-24 06:47:53,684 INFO org.apache.hadoop.yarn.server.resourcemanager.RMAuditLogger: USER=yarn	OPERATION=AM Allocated Container	TARGET=SchedulerApp	RESULT=SUCCESS	APPID=application_1669272252091_0001	CONTAINERID=container_1669272252091_0001_01_000014	RESOURCE=<memory:1024, vCores:1>	QUEUENAME=default
2022-11-24 06:47:53,684 INFO org.apache.hadoop.yarn.server.resourcemanager.scheduler.capacity.ParentQueue: assignedContainer queue=root usedCapacity=0.72552073 absoluteUsedCapacity=0.72552073 used=<memory:15360, vCores:14> cluster=<memory:21171, vCores:6>
2022-11-24 06:47:53,684 INFO org.apache.hadoop.yarn.server.resourcemanager.scheduler.capacity.CapacityScheduler: Allocation proposal accepted
2022-11-24 06:47:53,684 INFO org.apache.hadoop.yarn.server.resourcemanager.scheduler.capacity.allocator.AbstractContainerAllocator: assignedContainer application attempt=appattempt_1669272252091_0001_000001 container=null queue=default clusterResource=<memory:21171, vCores:6> type=NODE_LOCAL requestedPartition=
2022-11-24 06:47:53,685 INFO org.apache.hadoop.yarn.server.resourcemanager.rmcontainer.RMContainerImpl: container_1669272252091_0001_01_000015 Container Transitioned from NEW to ALLOCATED
2022-11-24 06:47:53,685 INFO org.apache.hadoop.yarn.server.resourcemanager.scheduler.common.fica.FiCaSchedulerNode: Assigned container container_1669272252091_0001_01_000015 of capacity <memory:1024, vCores:1> on host adh-hack-02-mnode3.ru-central1.internal:8041, which has 4 containers, <memory:4096, vCores:4> used and <memory:2961, vCores:-2> available after allocation
2022-11-24 06:47:53,685 INFO org.apache.hadoop.yarn.server.resourcemanager.RMAuditLogger: USER=yarn	OPERATION=AM Allocated Container	TARGET=SchedulerApp	RESULT=SUCCESS	APPID=application_1669272252091_0001	CONTAINERID=container_1669272252091_0001_01_000015	RESOURCE=<memory:1024, vCores:1>	QUEUENAME=default
2022-11-24 06:47:53,685 INFO org.apache.hadoop.yarn.server.resourcemanager.scheduler.capacity.ParentQueue: assignedContainer queue=root usedCapacity=0.7738888 absoluteUsedCapacity=0.7738888 used=<memory:16384, vCores:15> cluster=<memory:21171, vCores:6>
2022-11-24 06:47:53,685 INFO org.apache.hadoop.yarn.server.resourcemanager.scheduler.capacity.CapacityScheduler: Allocation proposal accepted
2022-11-24 06:47:53,686 INFO org.apache.hadoop.yarn.server.resourcemanager.scheduler.capacity.allocator.AbstractContainerAllocator: assignedContainer application attempt=appattempt_1669272252091_0001_000001 container=null queue=default clusterResource=<memory:21171, vCores:6> type=NODE_LOCAL requestedPartition=
2022-11-24 06:47:53,686 INFO org.apache.hadoop.yarn.server.resourcemanager.rmcontainer.RMContainerImpl: container_1669272252091_0001_01_000016 Container Transitioned from NEW to ALLOCATED
2022-11-24 06:47:53,686 INFO org.apache.hadoop.yarn.server.resourcemanager.scheduler.common.fica.FiCaSchedulerNode: Assigned container container_1669272252091_0001_01_000016 of capacity <memory:1024, vCores:1> on host adh-hack-02-mnode3.ru-central1.internal:8041, which has 5 containers, <memory:5120, vCores:5> used and <memory:1937, vCores:-3> available after allocation
2022-11-24 06:47:53,686 INFO org.apache.hadoop.yarn.server.resourcemanager.RMAuditLogger: USER=yarn	OPERATION=AM Allocated Container	TARGET=SchedulerApp	RESULT=SUCCESS	APPID=application_1669272252091_0001	CONTAINERID=container_1669272252091_0001_01_000016	RESOURCE=<memory:1024, vCores:1>	QUEUENAME=default
2022-11-24 06:47:53,686 INFO org.apache.hadoop.yarn.server.resourcemanager.scheduler.capacity.ParentQueue: assignedContainer queue=root usedCapacity=0.82225686 absoluteUsedCapacity=0.82225686 used=<memory:17408, vCores:16> cluster=<memory:21171, vCores:6>
2022-11-24 06:47:53,686 INFO org.apache.hadoop.yarn.server.resourcemanager.scheduler.capacity.CapacityScheduler: Allocation proposal accepted
2022-11-24 06:47:53,686 INFO org.apache.hadoop.yarn.server.resourcemanager.scheduler.capacity.allocator.AbstractContainerAllocator: assignedContainer application attempt=appattempt_1669272252091_0001_000001 container=null queue=default clusterResource=<memory:21171, vCores:6> type=NODE_LOCAL requestedPartition=
2022-11-24 06:47:53,687 INFO org.apache.hadoop.yarn.server.resourcemanager.rmcontainer.RMContainerImpl: container_1669272252091_0001_01_000017 Container Transitioned from NEW to ALLOCATED
2022-11-24 06:47:53,687 INFO org.apache.hadoop.yarn.server.resourcemanager.scheduler.common.fica.FiCaSchedulerNode: Assigned container container_1669272252091_0001_01_000017 of capacity <memory:1024, vCores:1> on host adh-hack-02-mnode3.ru-central1.internal:8041, which has 6 containers, <memory:6144, vCores:6> used and <memory:913, vCores:-4> available after allocation
2022-11-24 06:47:53,687 INFO org.apache.hadoop.yarn.server.resourcemanager.RMAuditLogger: USER=yarn	OPERATION=AM Allocated Container	TARGET=SchedulerApp	RESULT=SUCCESS	APPID=application_1669272252091_0001	CONTAINERID=container_1669272252091_0001_01_000017	RESOURCE=<memory:1024, vCores:1>	QUEUENAME=default
2022-11-24 06:47:53,687 INFO org.apache.hadoop.yarn.server.resourcemanager.scheduler.capacity.ParentQueue: assignedContainer queue=root usedCapacity=0.8706249 absoluteUsedCapacity=0.8706249 used=<memory:18432, vCores:17> cluster=<memory:21171, vCores:6>
2022-11-24 06:47:53,687 INFO org.apache.hadoop.yarn.server.resourcemanager.scheduler.capacity.CapacityScheduler: Allocation proposal accepted
2022-11-24 06:47:53,947 INFO org.apache.hadoop.yarn.server.resourcemanager.security.NMTokenSecretManagerInRM: Sending NMToken for nodeId : adh-hack-02-mnode1.ru-central1.internal:8041 for container : container_1669272252091_0001_01_000002
2022-11-24 06:47:53,947 INFO org.apache.hadoop.yarn.server.resourcemanager.rmcontainer.RMContainerImpl: container_1669272252091_0001_01_000002 Container Transitioned from ALLOCATED to ACQUIRED
2022-11-24 06:47:53,949 INFO org.apache.hadoop.yarn.server.resourcemanager.rmcontainer.RMContainerImpl: container_1669272252091_0001_01_000003 Container Transitioned from ALLOCATED to ACQUIRED
2022-11-24 06:47:53,953 INFO org.apache.hadoop.yarn.server.resourcemanager.rmcontainer.RMContainerImpl: container_1669272252091_0001_01_000004 Container Transitioned from ALLOCATED to ACQUIRED
2022-11-24 06:47:53,956 INFO org.apache.hadoop.yarn.server.resourcemanager.rmcontainer.RMContainerImpl: container_1669272252091_0001_01_000005 Container Transitioned from ALLOCATED to ACQUIRED
2022-11-24 06:47:53,957 INFO org.apache.hadoop.yarn.server.resourcemanager.security.NMTokenSecretManagerInRM: Sending NMToken for nodeId : adh-hack-02-mnode2.ru-central1.internal:8041 for container : container_1669272252091_0001_01_000006
2022-11-24 06:47:53,957 INFO org.apache.hadoop.yarn.server.resourcemanager.rmcontainer.RMContainerImpl: container_1669272252091_0001_01_000006 Container Transitioned from ALLOCATED to ACQUIRED
2022-11-24 06:47:53,959 INFO org.apache.hadoop.yarn.server.resourcemanager.rmcontainer.RMContainerImpl: container_1669272252091_0001_01_000007 Container Transitioned from ALLOCATED to ACQUIRED
2022-11-24 06:47:53,967 INFO org.apache.hadoop.yarn.server.resourcemanager.rmcontainer.RMContainerImpl: container_1669272252091_0001_01_000008 Container Transitioned from ALLOCATED to ACQUIRED
2022-11-24 06:47:53,969 INFO org.apache.hadoop.yarn.server.resourcemanager.rmcontainer.RMContainerImpl: container_1669272252091_0001_01_000009 Container Transitioned from ALLOCATED to ACQUIRED
2022-11-24 06:47:53,971 INFO org.apache.hadoop.yarn.server.resourcemanager.rmcontainer.RMContainerImpl: container_1669272252091_0001_01_000010 Container Transitioned from ALLOCATED to ACQUIRED
2022-11-24 06:47:53,972 INFO org.apache.hadoop.yarn.server.resourcemanager.rmcontainer.RMContainerImpl: container_1669272252091_0001_01_000011 Container Transitioned from ALLOCATED to ACQUIRED
2022-11-24 06:47:53,973 INFO org.apache.hadoop.yarn.server.resourcemanager.security.NMTokenSecretManagerInRM: Sending NMToken for nodeId : adh-hack-02-mnode3.ru-central1.internal:8041 for container : container_1669272252091_0001_01_000012
2022-11-24 06:47:53,974 INFO org.apache.hadoop.yarn.server.resourcemanager.rmcontainer.RMContainerImpl: container_1669272252091_0001_01_000012 Container Transitioned from ALLOCATED to ACQUIRED
2022-11-24 06:47:53,975 INFO org.apache.hadoop.yarn.server.resourcemanager.rmcontainer.RMContainerImpl: container_1669272252091_0001_01_000013 Container Transitioned from ALLOCATED to ACQUIRED
2022-11-24 06:47:53,976 INFO org.apache.hadoop.yarn.server.resourcemanager.rmcontainer.RMContainerImpl: container_1669272252091_0001_01_000014 Container Transitioned from ALLOCATED to ACQUIRED
2022-11-24 06:47:53,978 INFO org.apache.hadoop.yarn.server.resourcemanager.rmcontainer.RMContainerImpl: container_1669272252091_0001_01_000015 Container Transitioned from ALLOCATED to ACQUIRED
2022-11-24 06:47:53,978 INFO org.apache.hadoop.yarn.server.resourcemanager.rmcontainer.RMContainerImpl: container_1669272252091_0001_01_000016 Container Transitioned from ALLOCATED to ACQUIRED
2022-11-24 06:47:53,979 INFO org.apache.hadoop.yarn.server.resourcemanager.rmcontainer.RMContainerImpl: container_1669272252091_0001_01_000017 Container Transitioned from ALLOCATED to ACQUIRED
2022-11-24 06:47:54,434 INFO org.apache.hadoop.yarn.server.resourcemanager.rmcontainer.RMContainerImpl: container_1669272252091_0001_01_000002 Container Transitioned from ACQUIRED to RUNNING
2022-11-24 06:47:54,435 INFO org.apache.hadoop.yarn.server.resourcemanager.rmcontainer.RMContainerImpl: container_1669272252091_0001_01_000003 Container Transitioned from ACQUIRED to RUNNING
2022-11-24 06:47:54,435 INFO org.apache.hadoop.yarn.server.resourcemanager.rmcontainer.RMContainerImpl: container_1669272252091_0001_01_000004 Container Transitioned from ACQUIRED to RUNNING
2022-11-24 06:47:54,435 INFO org.apache.hadoop.yarn.server.resourcemanager.rmcontainer.RMContainerImpl: container_1669272252091_0001_01_000005 Container Transitioned from ACQUIRED to RUNNING
2022-11-24 06:47:54,738 INFO org.apache.hadoop.yarn.server.resourcemanager.rmcontainer.RMContainerImpl: container_1669272252091_0001_01_000006 Container Transitioned from ACQUIRED to RUNNING
2022-11-24 06:47:54,739 INFO org.apache.hadoop.yarn.server.resourcemanager.rmcontainer.RMContainerImpl: container_1669272252091_0001_01_000007 Container Transitioned from ACQUIRED to RUNNING
2022-11-24 06:47:54,742 INFO org.apache.hadoop.yarn.server.resourcemanager.rmcontainer.RMContainerImpl: container_1669272252091_0001_01_000008 Container Transitioned from ACQUIRED to RUNNING
2022-11-24 06:47:54,742 INFO org.apache.hadoop.yarn.server.resourcemanager.rmcontainer.RMContainerImpl: container_1669272252091_0001_01_000009 Container Transitioned from ACQUIRED to RUNNING
2022-11-24 06:47:54,742 INFO org.apache.hadoop.yarn.server.resourcemanager.rmcontainer.RMContainerImpl: container_1669272252091_0001_01_000010 Container Transitioned from ACQUIRED to RUNNING
2022-11-24 06:47:54,743 INFO org.apache.hadoop.yarn.server.resourcemanager.rmcontainer.RMContainerImpl: container_1669272252091_0001_01_000011 Container Transitioned from ACQUIRED to RUNNING
2022-11-24 06:47:54,797 INFO org.apache.hadoop.yarn.server.resourcemanager.rmcontainer.RMContainerImpl: container_1669272252091_0001_01_000012 Container Transitioned from ACQUIRED to RUNNING
2022-11-24 06:47:54,797 INFO org.apache.hadoop.yarn.server.resourcemanager.rmcontainer.RMContainerImpl: container_1669272252091_0001_01_000013 Container Transitioned from ACQUIRED to RUNNING
2022-11-24 06:47:54,798 INFO org.apache.hadoop.yarn.server.resourcemanager.rmcontainer.RMContainerImpl: container_1669272252091_0001_01_000014 Container Transitioned from ACQUIRED to RUNNING
2022-11-24 06:47:54,798 INFO org.apache.hadoop.yarn.server.resourcemanager.rmcontainer.RMContainerImpl: container_1669272252091_0001_01_000015 Container Transitioned from ACQUIRED to RUNNING
2022-11-24 06:47:54,799 INFO org.apache.hadoop.yarn.server.resourcemanager.rmcontainer.RMContainerImpl: container_1669272252091_0001_01_000016 Container Transitioned from ACQUIRED to RUNNING
2022-11-24 06:47:54,803 INFO org.apache.hadoop.yarn.server.resourcemanager.rmcontainer.RMContainerImpl: container_1669272252091_0001_01_000017 Container Transitioned from ACQUIRED to RUNNING
2022-11-24 06:47:55,028 INFO org.apache.hadoop.yarn.server.resourcemanager.scheduler.AppSchedulingInfo: checking for deactivate of application :application_1669272252091_0001
2022-11-24 06:48:00,604 INFO org.apache.hadoop.yarn.server.resourcemanager.rmcontainer.RMContainerImpl: container_1669272252091_0001_01_000004 Container Transitioned from RUNNING to COMPLETED
2022-11-24 06:48:00,604 INFO org.apache.hadoop.yarn.server.resourcemanager.RMAuditLogger: USER=yarn	OPERATION=AM Released Container	TARGET=SchedulerApp	RESULT=SUCCESS	APPID=application_1669272252091_0001	CONTAINERID=container_1669272252091_0001_01_000004	RESOURCE=<memory:1024, vCores:1>	QUEUENAME=default
2022-11-24 06:48:00,644 INFO org.apache.hadoop.yarn.server.resourcemanager.rmcontainer.RMContainerImpl: container_1669272252091_0001_01_000003 Container Transitioned from RUNNING to COMPLETED
2022-11-24 06:48:00,645 INFO org.apache.hadoop.yarn.server.resourcemanager.RMAuditLogger: USER=yarn	OPERATION=AM Released Container	TARGET=SchedulerApp	RESULT=SUCCESS	APPID=application_1669272252091_0001	CONTAINERID=container_1669272252091_0001_01_000003	RESOURCE=<memory:1024, vCores:1>	QUEUENAME=default
2022-11-24 06:48:00,768 INFO org.apache.hadoop.yarn.server.resourcemanager.rmcontainer.RMContainerImpl: container_1669272252091_0001_01_000002 Container Transitioned from RUNNING to COMPLETED
2022-11-24 06:48:00,768 INFO org.apache.hadoop.yarn.server.resourcemanager.RMAuditLogger: USER=yarn	OPERATION=AM Released Container	TARGET=SchedulerApp	RESULT=SUCCESS	APPID=application_1669272252091_0001	CONTAINERID=container_1669272252091_0001_01_000002	RESOURCE=<memory:1024, vCores:1>	QUEUENAME=default
2022-11-24 06:48:00,889 INFO org.apache.hadoop.yarn.server.resourcemanager.rmcontainer.RMContainerImpl: container_1669272252091_0001_01_000005 Container Transitioned from RUNNING to COMPLETED
2022-11-24 06:48:00,889 INFO org.apache.hadoop.yarn.server.resourcemanager.RMAuditLogger: USER=yarn	OPERATION=AM Released Container	TARGET=SchedulerApp	RESULT=SUCCESS	APPID=application_1669272252091_0001	CONTAINERID=container_1669272252091_0001_01_000005	RESOURCE=<memory:1024, vCores:1>	QUEUENAME=default
2022-11-24 06:48:01,892 INFO org.apache.hadoop.yarn.server.resourcemanager.scheduler.capacity.allocator.AbstractContainerAllocator: assignedContainer application attempt=appattempt_1669272252091_0001_000001 container=null queue=default clusterResource=<memory:21171, vCores:6> type=OFF_SWITCH requestedPartition=
2022-11-24 06:48:01,892 INFO org.apache.hadoop.yarn.server.resourcemanager.rmcontainer.RMContainerImpl: container_1669272252091_0001_01_000018 Container Transitioned from NEW to ALLOCATED
2022-11-24 06:48:01,892 INFO org.apache.hadoop.yarn.server.resourcemanager.scheduler.common.fica.FiCaSchedulerNode: Assigned container container_1669272252091_0001_01_000018 of capacity <memory:1024, vCores:1> on host adh-hack-02-mnode1.ru-central1.internal:8041, which has 2 containers, <memory:3072, vCores:2> used and <memory:3985, vCores:0> available after allocation
2022-11-24 06:48:01,892 INFO org.apache.hadoop.yarn.server.resourcemanager.RMAuditLogger: USER=yarn	OPERATION=AM Allocated Container	TARGET=SchedulerApp	RESULT=SUCCESS	APPID=application_1669272252091_0001	CONTAINERID=container_1669272252091_0001_01_000018	RESOURCE=<memory:1024, vCores:1>	QUEUENAME=default
2022-11-24 06:48:01,892 INFO org.apache.hadoop.yarn.server.resourcemanager.scheduler.capacity.ParentQueue: assignedContainer queue=root usedCapacity=0.72552073 absoluteUsedCapacity=0.72552073 used=<memory:15360, vCores:14> cluster=<memory:21171, vCores:6>
2022-11-24 06:48:01,893 INFO org.apache.hadoop.yarn.server.resourcemanager.scheduler.capacity.CapacityScheduler: Allocation proposal accepted
2022-11-24 06:48:02,171 INFO org.apache.hadoop.yarn.server.resourcemanager.rmcontainer.RMContainerImpl: container_1669272252091_0001_01_000018 Container Transitioned from ALLOCATED to ACQUIRED
2022-11-24 06:48:02,894 INFO org.apache.hadoop.yarn.server.resourcemanager.rmcontainer.RMContainerImpl: container_1669272252091_0001_01_000018 Container Transitioned from ACQUIRED to RUNNING
2022-11-24 06:48:03,176 INFO org.apache.hadoop.yarn.server.resourcemanager.scheduler.AppSchedulingInfo: checking for deactivate of application :application_1669272252091_0001
2022-11-24 06:48:04,099 INFO org.apache.hadoop.yarn.server.resourcemanager.rmcontainer.RMContainerImpl: container_1669272252091_0001_01_000006 Container Transitioned from RUNNING to COMPLETED
2022-11-24 06:48:04,099 INFO org.apache.hadoop.yarn.server.resourcemanager.RMAuditLogger: USER=yarn	OPERATION=AM Released Container	TARGET=SchedulerApp	RESULT=SUCCESS	APPID=application_1669272252091_0001	CONTAINERID=container_1669272252091_0001_01_000006	RESOURCE=<memory:1024, vCores:1>	QUEUENAME=default
2022-11-24 06:48:04,203 INFO org.apache.hadoop.yarn.server.resourcemanager.rmcontainer.RMContainerImpl: container_1669272252091_0001_01_000011 Container Transitioned from RUNNING to COMPLETED
2022-11-24 06:48:04,203 INFO org.apache.hadoop.yarn.server.resourcemanager.RMAuditLogger: USER=yarn	OPERATION=AM Released Container	TARGET=SchedulerApp	RESULT=SUCCESS	APPID=application_1669272252091_0001	CONTAINERID=container_1669272252091_0001_01_000011	RESOURCE=<memory:1024, vCores:1>	QUEUENAME=default
2022-11-24 06:48:04,332 INFO org.apache.hadoop.yarn.server.resourcemanager.rmcontainer.RMContainerImpl: container_1669272252091_0001_01_000009 Container Transitioned from RUNNING to COMPLETED
2022-11-24 06:48:04,332 INFO org.apache.hadoop.yarn.server.resourcemanager.RMAuditLogger: USER=yarn	OPERATION=AM Released Container	TARGET=SchedulerApp	RESULT=SUCCESS	APPID=application_1669272252091_0001	CONTAINERID=container_1669272252091_0001_01_000009	RESOURCE=<memory:1024, vCores:1>	QUEUENAME=default
2022-11-24 06:48:04,369 INFO org.apache.hadoop.yarn.server.resourcemanager.rmcontainer.RMContainerImpl: container_1669272252091_0001_01_000007 Container Transitioned from RUNNING to COMPLETED
2022-11-24 06:48:04,369 INFO org.apache.hadoop.yarn.server.resourcemanager.RMAuditLogger: USER=yarn	OPERATION=AM Released Container	TARGET=SchedulerApp	RESULT=SUCCESS	APPID=application_1669272252091_0001	CONTAINERID=container_1669272252091_0001_01_000007	RESOURCE=<memory:1024, vCores:1>	QUEUENAME=default
2022-11-24 06:48:04,399 INFO org.apache.hadoop.yarn.server.resourcemanager.rmcontainer.RMContainerImpl: container_1669272252091_0001_01_000013 Container Transitioned from RUNNING to COMPLETED
2022-11-24 06:48:04,399 INFO org.apache.hadoop.yarn.server.resourcemanager.RMAuditLogger: USER=yarn	OPERATION=AM Released Container	TARGET=SchedulerApp	RESULT=SUCCESS	APPID=application_1669272252091_0001	CONTAINERID=container_1669272252091_0001_01_000013	RESOURCE=<memory:1024, vCores:1>	QUEUENAME=default
2022-11-24 06:48:04,400 INFO org.apache.hadoop.yarn.server.resourcemanager.rmcontainer.RMContainerImpl: container_1669272252091_0001_01_000008 Container Transitioned from RUNNING to COMPLETED
2022-11-24 06:48:04,400 INFO org.apache.hadoop.yarn.server.resourcemanager.RMAuditLogger: USER=yarn	OPERATION=AM Released Container	TARGET=SchedulerApp	RESULT=SUCCESS	APPID=application_1669272252091_0001	CONTAINERID=container_1669272252091_0001_01_000008	RESOURCE=<memory:1024, vCores:1>	QUEUENAME=default
2022-11-24 06:48:04,429 INFO org.apache.hadoop.yarn.server.resourcemanager.rmcontainer.RMContainerImpl: container_1669272252091_0001_01_000010 Container Transitioned from RUNNING to COMPLETED
2022-11-24 06:48:04,429 INFO org.apache.hadoop.yarn.server.resourcemanager.RMAuditLogger: USER=yarn	OPERATION=AM Released Container	TARGET=SchedulerApp	RESULT=SUCCESS	APPID=application_1669272252091_0001	CONTAINERID=container_1669272252091_0001_01_000010	RESOURCE=<memory:1024, vCores:1>	QUEUENAME=default
2022-11-24 06:48:04,843 INFO org.apache.hadoop.yarn.server.resourcemanager.rmcontainer.RMContainerImpl: container_1669272252091_0001_01_000012 Container Transitioned from RUNNING to COMPLETED
2022-11-24 06:48:04,843 INFO org.apache.hadoop.yarn.server.resourcemanager.RMAuditLogger: USER=yarn	OPERATION=AM Released Container	TARGET=SchedulerApp	RESULT=SUCCESS	APPID=application_1669272252091_0001	CONTAINERID=container_1669272252091_0001_01_000012	RESOURCE=<memory:1024, vCores:1>	QUEUENAME=default
2022-11-24 06:48:04,906 INFO org.apache.hadoop.yarn.server.resourcemanager.rmcontainer.RMContainerImpl: container_1669272252091_0001_01_000017 Container Transitioned from RUNNING to COMPLETED
2022-11-24 06:48:04,906 INFO org.apache.hadoop.yarn.server.resourcemanager.RMAuditLogger: USER=yarn	OPERATION=AM Released Container	TARGET=SchedulerApp	RESULT=SUCCESS	APPID=application_1669272252091_0001	CONTAINERID=container_1669272252091_0001_01_000017	RESOURCE=<memory:1024, vCores:1>	QUEUENAME=default
2022-11-24 06:48:04,923 INFO org.apache.hadoop.yarn.server.resourcemanager.rmcontainer.RMContainerImpl: container_1669272252091_0001_01_000014 Container Transitioned from RUNNING to COMPLETED
2022-11-24 06:48:04,923 INFO org.apache.hadoop.yarn.server.resourcemanager.RMAuditLogger: USER=yarn	OPERATION=AM Released Container	TARGET=SchedulerApp	RESULT=SUCCESS	APPID=application_1669272252091_0001	CONTAINERID=container_1669272252091_0001_01_000014	RESOURCE=<memory:1024, vCores:1>	QUEUENAME=default
2022-11-24 06:48:04,961 INFO org.apache.hadoop.yarn.server.resourcemanager.rmcontainer.RMContainerImpl: container_1669272252091_0001_01_000016 Container Transitioned from RUNNING to COMPLETED
2022-11-24 06:48:04,961 INFO org.apache.hadoop.yarn.server.resourcemanager.RMAuditLogger: USER=yarn	OPERATION=AM Released Container	TARGET=SchedulerApp	RESULT=SUCCESS	APPID=application_1669272252091_0001	CONTAINERID=container_1669272252091_0001_01_000016	RESOURCE=<memory:1024, vCores:1>	QUEUENAME=default
2022-11-24 06:48:04,983 INFO org.apache.hadoop.yarn.server.resourcemanager.rmcontainer.RMContainerImpl: container_1669272252091_0001_01_000015 Container Transitioned from RUNNING to COMPLETED
2022-11-24 06:48:04,984 INFO org.apache.hadoop.yarn.server.resourcemanager.RMAuditLogger: USER=yarn	OPERATION=AM Released Container	TARGET=SchedulerApp	RESULT=SUCCESS	APPID=application_1669272252091_0001	CONTAINERID=container_1669272252091_0001_01_000015	RESOURCE=<memory:1024, vCores:1>	QUEUENAME=default
2022-11-24 06:48:05,826 INFO org.apache.hadoop.yarn.server.resourcemanager.rmapp.attempt.RMAppAttemptImpl: Updating application attempt appattempt_1669272252091_0001_000001 with final state: FINISHING, and exit status: -1000
2022-11-24 06:48:05,827 INFO org.apache.hadoop.yarn.server.resourcemanager.rmapp.attempt.RMAppAttemptImpl: appattempt_1669272252091_0001_000001 State change from RUNNING to FINAL_SAVING on event = UNREGISTERED
2022-11-24 06:48:05,827 INFO org.apache.hadoop.yarn.server.resourcemanager.rmapp.RMAppImpl: Updating application application_1669272252091_0001 with final state: FINISHING
2022-11-24 06:48:05,827 INFO org.apache.hadoop.yarn.server.resourcemanager.rmapp.RMAppImpl: application_1669272252091_0001 State change from RUNNING to FINAL_SAVING on event = ATTEMPT_UNREGISTERED
2022-11-24 06:48:05,827 INFO org.apache.hadoop.yarn.server.resourcemanager.recovery.RMStateStore: Updating info for app: application_1669272252091_0001
2022-11-24 06:48:05,828 INFO org.apache.hadoop.yarn.server.resourcemanager.rmapp.attempt.RMAppAttemptImpl: appattempt_1669272252091_0001_000001 State change from FINAL_SAVING to FINISHING on event = ATTEMPT_UPDATE_SAVED
2022-11-24 06:48:05,829 INFO org.apache.hadoop.yarn.server.resourcemanager.rmcontainer.RMContainerImpl: container_1669272252091_0001_01_000018 Container Transitioned from RUNNING to COMPLETED
2022-11-24 06:48:05,829 INFO org.apache.hadoop.yarn.server.resourcemanager.RMAuditLogger: USER=yarn	OPERATION=AM Released Container	TARGET=SchedulerApp	RESULT=SUCCESS	APPID=application_1669272252091_0001	CONTAINERID=container_1669272252091_0001_01_000018	RESOURCE=<memory:1024, vCores:1>	QUEUENAME=default
2022-11-24 06:48:05,829 INFO org.apache.hadoop.yarn.server.resourcemanager.rmapp.RMAppImpl: application_1669272252091_0001 State change from FINAL_SAVING to FINISHING on event = APP_UPDATE_SAVED
2022-11-24 06:48:06,828 INFO org.apache.hadoop.yarn.server.resourcemanager.ApplicationMasterService: application_1669272252091_0001 unregistered successfully. 
2022-11-24 06:48:12,217 INFO org.apache.hadoop.yarn.server.resourcemanager.rmcontainer.RMContainerImpl: container_1669272252091_0001_01_000001 Container Transitioned from RUNNING to COMPLETED
2022-11-24 06:48:12,217 INFO org.apache.hadoop.yarn.server.resourcemanager.ApplicationMasterService: Unregistering app attempt : appattempt_1669272252091_0001_000001
2022-11-24 06:48:12,217 INFO org.apache.hadoop.yarn.server.resourcemanager.RMAuditLogger: USER=yarn	OPERATION=AM Released Container	TARGET=SchedulerApp	RESULT=SUCCESS	APPID=application_1669272252091_0001	CONTAINERID=container_1669272252091_0001_01_000001	RESOURCE=<memory:2048, vCores:1>	QUEUENAME=default
2022-11-24 06:48:12,218 INFO org.apache.hadoop.yarn.server.resourcemanager.security.AMRMTokenSecretManager: Application finished, removing password for appattempt_1669272252091_0001_000001
2022-11-24 06:48:12,220 INFO org.apache.hadoop.yarn.server.resourcemanager.rmapp.attempt.RMAppAttemptImpl: appattempt_1669272252091_0001_000001 State change from FINISHING to FINISHED on event = CONTAINER_FINISHED
2022-11-24 06:48:12,223 INFO org.apache.hadoop.yarn.server.resourcemanager.rmapp.RMAppImpl: application_1669272252091_0001 State change from FINISHING to FINISHED on event = ATTEMPT_FINISHED
2022-11-24 06:48:12,223 INFO org.apache.hadoop.yarn.server.resourcemanager.scheduler.capacity.CapacityScheduler: Application Attempt appattempt_1669272252091_0001_000001 is done. finalState=FINISHED
2022-11-24 06:48:12,224 INFO org.apache.hadoop.yarn.server.resourcemanager.scheduler.AppSchedulingInfo: Application application_1669272252091_0001 requests cleared
2022-11-24 06:48:12,224 INFO org.apache.hadoop.yarn.server.resourcemanager.scheduler.capacity.LeafQueue: Application removed - appId: application_1669272252091_0001 user: yarn queue: default #user-pending-applications: 0 #user-active-applications: 0 #queue-pending-applications: 0 #queue-active-applications: 0
2022-11-24 06:48:12,224 INFO org.apache.hadoop.yarn.server.resourcemanager.scheduler.capacity.ParentQueue: Application removed - appId: application_1669272252091_0001 user: yarn leaf-queue of parent: root #applications: 0
2022-11-24 06:48:12,224 INFO org.apache.hadoop.yarn.server.resourcemanager.RMAuditLogger: USER=yarn	OPERATION=Application Finished - Succeeded	TARGET=RMAppManager	RESULT=SUCCESS	APPID=application_1669272252091_0001
2022-11-24 06:48:12,225 INFO org.apache.hadoop.yarn.server.resourcemanager.amlauncher.AMLauncher: Cleaning master appattempt_1669272252091_0001_000001
2022-11-24 06:48:12,227 INFO org.apache.hadoop.yarn.server.resourcemanager.RMAppManager$ApplicationSummary: appId=application_1669272252091_0001,name=QuasiMonteCarlo,user=yarn,queue=default,state=FINISHED,trackingUrl=http://adh-hack-02-mnode1.ru-central1.internal:8088/proxy/application_1669272252091_0001/,appMasterHost=adh-hack-02-mnode1.ru-central1.internal,submitTime=1669272465690,startTime=1669272465751,finishTime=1669272485827,finalStatus=SUCCEEDED,memorySeconds=220596,vcoreSeconds=181,preemptedMemorySeconds=0,preemptedVcoreSeconds=0,preemptedAMContainers=0,preemptedNonAMContainers=0,preemptedResources=<memory:0\, vCores:0>,applicationType=MAPREDUCE,resourceSeconds=220596 MB-seconds\, 181 vcore-seconds,preemptedResourceSeconds=0 MB-seconds\, 0 vcore-seconds
2022-11-24 06:54:09,877 INFO org.apache.hadoop.yarn.server.resourcemanager.scheduler.AbstractYarnScheduler: Release request cache is cleaned up
2022-11-24 06:57:45,415 INFO org.apache.hadoop.yarn.server.resourcemanager.ClientRMService: Allocated new applicationId: 2
2022-11-24 06:57:45,766 INFO org.apache.hadoop.yarn.server.resourcemanager.scheduler.capacity.CapacityScheduler: Application 'application_1669272252091_0002' is submitted without priority hence considering default queue/cluster priority: 0
2022-11-24 06:57:45,766 INFO org.apache.hadoop.yarn.server.resourcemanager.scheduler.capacity.CapacityScheduler: Priority '0' is acceptable in queue : default for application: application_1669272252091_0002
2022-11-24 06:57:45,766 INFO org.apache.hadoop.yarn.server.resourcemanager.ClientRMService: Application with id 2 submitted by user hive
2022-11-24 06:57:45,766 INFO org.apache.hadoop.yarn.server.resourcemanager.RMAuditLogger: USER=hive	IP=10.129.0.155	OPERATION=Submit Application Request	TARGET=ClientRMService	RESULT=SUCCESS	APPID=application_1669272252091_0002	QUEUENAME=default
2022-11-24 06:57:45,767 INFO org.apache.hadoop.yarn.server.resourcemanager.rmapp.RMAppImpl: Storing application with id application_1669272252091_0002
2022-11-24 06:57:45,767 INFO org.apache.hadoop.yarn.server.resourcemanager.recovery.RMStateStore: Storing info for app: application_1669272252091_0002
2022-11-24 06:57:45,767 INFO org.apache.hadoop.yarn.server.resourcemanager.rmapp.RMAppImpl: application_1669272252091_0002 State change from NEW to NEW_SAVING on event = START
2022-11-24 06:57:45,768 INFO org.apache.hadoop.yarn.server.resourcemanager.rmapp.RMAppImpl: application_1669272252091_0002 State change from NEW_SAVING to SUBMITTED on event = APP_NEW_SAVED
2022-11-24 06:57:45,768 INFO org.apache.hadoop.yarn.server.resourcemanager.scheduler.capacity.ParentQueue: Application added - appId: application_1669272252091_0002 user: hive leaf-queue of parent: root #applications: 1
2022-11-24 06:57:45,768 INFO org.apache.hadoop.yarn.server.resourcemanager.scheduler.capacity.CapacityScheduler: Accepted application application_1669272252091_0002 from user: hive, in queue: default
2022-11-24 06:57:45,770 INFO org.apache.hadoop.yarn.server.resourcemanager.rmapp.RMAppImpl: application_1669272252091_0002 State change from SUBMITTED to ACCEPTED on event = APP_ACCEPTED
2022-11-24 06:57:45,770 INFO org.apache.hadoop.yarn.server.resourcemanager.ApplicationMasterService: Registering app attempt : appattempt_1669272252091_0002_000001
2022-11-24 06:57:45,770 INFO org.apache.hadoop.yarn.server.resourcemanager.rmapp.attempt.RMAppAttemptImpl: appattempt_1669272252091_0002_000001 State change from NEW to SUBMITTED on event = START
2022-11-24 06:57:45,770 INFO org.apache.hadoop.yarn.server.resourcemanager.scheduler.capacity.LeafQueue: Application application_1669272252091_0002 from user: hive activated in queue: default
2022-11-24 06:57:45,770 INFO org.apache.hadoop.yarn.server.resourcemanager.scheduler.capacity.LeafQueue: Application added - appId: application_1669272252091_0002 user: hive, leaf-queue: default #user-pending-applications: 0 #user-active-applications: 1 #queue-pending-applications: 0 #queue-active-applications: 1
2022-11-24 06:57:45,770 INFO org.apache.hadoop.yarn.server.resourcemanager.scheduler.capacity.CapacityScheduler: Added Application Attempt appattempt_1669272252091_0002_000001 to scheduler from user hive in queue default
2022-11-24 06:57:45,771 INFO org.apache.hadoop.yarn.server.resourcemanager.rmapp.attempt.RMAppAttemptImpl: appattempt_1669272252091_0002_000001 State change from SUBMITTED to SCHEDULED on event = ATTEMPT_ADDED
2022-11-24 06:57:46,030 INFO org.apache.hadoop.yarn.server.resourcemanager.scheduler.capacity.allocator.AbstractContainerAllocator: assignedContainer application attempt=appattempt_1669272252091_0002_000001 container=null queue=default clusterResource=<memory:21171, vCores:6> type=OFF_SWITCH requestedPartition=
2022-11-24 06:57:46,031 INFO org.apache.hadoop.yarn.server.resourcemanager.rmcontainer.RMContainerImpl: container_1669272252091_0002_01_000001 Container Transitioned from NEW to ALLOCATED
2022-11-24 06:57:46,031 INFO org.apache.hadoop.yarn.server.resourcemanager.scheduler.common.fica.FiCaSchedulerNode: Assigned container container_1669272252091_0002_01_000001 of capacity <memory:1024, vCores:1> on host adh-hack-02-mnode1.ru-central1.internal:8041, which has 1 containers, <memory:1024, vCores:1> used and <memory:6033, vCores:1> available after allocation
2022-11-24 06:57:46,031 INFO org.apache.hadoop.yarn.server.resourcemanager.RMAuditLogger: USER=hive	OPERATION=AM Allocated Container	TARGET=SchedulerApp	RESULT=SUCCESS	APPID=application_1669272252091_0002	CONTAINERID=container_1669272252091_0002_01_000001	RESOURCE=<memory:1024, vCores:1>	QUEUENAME=default
2022-11-24 06:57:46,033 INFO org.apache.hadoop.yarn.server.resourcemanager.security.NMTokenSecretManagerInRM: Sending NMToken for nodeId : adh-hack-02-mnode1.ru-central1.internal:8041 for container : container_1669272252091_0002_01_000001
2022-11-24 06:57:46,034 INFO org.apache.hadoop.yarn.server.resourcemanager.rmcontainer.RMContainerImpl: container_1669272252091_0002_01_000001 Container Transitioned from ALLOCATED to ACQUIRED
2022-11-24 06:57:46,034 INFO org.apache.hadoop.yarn.server.resourcemanager.security.NMTokenSecretManagerInRM: Clear node set for appattempt_1669272252091_0002_000001
2022-11-24 06:57:46,034 INFO org.apache.hadoop.yarn.server.resourcemanager.rmapp.attempt.RMAppAttemptImpl: Storing attempt: AppId: application_1669272252091_0002 AttemptId: appattempt_1669272252091_0002_000001 MasterContainer: Container: [ContainerId: container_1669272252091_0002_01_000001, AllocationRequestId: -1, Version: 0, NodeId: adh-hack-02-mnode1.ru-central1.internal:8041, NodeHttpAddress: adh-hack-02-mnode1.ru-central1.internal:8042, Resource: <memory:1024, vCores:1>, Priority: 0, Token: Token { kind: ContainerToken, service: 10.129.0.153:8041 }, ExecutionType: GUARANTEED, ]
2022-11-24 06:57:46,034 INFO org.apache.hadoop.yarn.server.resourcemanager.scheduler.capacity.ParentQueue: assignedContainer queue=root usedCapacity=0.04836805 absoluteUsedCapacity=0.04836805 used=<memory:1024, vCores:1> cluster=<memory:21171, vCores:6>
2022-11-24 06:57:46,034 INFO org.apache.hadoop.yarn.server.resourcemanager.scheduler.capacity.CapacityScheduler: Allocation proposal accepted
2022-11-24 06:57:46,035 INFO org.apache.hadoop.yarn.server.resourcemanager.rmapp.attempt.RMAppAttemptImpl: appattempt_1669272252091_0002_000001 State change from SCHEDULED to ALLOCATED_SAVING on event = CONTAINER_ALLOCATED
2022-11-24 06:57:46,035 INFO org.apache.hadoop.yarn.server.resourcemanager.rmapp.attempt.RMAppAttemptImpl: appattempt_1669272252091_0002_000001 State change from ALLOCATED_SAVING to ALLOCATED on event = ATTEMPT_NEW_SAVED
2022-11-24 06:57:46,036 INFO org.apache.hadoop.yarn.server.resourcemanager.amlauncher.AMLauncher: Launching masterappattempt_1669272252091_0002_000001
2022-11-24 06:57:46,039 INFO org.apache.hadoop.yarn.server.resourcemanager.amlauncher.AMLauncher: Setting up container Container: [ContainerId: container_1669272252091_0002_01_000001, AllocationRequestId: -1, Version: 0, NodeId: adh-hack-02-mnode1.ru-central1.internal:8041, NodeHttpAddress: adh-hack-02-mnode1.ru-central1.internal:8042, Resource: <memory:1024, vCores:1>, Priority: 0, Token: Token { kind: ContainerToken, service: 10.129.0.153:8041 }, ExecutionType: GUARANTEED, ] for AM appattempt_1669272252091_0002_000001
2022-11-24 06:57:46,039 INFO org.apache.hadoop.yarn.server.resourcemanager.security.AMRMTokenSecretManager: Create AMRMToken for ApplicationAttempt: appattempt_1669272252091_0002_000001
2022-11-24 06:57:46,039 INFO org.apache.hadoop.yarn.server.resourcemanager.security.AMRMTokenSecretManager: Creating password for appattempt_1669272252091_0002_000001
2022-11-24 06:57:46,055 INFO org.apache.hadoop.yarn.server.resourcemanager.amlauncher.AMLauncher: Done launching container Container: [ContainerId: container_1669272252091_0002_01_000001, AllocationRequestId: -1, Version: 0, NodeId: adh-hack-02-mnode1.ru-central1.internal:8041, NodeHttpAddress: adh-hack-02-mnode1.ru-central1.internal:8042, Resource: <memory:1024, vCores:1>, Priority: 0, Token: Token { kind: ContainerToken, service: 10.129.0.153:8041 }, ExecutionType: GUARANTEED, ] for AM appattempt_1669272252091_0002_000001
2022-11-24 06:57:46,055 INFO org.apache.hadoop.yarn.server.resourcemanager.rmapp.attempt.RMAppAttemptImpl: appattempt_1669272252091_0002_000001 State change from ALLOCATED to LAUNCHED on event = LAUNCHED
2022-11-24 06:57:47,036 INFO org.apache.hadoop.yarn.server.resourcemanager.rmcontainer.RMContainerImpl: container_1669272252091_0002_01_000001 Container Transitioned from ACQUIRED to RUNNING
2022-11-24 06:57:49,495 INFO SecurityLogger.org.apache.hadoop.ipc.Server: Auth successful for appattempt_1669272252091_0002_000001 (auth:SIMPLE)
2022-11-24 06:57:49,499 INFO org.apache.hadoop.yarn.server.resourcemanager.DefaultAMSProcessor: AM registration appattempt_1669272252091_0002_000001
2022-11-24 06:57:49,499 INFO org.apache.hadoop.yarn.server.resourcemanager.RMAuditLogger: USER=hive	IP=10.129.0.153	OPERATION=Register App Master	TARGET=ApplicationMasterService	RESULT=SUCCESS	APPID=application_1669272252091_0002	APPATTEMPTID=appattempt_1669272252091_0002_000001
2022-11-24 06:57:49,500 INFO org.apache.hadoop.yarn.server.resourcemanager.rmapp.attempt.RMAppAttemptImpl: appattempt_1669272252091_0002_000001 State change from LAUNCHED to RUNNING on event = REGISTERED
2022-11-24 06:57:49,501 INFO org.apache.hadoop.yarn.server.resourcemanager.rmapp.RMAppImpl: application_1669272252091_0002 State change from ACCEPTED to RUNNING on event = ATTEMPT_REGISTERED
2022-11-24 06:59:51,505 INFO org.apache.hadoop.yarn.server.resourcemanager.ClientRMService: Allocated new applicationId: 3
2022-11-24 06:59:51,618 INFO org.apache.hadoop.yarn.server.resourcemanager.ClientRMService: Allocated new applicationId: 4
2022-11-24 06:59:51,620 INFO org.apache.hadoop.yarn.server.resourcemanager.ClientRMService: Allocated new applicationId: 5
2022-11-24 06:59:52,077 INFO org.apache.hadoop.yarn.server.resourcemanager.scheduler.capacity.CapacityScheduler: Application 'application_1669272252091_0003' is submitted without priority hence considering default queue/cluster priority: 0
2022-11-24 06:59:52,077 INFO org.apache.hadoop.yarn.server.resourcemanager.scheduler.capacity.CapacityScheduler: Priority '0' is acceptable in queue : default for application: application_1669272252091_0003
2022-11-24 06:59:52,077 INFO org.apache.hadoop.yarn.server.resourcemanager.ClientRMService: Application with id 3 submitted by user hive
2022-11-24 06:59:52,077 INFO org.apache.hadoop.yarn.server.resourcemanager.RMAuditLogger: USER=hive	IP=10.129.0.154	OPERATION=Submit Application Request	TARGET=ClientRMService	RESULT=SUCCESS	APPID=application_1669272252091_0003	CALLERCONTEXT=CLI	QUEUENAME=default
2022-11-24 06:59:52,095 INFO org.apache.hadoop.yarn.server.resourcemanager.rmapp.RMAppImpl: Storing application with id application_1669272252091_0003
2022-11-24 06:59:52,095 INFO org.apache.hadoop.yarn.server.resourcemanager.recovery.RMStateStore: Storing info for app: application_1669272252091_0003
2022-11-24 06:59:52,095 INFO org.apache.hadoop.yarn.server.resourcemanager.rmapp.RMAppImpl: application_1669272252091_0003 State change from NEW to NEW_SAVING on event = START
2022-11-24 06:59:52,097 INFO org.apache.hadoop.yarn.server.resourcemanager.rmapp.RMAppImpl: application_1669272252091_0003 State change from NEW_SAVING to SUBMITTED on event = APP_NEW_SAVED
2022-11-24 06:59:52,097 INFO org.apache.hadoop.yarn.server.resourcemanager.scheduler.capacity.ParentQueue: Application added - appId: application_1669272252091_0003 user: hive leaf-queue of parent: root #applications: 2
2022-11-24 06:59:52,097 INFO org.apache.hadoop.yarn.server.resourcemanager.scheduler.capacity.CapacityScheduler: Accepted application application_1669272252091_0003 from user: hive, in queue: default
2022-11-24 06:59:52,098 INFO org.apache.hadoop.yarn.server.resourcemanager.rmapp.RMAppImpl: application_1669272252091_0003 State change from SUBMITTED to ACCEPTED on event = APP_ACCEPTED
2022-11-24 06:59:52,098 INFO org.apache.hadoop.yarn.server.resourcemanager.ApplicationMasterService: Registering app attempt : appattempt_1669272252091_0003_000001
2022-11-24 06:59:52,098 INFO org.apache.hadoop.yarn.server.resourcemanager.rmapp.attempt.RMAppAttemptImpl: appattempt_1669272252091_0003_000001 State change from NEW to SUBMITTED on event = START
2022-11-24 06:59:52,098 INFO org.apache.hadoop.yarn.server.resourcemanager.scheduler.capacity.LeafQueue: Application application_1669272252091_0003 from user: hive activated in queue: default
2022-11-24 06:59:52,098 INFO org.apache.hadoop.yarn.server.resourcemanager.scheduler.capacity.LeafQueue: Application added - appId: application_1669272252091_0003 user: hive, leaf-queue: default #user-pending-applications: 0 #user-active-applications: 2 #queue-pending-applications: 0 #queue-active-applications: 2
2022-11-24 06:59:52,098 INFO org.apache.hadoop.yarn.server.resourcemanager.scheduler.capacity.CapacityScheduler: Added Application Attempt appattempt_1669272252091_0003_000001 to scheduler from user hive in queue default
2022-11-24 06:59:52,099 INFO org.apache.hadoop.yarn.server.resourcemanager.rmapp.attempt.RMAppAttemptImpl: appattempt_1669272252091_0003_000001 State change from SUBMITTED to SCHEDULED on event = ATTEMPT_ADDED
2022-11-24 06:59:52,227 INFO org.apache.hadoop.yarn.server.resourcemanager.scheduler.capacity.CapacityScheduler: Application 'application_1669272252091_0005' is submitted without priority hence considering default queue/cluster priority: 0
2022-11-24 06:59:52,227 INFO org.apache.hadoop.yarn.server.resourcemanager.scheduler.capacity.CapacityScheduler: Priority '0' is acceptable in queue : default for application: application_1669272252091_0005
2022-11-24 06:59:52,227 INFO org.apache.hadoop.yarn.server.resourcemanager.ClientRMService: Application with id 5 submitted by user hive
2022-11-24 06:59:52,227 INFO org.apache.hadoop.yarn.server.resourcemanager.RMAuditLogger: USER=hive	IP=10.129.0.153	OPERATION=Submit Application Request	TARGET=ClientRMService	RESULT=SUCCESS	APPID=application_1669272252091_0005	CALLERCONTEXT=CLI	QUEUENAME=default
2022-11-24 06:59:52,228 INFO org.apache.hadoop.yarn.server.resourcemanager.rmapp.RMAppImpl: Storing application with id application_1669272252091_0005
2022-11-24 06:59:52,229 INFO org.apache.hadoop.yarn.server.resourcemanager.rmapp.RMAppImpl: application_1669272252091_0005 State change from NEW to NEW_SAVING on event = START
2022-11-24 06:59:52,229 INFO org.apache.hadoop.yarn.server.resourcemanager.recovery.RMStateStore: Storing info for app: application_1669272252091_0005
2022-11-24 06:59:52,230 INFO org.apache.hadoop.yarn.server.resourcemanager.rmapp.RMAppImpl: application_1669272252091_0005 State change from NEW_SAVING to SUBMITTED on event = APP_NEW_SAVED
2022-11-24 06:59:52,230 INFO org.apache.hadoop.yarn.server.resourcemanager.scheduler.capacity.ParentQueue: Application added - appId: application_1669272252091_0005 user: hive leaf-queue of parent: root #applications: 3
2022-11-24 06:59:52,230 INFO org.apache.hadoop.yarn.server.resourcemanager.scheduler.capacity.CapacityScheduler: Accepted application application_1669272252091_0005 from user: hive, in queue: default
2022-11-24 06:59:52,230 INFO org.apache.hadoop.yarn.server.resourcemanager.rmapp.RMAppImpl: application_1669272252091_0005 State change from SUBMITTED to ACCEPTED on event = APP_ACCEPTED
2022-11-24 06:59:52,230 INFO org.apache.hadoop.yarn.server.resourcemanager.ApplicationMasterService: Registering app attempt : appattempt_1669272252091_0005_000001
2022-11-24 06:59:52,230 INFO org.apache.hadoop.yarn.server.resourcemanager.rmapp.attempt.RMAppAttemptImpl: appattempt_1669272252091_0005_000001 State change from NEW to SUBMITTED on event = START
2022-11-24 06:59:52,231 INFO org.apache.hadoop.yarn.server.resourcemanager.scheduler.capacity.LeafQueue: Application application_1669272252091_0005 from user: hive activated in queue: default
2022-11-24 06:59:52,231 INFO org.apache.hadoop.yarn.server.resourcemanager.scheduler.capacity.LeafQueue: Application added - appId: application_1669272252091_0005 user: hive, leaf-queue: default #user-pending-applications: 0 #user-active-applications: 3 #queue-pending-applications: 0 #queue-active-applications: 3
2022-11-24 06:59:52,231 INFO org.apache.hadoop.yarn.server.resourcemanager.scheduler.capacity.CapacityScheduler: Added Application Attempt appattempt_1669272252091_0005_000001 to scheduler from user hive in queue default
2022-11-24 06:59:52,233 INFO org.apache.hadoop.yarn.server.resourcemanager.rmapp.attempt.RMAppAttemptImpl: appattempt_1669272252091_0005_000001 State change from SUBMITTED to SCHEDULED on event = ATTEMPT_ADDED
2022-11-24 06:59:52,254 INFO org.apache.hadoop.yarn.server.resourcemanager.scheduler.capacity.allocator.AbstractContainerAllocator: assignedContainer application attempt=appattempt_1669272252091_0003_000001 container=null queue=default clusterResource=<memory:21171, vCores:6> type=OFF_SWITCH requestedPartition=
2022-11-24 06:59:52,255 INFO org.apache.hadoop.yarn.server.resourcemanager.rmcontainer.RMContainerImpl: container_1669272252091_0003_01_000001 Container Transitioned from NEW to ALLOCATED
2022-11-24 06:59:52,255 INFO org.apache.hadoop.yarn.server.resourcemanager.scheduler.common.fica.FiCaSchedulerNode: Assigned container container_1669272252091_0003_01_000001 of capacity <memory:1024, vCores:1> on host adh-hack-02-mnode1.ru-central1.internal:8041, which has 2 containers, <memory:2048, vCores:2> used and <memory:5009, vCores:0> available after allocation
2022-11-24 06:59:52,255 INFO org.apache.hadoop.yarn.server.resourcemanager.RMAuditLogger: USER=hive	OPERATION=AM Allocated Container	TARGET=SchedulerApp	RESULT=SUCCESS	APPID=application_1669272252091_0003	CONTAINERID=container_1669272252091_0003_01_000001	RESOURCE=<memory:1024, vCores:1>	QUEUENAME=default
2022-11-24 06:59:52,255 INFO org.apache.hadoop.yarn.server.resourcemanager.scheduler.capacity.ParentQueue: assignedContainer queue=root usedCapacity=0.0967361 absoluteUsedCapacity=0.0967361 used=<memory:2048, vCores:2> cluster=<memory:21171, vCores:6>
2022-11-24 06:59:52,255 INFO org.apache.hadoop.yarn.server.resourcemanager.scheduler.capacity.CapacityScheduler: Allocation proposal accepted
2022-11-24 06:59:52,256 INFO org.apache.hadoop.yarn.server.resourcemanager.security.NMTokenSecretManagerInRM: Sending NMToken for nodeId : adh-hack-02-mnode1.ru-central1.internal:8041 for container : container_1669272252091_0003_01_000001
2022-11-24 06:59:52,258 INFO org.apache.hadoop.yarn.server.resourcemanager.rmcontainer.RMContainerImpl: container_1669272252091_0003_01_000001 Container Transitioned from ALLOCATED to ACQUIRED
2022-11-24 06:59:52,258 INFO org.apache.hadoop.yarn.server.resourcemanager.security.NMTokenSecretManagerInRM: Clear node set for appattempt_1669272252091_0003_000001
2022-11-24 06:59:52,258 INFO org.apache.hadoop.yarn.server.resourcemanager.rmapp.attempt.RMAppAttemptImpl: Storing attempt: AppId: application_1669272252091_0003 AttemptId: appattempt_1669272252091_0003_000001 MasterContainer: Container: [ContainerId: container_1669272252091_0003_01_000001, AllocationRequestId: -1, Version: 0, NodeId: adh-hack-02-mnode1.ru-central1.internal:8041, NodeHttpAddress: adh-hack-02-mnode1.ru-central1.internal:8042, Resource: <memory:1024, vCores:1>, Priority: 0, Token: Token { kind: ContainerToken, service: 10.129.0.153:8041 }, ExecutionType: GUARANTEED, ]
2022-11-24 06:59:52,258 INFO org.apache.hadoop.yarn.server.resourcemanager.rmapp.attempt.RMAppAttemptImpl: appattempt_1669272252091_0003_000001 State change from SCHEDULED to ALLOCATED_SAVING on event = CONTAINER_ALLOCATED
2022-11-24 06:59:52,259 INFO org.apache.hadoop.yarn.server.resourcemanager.rmapp.attempt.RMAppAttemptImpl: appattempt_1669272252091_0003_000001 State change from ALLOCATED_SAVING to ALLOCATED on event = ATTEMPT_NEW_SAVED
2022-11-24 06:59:52,261 INFO org.apache.hadoop.yarn.server.resourcemanager.amlauncher.AMLauncher: Launching masterappattempt_1669272252091_0003_000001
2022-11-24 06:59:52,263 INFO org.apache.hadoop.yarn.server.resourcemanager.amlauncher.AMLauncher: Setting up container Container: [ContainerId: container_1669272252091_0003_01_000001, AllocationRequestId: -1, Version: 0, NodeId: adh-hack-02-mnode1.ru-central1.internal:8041, NodeHttpAddress: adh-hack-02-mnode1.ru-central1.internal:8042, Resource: <memory:1024, vCores:1>, Priority: 0, Token: Token { kind: ContainerToken, service: 10.129.0.153:8041 }, ExecutionType: GUARANTEED, ] for AM appattempt_1669272252091_0003_000001
2022-11-24 06:59:52,263 INFO org.apache.hadoop.yarn.server.resourcemanager.security.AMRMTokenSecretManager: Create AMRMToken for ApplicationAttempt: appattempt_1669272252091_0003_000001
2022-11-24 06:59:52,263 INFO org.apache.hadoop.yarn.server.resourcemanager.security.AMRMTokenSecretManager: Creating password for appattempt_1669272252091_0003_000001
2022-11-24 06:59:52,286 INFO org.apache.hadoop.yarn.server.resourcemanager.amlauncher.AMLauncher: Done launching container Container: [ContainerId: container_1669272252091_0003_01_000001, AllocationRequestId: -1, Version: 0, NodeId: adh-hack-02-mnode1.ru-central1.internal:8041, NodeHttpAddress: adh-hack-02-mnode1.ru-central1.internal:8042, Resource: <memory:1024, vCores:1>, Priority: 0, Token: Token { kind: ContainerToken, service: 10.129.0.153:8041 }, ExecutionType: GUARANTEED, ] for AM appattempt_1669272252091_0003_000001
2022-11-24 06:59:52,286 INFO org.apache.hadoop.yarn.server.resourcemanager.rmapp.attempt.RMAppAttemptImpl: appattempt_1669272252091_0003_000001 State change from ALLOCATED to LAUNCHED on event = LAUNCHED
2022-11-24 06:59:52,343 INFO org.apache.hadoop.yarn.server.resourcemanager.scheduler.capacity.CapacityScheduler: Application 'application_1669272252091_0004' is submitted without priority hence considering default queue/cluster priority: 0
2022-11-24 06:59:52,344 INFO org.apache.hadoop.yarn.server.resourcemanager.scheduler.capacity.CapacityScheduler: Priority '0' is acceptable in queue : default for application: application_1669272252091_0004
2022-11-24 06:59:52,344 INFO org.apache.hadoop.yarn.server.resourcemanager.ClientRMService: Application with id 4 submitted by user hive
2022-11-24 06:59:52,344 INFO org.apache.hadoop.yarn.server.resourcemanager.RMAuditLogger: USER=hive	IP=10.129.0.155	OPERATION=Submit Application Request	TARGET=ClientRMService	RESULT=SUCCESS	APPID=application_1669272252091_0004	CALLERCONTEXT=CLI	QUEUENAME=default
2022-11-24 06:59:52,345 INFO org.apache.hadoop.yarn.server.resourcemanager.rmapp.RMAppImpl: Storing application with id application_1669272252091_0004
2022-11-24 06:59:52,345 INFO org.apache.hadoop.yarn.server.resourcemanager.recovery.RMStateStore: Storing info for app: application_1669272252091_0004
2022-11-24 06:59:52,345 INFO org.apache.hadoop.yarn.server.resourcemanager.rmapp.RMAppImpl: application_1669272252091_0004 State change from NEW to NEW_SAVING on event = START
2022-11-24 06:59:52,348 INFO org.apache.hadoop.yarn.server.resourcemanager.rmapp.RMAppImpl: application_1669272252091_0004 State change from NEW_SAVING to SUBMITTED on event = APP_NEW_SAVED
2022-11-24 06:59:52,348 INFO org.apache.hadoop.yarn.server.resourcemanager.scheduler.capacity.ParentQueue: Application added - appId: application_1669272252091_0004 user: hive leaf-queue of parent: root #applications: 4
2022-11-24 06:59:52,349 INFO org.apache.hadoop.yarn.server.resourcemanager.scheduler.capacity.CapacityScheduler: Accepted application application_1669272252091_0004 from user: hive, in queue: default
2022-11-24 06:59:52,349 INFO org.apache.hadoop.yarn.server.resourcemanager.rmapp.RMAppImpl: application_1669272252091_0004 State change from SUBMITTED to ACCEPTED on event = APP_ACCEPTED
2022-11-24 06:59:52,349 INFO org.apache.hadoop.yarn.server.resourcemanager.ApplicationMasterService: Registering app attempt : appattempt_1669272252091_0004_000001
2022-11-24 06:59:52,349 INFO org.apache.hadoop.yarn.server.resourcemanager.rmapp.attempt.RMAppAttemptImpl: appattempt_1669272252091_0004_000001 State change from NEW to SUBMITTED on event = START
2022-11-24 06:59:52,351 INFO org.apache.hadoop.yarn.server.resourcemanager.scheduler.capacity.LeafQueue: Application application_1669272252091_0004 from user: hive activated in queue: default
2022-11-24 06:59:52,351 INFO org.apache.hadoop.yarn.server.resourcemanager.scheduler.capacity.LeafQueue: Application added - appId: application_1669272252091_0004 user: hive, leaf-queue: default #user-pending-applications: 0 #user-active-applications: 4 #queue-pending-applications: 0 #queue-active-applications: 4
2022-11-24 06:59:52,351 INFO org.apache.hadoop.yarn.server.resourcemanager.scheduler.capacity.CapacityScheduler: Added Application Attempt appattempt_1669272252091_0004_000001 to scheduler from user hive in queue default
2022-11-24 06:59:52,352 INFO org.apache.hadoop.yarn.server.resourcemanager.rmapp.attempt.RMAppAttemptImpl: appattempt_1669272252091_0004_000001 State change from SUBMITTED to SCHEDULED on event = ATTEMPT_ADDED
2022-11-24 06:59:52,528 INFO org.apache.hadoop.yarn.server.resourcemanager.scheduler.capacity.allocator.AbstractContainerAllocator: assignedContainer application attempt=appattempt_1669272252091_0004_000001 container=null queue=default clusterResource=<memory:21171, vCores:6> type=OFF_SWITCH requestedPartition=
2022-11-24 06:59:52,528 INFO org.apache.hadoop.yarn.server.resourcemanager.rmcontainer.RMContainerImpl: container_1669272252091_0004_01_000001 Container Transitioned from NEW to ALLOCATED
2022-11-24 06:59:52,528 INFO org.apache.hadoop.yarn.server.resourcemanager.scheduler.common.fica.FiCaSchedulerNode: Assigned container container_1669272252091_0004_01_000001 of capacity <memory:1024, vCores:1> on host adh-hack-02-mnode3.ru-central1.internal:8041, which has 1 containers, <memory:1024, vCores:1> used and <memory:6033, vCores:1> available after allocation
2022-11-24 06:59:52,529 INFO org.apache.hadoop.yarn.server.resourcemanager.RMAuditLogger: USER=hive	OPERATION=AM Allocated Container	TARGET=SchedulerApp	RESULT=SUCCESS	APPID=application_1669272252091_0004	CONTAINERID=container_1669272252091_0004_01_000001	RESOURCE=<memory:1024, vCores:1>	QUEUENAME=default
2022-11-24 06:59:52,529 INFO org.apache.hadoop.yarn.server.resourcemanager.security.NMTokenSecretManagerInRM: Sending NMToken for nodeId : adh-hack-02-mnode3.ru-central1.internal:8041 for container : container_1669272252091_0004_01_000001
2022-11-24 06:59:52,530 INFO org.apache.hadoop.yarn.server.resourcemanager.rmcontainer.RMContainerImpl: container_1669272252091_0004_01_000001 Container Transitioned from ALLOCATED to ACQUIRED
2022-11-24 06:59:52,530 INFO org.apache.hadoop.yarn.server.resourcemanager.security.NMTokenSecretManagerInRM: Clear node set for appattempt_1669272252091_0004_000001
2022-11-24 06:59:52,531 INFO org.apache.hadoop.yarn.server.resourcemanager.rmapp.attempt.RMAppAttemptImpl: Storing attempt: AppId: application_1669272252091_0004 AttemptId: appattempt_1669272252091_0004_000001 MasterContainer: Container: [ContainerId: container_1669272252091_0004_01_000001, AllocationRequestId: -1, Version: 0, NodeId: adh-hack-02-mnode3.ru-central1.internal:8041, NodeHttpAddress: adh-hack-02-mnode3.ru-central1.internal:8042, Resource: <memory:1024, vCores:1>, Priority: 0, Token: Token { kind: ContainerToken, service: 10.129.0.155:8041 }, ExecutionType: GUARANTEED, ]
2022-11-24 06:59:52,531 INFO org.apache.hadoop.yarn.server.resourcemanager.rmapp.attempt.RMAppAttemptImpl: appattempt_1669272252091_0004_000001 State change from SCHEDULED to ALLOCATED_SAVING on event = CONTAINER_ALLOCATED
2022-11-24 06:59:52,532 INFO org.apache.hadoop.yarn.server.resourcemanager.scheduler.capacity.ParentQueue: assignedContainer queue=root usedCapacity=0.14510415 absoluteUsedCapacity=0.14510415 used=<memory:3072, vCores:3> cluster=<memory:21171, vCores:6>
2022-11-24 06:59:52,533 INFO org.apache.hadoop.yarn.server.resourcemanager.scheduler.capacity.CapacityScheduler: Allocation proposal accepted
2022-11-24 06:59:52,532 INFO org.apache.hadoop.yarn.server.resourcemanager.rmapp.attempt.RMAppAttemptImpl: appattempt_1669272252091_0004_000001 State change from ALLOCATED_SAVING to ALLOCATED on event = ATTEMPT_NEW_SAVED
2022-11-24 06:59:52,536 INFO org.apache.hadoop.yarn.server.resourcemanager.amlauncher.AMLauncher: Launching masterappattempt_1669272252091_0004_000001
2022-11-24 06:59:52,538 INFO org.apache.hadoop.yarn.server.resourcemanager.amlauncher.AMLauncher: Setting up container Container: [ContainerId: container_1669272252091_0004_01_000001, AllocationRequestId: -1, Version: 0, NodeId: adh-hack-02-mnode3.ru-central1.internal:8041, NodeHttpAddress: adh-hack-02-mnode3.ru-central1.internal:8042, Resource: <memory:1024, vCores:1>, Priority: 0, Token: Token { kind: ContainerToken, service: 10.129.0.155:8041 }, ExecutionType: GUARANTEED, ] for AM appattempt_1669272252091_0004_000001
2022-11-24 06:59:52,538 INFO org.apache.hadoop.yarn.server.resourcemanager.security.AMRMTokenSecretManager: Create AMRMToken for ApplicationAttempt: appattempt_1669272252091_0004_000001
2022-11-24 06:59:52,538 INFO org.apache.hadoop.yarn.server.resourcemanager.security.AMRMTokenSecretManager: Creating password for appattempt_1669272252091_0004_000001
2022-11-24 06:59:52,555 INFO org.apache.hadoop.yarn.server.resourcemanager.amlauncher.AMLauncher: Done launching container Container: [ContainerId: container_1669272252091_0004_01_000001, AllocationRequestId: -1, Version: 0, NodeId: adh-hack-02-mnode3.ru-central1.internal:8041, NodeHttpAddress: adh-hack-02-mnode3.ru-central1.internal:8042, Resource: <memory:1024, vCores:1>, Priority: 0, Token: Token { kind: ContainerToken, service: 10.129.0.155:8041 }, ExecutionType: GUARANTEED, ] for AM appattempt_1669272252091_0004_000001
2022-11-24 06:59:52,556 INFO org.apache.hadoop.yarn.server.resourcemanager.rmapp.attempt.RMAppAttemptImpl: appattempt_1669272252091_0004_000001 State change from ALLOCATED to LAUNCHED on event = LAUNCHED
2022-11-24 06:59:52,778 INFO org.apache.hadoop.yarn.server.resourcemanager.scheduler.capacity.allocator.AbstractContainerAllocator: assignedContainer application attempt=appattempt_1669272252091_0005_000001 container=null queue=default clusterResource=<memory:21171, vCores:6> type=OFF_SWITCH requestedPartition=
2022-11-24 06:59:52,785 INFO org.apache.hadoop.yarn.server.resourcemanager.rmcontainer.RMContainerImpl: container_1669272252091_0005_01_000001 Container Transitioned from NEW to ALLOCATED
2022-11-24 06:59:52,785 INFO org.apache.hadoop.yarn.server.resourcemanager.scheduler.common.fica.FiCaSchedulerNode: Assigned container container_1669272252091_0005_01_000001 of capacity <memory:1024, vCores:1> on host adh-hack-02-mnode2.ru-central1.internal:8041, which has 1 containers, <memory:1024, vCores:1> used and <memory:6033, vCores:1> available after allocation
2022-11-24 06:59:52,785 INFO org.apache.hadoop.yarn.server.resourcemanager.RMAuditLogger: USER=hive	OPERATION=AM Allocated Container	TARGET=SchedulerApp	RESULT=SUCCESS	APPID=application_1669272252091_0005	CONTAINERID=container_1669272252091_0005_01_000001	RESOURCE=<memory:1024, vCores:1>	QUEUENAME=default
2022-11-24 06:59:52,785 INFO org.apache.hadoop.yarn.server.resourcemanager.scheduler.capacity.ParentQueue: assignedContainer queue=root usedCapacity=0.1934722 absoluteUsedCapacity=0.1934722 used=<memory:4096, vCores:4> cluster=<memory:21171, vCores:6>
2022-11-24 06:59:52,785 INFO org.apache.hadoop.yarn.server.resourcemanager.scheduler.capacity.CapacityScheduler: Allocation proposal accepted
2022-11-24 06:59:52,787 INFO org.apache.hadoop.yarn.server.resourcemanager.security.NMTokenSecretManagerInRM: Sending NMToken for nodeId : adh-hack-02-mnode2.ru-central1.internal:8041 for container : container_1669272252091_0005_01_000001
2022-11-24 06:59:52,789 INFO org.apache.hadoop.yarn.server.resourcemanager.rmcontainer.RMContainerImpl: container_1669272252091_0005_01_000001 Container Transitioned from ALLOCATED to ACQUIRED
2022-11-24 06:59:52,790 INFO org.apache.hadoop.yarn.server.resourcemanager.security.NMTokenSecretManagerInRM: Clear node set for appattempt_1669272252091_0005_000001
2022-11-24 06:59:52,790 INFO org.apache.hadoop.yarn.server.resourcemanager.rmapp.attempt.RMAppAttemptImpl: Storing attempt: AppId: application_1669272252091_0005 AttemptId: appattempt_1669272252091_0005_000001 MasterContainer: Container: [ContainerId: container_1669272252091_0005_01_000001, AllocationRequestId: -1, Version: 0, NodeId: adh-hack-02-mnode2.ru-central1.internal:8041, NodeHttpAddress: adh-hack-02-mnode2.ru-central1.internal:8042, Resource: <memory:1024, vCores:1>, Priority: 0, Token: Token { kind: ContainerToken, service: 10.129.0.154:8041 }, ExecutionType: GUARANTEED, ]
2022-11-24 06:59:52,790 INFO org.apache.hadoop.yarn.server.resourcemanager.rmapp.attempt.RMAppAttemptImpl: appattempt_1669272252091_0005_000001 State change from SCHEDULED to ALLOCATED_SAVING on event = CONTAINER_ALLOCATED
2022-11-24 06:59:52,791 INFO org.apache.hadoop.yarn.server.resourcemanager.rmapp.attempt.RMAppAttemptImpl: appattempt_1669272252091_0005_000001 State change from ALLOCATED_SAVING to ALLOCATED on event = ATTEMPT_NEW_SAVED
2022-11-24 06:59:52,791 INFO org.apache.hadoop.yarn.server.resourcemanager.amlauncher.AMLauncher: Launching masterappattempt_1669272252091_0005_000001
2022-11-24 06:59:52,793 INFO org.apache.hadoop.yarn.server.resourcemanager.amlauncher.AMLauncher: Setting up container Container: [ContainerId: container_1669272252091_0005_01_000001, AllocationRequestId: -1, Version: 0, NodeId: adh-hack-02-mnode2.ru-central1.internal:8041, NodeHttpAddress: adh-hack-02-mnode2.ru-central1.internal:8042, Resource: <memory:1024, vCores:1>, Priority: 0, Token: Token { kind: ContainerToken, service: 10.129.0.154:8041 }, ExecutionType: GUARANTEED, ] for AM appattempt_1669272252091_0005_000001
2022-11-24 06:59:52,793 INFO org.apache.hadoop.yarn.server.resourcemanager.security.AMRMTokenSecretManager: Create AMRMToken for ApplicationAttempt: appattempt_1669272252091_0005_000001
2022-11-24 06:59:52,793 INFO org.apache.hadoop.yarn.server.resourcemanager.security.AMRMTokenSecretManager: Creating password for appattempt_1669272252091_0005_000001
2022-11-24 06:59:52,845 INFO org.apache.hadoop.yarn.server.resourcemanager.amlauncher.AMLauncher: Done launching container Container: [ContainerId: container_1669272252091_0005_01_000001, AllocationRequestId: -1, Version: 0, NodeId: adh-hack-02-mnode2.ru-central1.internal:8041, NodeHttpAddress: adh-hack-02-mnode2.ru-central1.internal:8042, Resource: <memory:1024, vCores:1>, Priority: 0, Token: Token { kind: ContainerToken, service: 10.129.0.154:8041 }, ExecutionType: GUARANTEED, ] for AM appattempt_1669272252091_0005_000001
2022-11-24 06:59:52,846 INFO org.apache.hadoop.yarn.server.resourcemanager.rmapp.attempt.RMAppAttemptImpl: appattempt_1669272252091_0005_000001 State change from ALLOCATED to LAUNCHED on event = LAUNCHED
2022-11-24 06:59:53,256 INFO org.apache.hadoop.yarn.server.resourcemanager.rmcontainer.RMContainerImpl: container_1669272252091_0003_01_000001 Container Transitioned from ACQUIRED to RUNNING
2022-11-24 06:59:53,530 INFO org.apache.hadoop.yarn.server.resourcemanager.rmcontainer.RMContainerImpl: container_1669272252091_0004_01_000001 Container Transitioned from ACQUIRED to RUNNING
2022-11-24 06:59:53,778 INFO org.apache.hadoop.yarn.server.resourcemanager.rmcontainer.RMContainerImpl: container_1669272252091_0005_01_000001 Container Transitioned from ACQUIRED to RUNNING
2022-11-24 06:59:55,540 INFO SecurityLogger.org.apache.hadoop.ipc.Server: Auth successful for appattempt_1669272252091_0003_000001 (auth:SIMPLE)
2022-11-24 06:59:55,544 INFO org.apache.hadoop.yarn.server.resourcemanager.DefaultAMSProcessor: AM registration appattempt_1669272252091_0003_000001
2022-11-24 06:59:55,544 INFO org.apache.hadoop.yarn.server.resourcemanager.RMAuditLogger: USER=hive	IP=10.129.0.153	OPERATION=Register App Master	TARGET=ApplicationMasterService	RESULT=SUCCESS	APPID=application_1669272252091_0003	APPATTEMPTID=appattempt_1669272252091_0003_000001
2022-11-24 06:59:55,550 INFO org.apache.hadoop.yarn.server.resourcemanager.rmapp.attempt.RMAppAttemptImpl: appattempt_1669272252091_0003_000001 State change from LAUNCHED to RUNNING on event = REGISTERED
2022-11-24 06:59:55,550 INFO org.apache.hadoop.yarn.server.resourcemanager.rmapp.RMAppImpl: application_1669272252091_0003 State change from ACCEPTED to RUNNING on event = ATTEMPT_REGISTERED
2022-11-24 06:59:56,004 INFO SecurityLogger.org.apache.hadoop.ipc.Server: Auth successful for appattempt_1669272252091_0004_000001 (auth:SIMPLE)
2022-11-24 06:59:56,007 INFO org.apache.hadoop.yarn.server.resourcemanager.DefaultAMSProcessor: AM registration appattempt_1669272252091_0004_000001
2022-11-24 06:59:56,007 INFO org.apache.hadoop.yarn.server.resourcemanager.RMAuditLogger: USER=hive	IP=10.129.0.155	OPERATION=Register App Master	TARGET=ApplicationMasterService	RESULT=SUCCESS	APPID=application_1669272252091_0004	APPATTEMPTID=appattempt_1669272252091_0004_000001
2022-11-24 06:59:56,008 INFO org.apache.hadoop.yarn.server.resourcemanager.rmapp.attempt.RMAppAttemptImpl: appattempt_1669272252091_0004_000001 State change from LAUNCHED to RUNNING on event = REGISTERED
2022-11-24 06:59:56,008 INFO org.apache.hadoop.yarn.server.resourcemanager.rmapp.RMAppImpl: application_1669272252091_0004 State change from ACCEPTED to RUNNING on event = ATTEMPT_REGISTERED
2022-11-24 06:59:56,513 INFO SecurityLogger.org.apache.hadoop.ipc.Server: Auth successful for appattempt_1669272252091_0005_000001 (auth:SIMPLE)
2022-11-24 06:59:56,521 INFO org.apache.hadoop.yarn.server.resourcemanager.DefaultAMSProcessor: AM registration appattempt_1669272252091_0005_000001
2022-11-24 06:59:56,521 INFO org.apache.hadoop.yarn.server.resourcemanager.RMAuditLogger: USER=hive	IP=10.129.0.154	OPERATION=Register App Master	TARGET=ApplicationMasterService	RESULT=SUCCESS	APPID=application_1669272252091_0005	APPATTEMPTID=appattempt_1669272252091_0005_000001
2022-11-24 06:59:56,521 INFO org.apache.hadoop.yarn.server.resourcemanager.rmapp.attempt.RMAppAttemptImpl: appattempt_1669272252091_0005_000001 State change from LAUNCHED to RUNNING on event = REGISTERED
2022-11-24 06:59:56,521 INFO org.apache.hadoop.yarn.server.resourcemanager.rmapp.RMAppImpl: application_1669272252091_0005 State change from ACCEPTED to RUNNING on event = ATTEMPT_REGISTERED
2022-11-24 06:59:56,826 INFO org.apache.hadoop.yarn.server.resourcemanager.scheduler.capacity.allocator.AbstractContainerAllocator: assignedContainer application attempt=appattempt_1669272252091_0003_000001 container=null queue=default clusterResource=<memory:21171, vCores:6> type=NODE_LOCAL requestedPartition=
2022-11-24 06:59:56,826 INFO org.apache.hadoop.yarn.server.resourcemanager.rmcontainer.RMContainerImpl: container_1669272252091_0003_01_000002 Container Transitioned from NEW to ALLOCATED
2022-11-24 06:59:56,827 INFO org.apache.hadoop.yarn.server.resourcemanager.scheduler.common.fica.FiCaSchedulerNode: Assigned container container_1669272252091_0003_01_000002 of capacity <memory:1024, vCores:1> on host adh-hack-02-mnode2.ru-central1.internal:8041, which has 2 containers, <memory:2048, vCores:2> used and <memory:5009, vCores:0> available after allocation
2022-11-24 06:59:56,827 INFO org.apache.hadoop.yarn.server.resourcemanager.RMAuditLogger: USER=hive	OPERATION=AM Allocated Container	TARGET=SchedulerApp	RESULT=SUCCESS	APPID=application_1669272252091_0003	CONTAINERID=container_1669272252091_0003_01_000002	RESOURCE=<memory:1024, vCores:1>	QUEUENAME=default
2022-11-24 06:59:56,827 INFO org.apache.hadoop.yarn.server.resourcemanager.scheduler.capacity.ParentQueue: assignedContainer queue=root usedCapacity=0.24184026 absoluteUsedCapacity=0.24184026 used=<memory:5120, vCores:5> cluster=<memory:21171, vCores:6>
2022-11-24 06:59:56,827 INFO org.apache.hadoop.yarn.server.resourcemanager.scheduler.capacity.CapacityScheduler: Allocation proposal accepted
2022-11-24 06:59:57,272 INFO org.apache.hadoop.yarn.server.resourcemanager.scheduler.capacity.allocator.AbstractContainerAllocator: assignedContainer application attempt=appattempt_1669272252091_0004_000001 container=null queue=default clusterResource=<memory:21171, vCores:6> type=NODE_LOCAL requestedPartition=
2022-11-24 06:59:57,273 INFO org.apache.hadoop.yarn.server.resourcemanager.rmcontainer.RMContainerImpl: container_1669272252091_0004_01_000002 Container Transitioned from NEW to ALLOCATED
2022-11-24 06:59:57,273 INFO org.apache.hadoop.yarn.server.resourcemanager.scheduler.common.fica.FiCaSchedulerNode: Assigned container container_1669272252091_0004_01_000002 of capacity <memory:1024, vCores:1> on host adh-hack-02-mnode1.ru-central1.internal:8041, which has 3 containers, <memory:3072, vCores:3> used and <memory:3985, vCores:-1> available after allocation
2022-11-24 06:59:57,273 INFO org.apache.hadoop.yarn.server.resourcemanager.RMAuditLogger: USER=hive	OPERATION=AM Allocated Container	TARGET=SchedulerApp	RESULT=SUCCESS	APPID=application_1669272252091_0004	CONTAINERID=container_1669272252091_0004_01_000002	RESOURCE=<memory:1024, vCores:1>	QUEUENAME=default
2022-11-24 06:59:57,274 INFO org.apache.hadoop.yarn.server.resourcemanager.scheduler.capacity.ParentQueue: assignedContainer queue=root usedCapacity=0.2902083 absoluteUsedCapacity=0.2902083 used=<memory:6144, vCores:6> cluster=<memory:21171, vCores:6>
2022-11-24 06:59:57,274 INFO org.apache.hadoop.yarn.server.resourcemanager.scheduler.capacity.CapacityScheduler: Allocation proposal accepted
2022-11-24 06:59:57,749 INFO org.apache.hadoop.yarn.server.resourcemanager.security.NMTokenSecretManagerInRM: Sending NMToken for nodeId : adh-hack-02-mnode2.ru-central1.internal:8041 for container : container_1669272252091_0003_01_000002
2022-11-24 06:59:57,750 INFO org.apache.hadoop.yarn.server.resourcemanager.rmcontainer.RMContainerImpl: container_1669272252091_0003_01_000002 Container Transitioned from ALLOCATED to ACQUIRED
2022-11-24 06:59:57,830 INFO org.apache.hadoop.yarn.server.resourcemanager.scheduler.capacity.allocator.AbstractContainerAllocator: assignedContainer application attempt=appattempt_1669272252091_0005_000001 container=null queue=default clusterResource=<memory:21171, vCores:6> type=NODE_LOCAL requestedPartition=
2022-11-24 06:59:57,831 INFO org.apache.hadoop.yarn.server.resourcemanager.rmcontainer.RMContainerImpl: container_1669272252091_0005_01_000002 Container Transitioned from NEW to ALLOCATED
2022-11-24 06:59:57,831 INFO org.apache.hadoop.yarn.server.resourcemanager.scheduler.common.fica.FiCaSchedulerNode: Assigned container container_1669272252091_0005_01_000002 of capacity <memory:1024, vCores:1> on host adh-hack-02-mnode2.ru-central1.internal:8041, which has 3 containers, <memory:3072, vCores:3> used and <memory:3985, vCores:-1> available after allocation
2022-11-24 06:59:57,831 INFO org.apache.hadoop.yarn.server.resourcemanager.RMAuditLogger: USER=hive	OPERATION=AM Allocated Container	TARGET=SchedulerApp	RESULT=SUCCESS	APPID=application_1669272252091_0005	CONTAINERID=container_1669272252091_0005_01_000002	RESOURCE=<memory:1024, vCores:1>	QUEUENAME=default
2022-11-24 06:59:57,831 INFO org.apache.hadoop.yarn.server.resourcemanager.scheduler.capacity.ParentQueue: assignedContainer queue=root usedCapacity=0.33857635 absoluteUsedCapacity=0.33857635 used=<memory:7168, vCores:7> cluster=<memory:21171, vCores:6>
2022-11-24 06:59:57,831 INFO org.apache.hadoop.yarn.server.resourcemanager.scheduler.capacity.CapacityScheduler: Allocation proposal accepted
2022-11-24 06:59:58,227 INFO org.apache.hadoop.yarn.server.resourcemanager.security.NMTokenSecretManagerInRM: Sending NMToken for nodeId : adh-hack-02-mnode1.ru-central1.internal:8041 for container : container_1669272252091_0004_01_000002
2022-11-24 06:59:58,228 INFO org.apache.hadoop.yarn.server.resourcemanager.rmcontainer.RMContainerImpl: container_1669272252091_0004_01_000002 Container Transitioned from ALLOCATED to ACQUIRED
2022-11-24 06:59:58,765 INFO org.apache.hadoop.yarn.server.resourcemanager.scheduler.AppSchedulingInfo: checking for deactivate of application :application_1669272252091_0003
2022-11-24 06:59:58,799 INFO org.apache.hadoop.yarn.server.resourcemanager.security.NMTokenSecretManagerInRM: Sending NMToken for nodeId : adh-hack-02-mnode2.ru-central1.internal:8041 for container : container_1669272252091_0005_01_000002
2022-11-24 06:59:58,800 INFO org.apache.hadoop.yarn.server.resourcemanager.rmcontainer.RMContainerImpl: container_1669272252091_0005_01_000002 Container Transitioned from ALLOCATED to ACQUIRED
2022-11-24 06:59:58,843 INFO org.apache.hadoop.yarn.server.resourcemanager.rmcontainer.RMContainerImpl: container_1669272252091_0003_01_000002 Container Transitioned from ACQUIRED to RUNNING
2022-11-24 06:59:59,242 INFO org.apache.hadoop.yarn.server.resourcemanager.scheduler.AppSchedulingInfo: checking for deactivate of application :application_1669272252091_0004
2022-11-24 06:59:59,275 INFO org.apache.hadoop.yarn.server.resourcemanager.rmcontainer.RMContainerImpl: container_1669272252091_0004_01_000002 Container Transitioned from ACQUIRED to RUNNING
2022-11-24 06:59:59,812 INFO org.apache.hadoop.yarn.server.resourcemanager.scheduler.AppSchedulingInfo: checking for deactivate of application :application_1669272252091_0005
2022-11-24 06:59:59,848 INFO org.apache.hadoop.yarn.server.resourcemanager.rmcontainer.RMContainerImpl: container_1669272252091_0005_01_000002 Container Transitioned from ACQUIRED to RUNNING
2022-11-24 07:00:00,771 INFO org.apache.hadoop.yarn.server.resourcemanager.scheduler.AppSchedulingInfo: checking for deactivate of application :application_1669272252091_0003
2022-11-24 07:00:00,771 INFO org.apache.hadoop.yarn.server.resourcemanager.scheduler.AppSchedulingInfo: checking for deactivate of application :application_1669272252091_0003
2022-11-24 07:00:01,248 INFO org.apache.hadoop.yarn.server.resourcemanager.scheduler.AppSchedulingInfo: checking for deactivate of application :application_1669272252091_0004
2022-11-24 07:00:01,248 INFO org.apache.hadoop.yarn.server.resourcemanager.scheduler.AppSchedulingInfo: checking for deactivate of application :application_1669272252091_0004
2022-11-24 07:00:01,829 INFO org.apache.hadoop.yarn.server.resourcemanager.scheduler.AppSchedulingInfo: checking for deactivate of application :application_1669272252091_0005
2022-11-24 07:00:01,829 INFO org.apache.hadoop.yarn.server.resourcemanager.scheduler.AppSchedulingInfo: checking for deactivate of application :application_1669272252091_0005
2022-11-24 07:00:06,160 INFO org.apache.hadoop.yarn.server.resourcemanager.rmcontainer.RMContainerImpl: container_1669272252091_0004_01_000002 Container Transitioned from RUNNING to COMPLETED
2022-11-24 07:00:06,160 INFO org.apache.hadoop.yarn.server.resourcemanager.RMAuditLogger: USER=hive	OPERATION=AM Released Container	TARGET=SchedulerApp	RESULT=SUCCESS	APPID=application_1669272252091_0004	CONTAINERID=container_1669272252091_0004_01_000002	RESOURCE=<memory:1024, vCores:1>	QUEUENAME=default
2022-11-24 07:00:06,167 INFO org.apache.hadoop.yarn.server.resourcemanager.rmapp.attempt.RMAppAttemptImpl: Updating application attempt appattempt_1669272252091_0004_000001 with final state: FINISHING, and exit status: -1000
2022-11-24 07:00:06,167 INFO org.apache.hadoop.yarn.server.resourcemanager.rmapp.attempt.RMAppAttemptImpl: appattempt_1669272252091_0004_000001 State change from RUNNING to FINAL_SAVING on event = UNREGISTERED
2022-11-24 07:00:06,167 INFO org.apache.hadoop.yarn.server.resourcemanager.rmapp.RMAppImpl: Updating application application_1669272252091_0004 with final state: FINISHING
2022-11-24 07:00:06,168 INFO org.apache.hadoop.yarn.server.resourcemanager.rmapp.RMAppImpl: application_1669272252091_0004 State change from RUNNING to FINAL_SAVING on event = ATTEMPT_UNREGISTERED
2022-11-24 07:00:06,168 INFO org.apache.hadoop.yarn.server.resourcemanager.recovery.RMStateStore: Updating info for app: application_1669272252091_0004
2022-11-24 07:00:06,168 INFO org.apache.hadoop.yarn.server.resourcemanager.rmapp.attempt.RMAppAttemptImpl: appattempt_1669272252091_0004_000001 State change from FINAL_SAVING to FINISHING on event = ATTEMPT_UPDATE_SAVED
2022-11-24 07:00:06,168 INFO org.apache.hadoop.yarn.server.resourcemanager.rmapp.RMAppImpl: application_1669272252091_0004 State change from FINAL_SAVING to FINISHING on event = APP_UPDATE_SAVED
2022-11-24 07:00:06,191 INFO org.apache.hadoop.yarn.server.resourcemanager.rmapp.attempt.RMAppAttemptImpl: Updating application attempt appattempt_1669272252091_0003_000001 with final state: FINISHING, and exit status: -1000
2022-11-24 07:00:06,191 INFO org.apache.hadoop.yarn.server.resourcemanager.rmapp.attempt.RMAppAttemptImpl: appattempt_1669272252091_0003_000001 State change from RUNNING to FINAL_SAVING on event = UNREGISTERED
2022-11-24 07:00:06,191 INFO org.apache.hadoop.yarn.server.resourcemanager.rmapp.RMAppImpl: Updating application application_1669272252091_0003 with final state: FINISHING
2022-11-24 07:00:06,191 INFO org.apache.hadoop.yarn.server.resourcemanager.rmapp.RMAppImpl: application_1669272252091_0003 State change from RUNNING to FINAL_SAVING on event = ATTEMPT_UNREGISTERED
2022-11-24 07:00:06,191 INFO org.apache.hadoop.yarn.server.resourcemanager.recovery.RMStateStore: Updating info for app: application_1669272252091_0003
2022-11-24 07:00:06,192 INFO org.apache.hadoop.yarn.server.resourcemanager.rmapp.attempt.RMAppAttemptImpl: appattempt_1669272252091_0003_000001 State change from FINAL_SAVING to FINISHING on event = ATTEMPT_UPDATE_SAVED
2022-11-24 07:00:06,192 INFO org.apache.hadoop.yarn.server.resourcemanager.rmapp.RMAppImpl: application_1669272252091_0003 State change from FINAL_SAVING to FINISHING on event = APP_UPDATE_SAVED
2022-11-24 07:00:06,218 INFO org.apache.hadoop.yarn.server.resourcemanager.rmcontainer.RMContainerImpl: container_1669272252091_0003_01_000002 Container Transitioned from RUNNING to COMPLETED
2022-11-24 07:00:06,218 INFO org.apache.hadoop.yarn.server.resourcemanager.RMAuditLogger: USER=hive	OPERATION=AM Released Container	TARGET=SchedulerApp	RESULT=SUCCESS	APPID=application_1669272252091_0003	CONTAINERID=container_1669272252091_0003_01_000002	RESOURCE=<memory:1024, vCores:1>	QUEUENAME=default
2022-11-24 07:00:06,273 INFO org.apache.hadoop.yarn.server.resourcemanager.ApplicationMasterService: application_1669272252091_0004 unregistered successfully. 
2022-11-24 07:00:06,293 INFO org.apache.hadoop.yarn.server.resourcemanager.ApplicationMasterService: application_1669272252091_0003 unregistered successfully. 
2022-11-24 07:00:06,661 INFO org.apache.hadoop.yarn.server.resourcemanager.ApplicationMasterService: Unregistering app attempt : appattempt_1669272252091_0004_000001
2022-11-24 07:00:06,661 INFO org.apache.hadoop.yarn.server.resourcemanager.rmcontainer.RMContainerImpl: container_1669272252091_0004_01_000001 Container Transitioned from RUNNING to COMPLETED
2022-11-24 07:00:06,661 INFO org.apache.hadoop.yarn.server.resourcemanager.security.AMRMTokenSecretManager: Application finished, removing password for appattempt_1669272252091_0004_000001
2022-11-24 07:00:06,661 INFO org.apache.hadoop.yarn.server.resourcemanager.RMAuditLogger: USER=hive	OPERATION=AM Released Container	TARGET=SchedulerApp	RESULT=SUCCESS	APPID=application_1669272252091_0004	CONTAINERID=container_1669272252091_0004_01_000001	RESOURCE=<memory:1024, vCores:1>	QUEUENAME=default
2022-11-24 07:00:06,661 INFO org.apache.hadoop.yarn.server.resourcemanager.rmapp.attempt.RMAppAttemptImpl: appattempt_1669272252091_0004_000001 State change from FINISHING to FINISHED on event = CONTAINER_FINISHED
2022-11-24 07:00:06,662 INFO org.apache.hadoop.yarn.server.resourcemanager.rmapp.RMAppImpl: application_1669272252091_0004 State change from FINISHING to FINISHED on event = ATTEMPT_FINISHED
2022-11-24 07:00:06,662 INFO org.apache.hadoop.yarn.server.resourcemanager.scheduler.capacity.CapacityScheduler: Application Attempt appattempt_1669272252091_0004_000001 is done. finalState=FINISHED
2022-11-24 07:00:06,663 INFO org.apache.hadoop.yarn.server.resourcemanager.scheduler.AppSchedulingInfo: Application application_1669272252091_0004 requests cleared
2022-11-24 07:00:06,663 INFO org.apache.hadoop.yarn.server.resourcemanager.scheduler.capacity.LeafQueue: Application removed - appId: application_1669272252091_0004 user: hive queue: default #user-pending-applications: 0 #user-active-applications: 3 #queue-pending-applications: 0 #queue-active-applications: 3
2022-11-24 07:00:06,663 INFO org.apache.hadoop.yarn.server.resourcemanager.RMAuditLogger: USER=hive	OPERATION=Application Finished - Succeeded	TARGET=RMAppManager	RESULT=SUCCESS	APPID=application_1669272252091_0004
2022-11-24 07:00:06,664 INFO org.apache.hadoop.yarn.server.resourcemanager.scheduler.capacity.ParentQueue: Application removed - appId: application_1669272252091_0004 user: hive leaf-queue of parent: root #applications: 3
2022-11-24 07:00:06,664 INFO org.apache.hadoop.yarn.server.resourcemanager.RMAppManager$ApplicationSummary: appId=application_1669272252091_0004,name=OrderedWordCount,user=hive,queue=default,state=FINISHED,trackingUrl=http://adh-hack-02-mnode1.ru-central1.internal:8088/proxy/application_1669272252091_0004/,appMasterHost=adh-hack-02-mnode3.ru-central1.internal,submitTime=1669273192342,startTime=1669273192344,finishTime=1669273206167,finalStatus=SUCCEEDED,memorySeconds=23572,vcoreSeconds=22,preemptedMemorySeconds=0,preemptedVcoreSeconds=0,preemptedAMContainers=0,preemptedNonAMContainers=0,preemptedResources=<memory:0\, vCores:0>,applicationType=TEZ,resourceSeconds=23572 MB-seconds\, 22 vcore-seconds,preemptedResourceSeconds=0 MB-seconds\, 0 vcore-seconds
2022-11-24 07:00:06,664 INFO org.apache.hadoop.yarn.server.resourcemanager.amlauncher.AMLauncher: Cleaning master appattempt_1669272252091_0004_000001
2022-11-24 07:00:06,676 INFO org.apache.hadoop.yarn.server.resourcemanager.rmcontainer.RMContainerImpl: container_1669272252091_0003_01_000001 Container Transitioned from RUNNING to COMPLETED
2022-11-24 07:00:06,678 INFO org.apache.hadoop.yarn.server.resourcemanager.RMAuditLogger: USER=hive	OPERATION=AM Released Container	TARGET=SchedulerApp	RESULT=SUCCESS	APPID=application_1669272252091_0003	CONTAINERID=container_1669272252091_0003_01_000001	RESOURCE=<memory:1024, vCores:1>	QUEUENAME=default
2022-11-24 07:00:06,678 INFO org.apache.hadoop.yarn.server.resourcemanager.ApplicationMasterService: Unregistering app attempt : appattempt_1669272252091_0003_000001
2022-11-24 07:00:06,679 INFO org.apache.hadoop.yarn.server.resourcemanager.security.AMRMTokenSecretManager: Application finished, removing password for appattempt_1669272252091_0003_000001
2022-11-24 07:00:06,679 INFO org.apache.hadoop.yarn.server.resourcemanager.rmapp.attempt.RMAppAttemptImpl: appattempt_1669272252091_0003_000001 State change from FINISHING to FINISHED on event = CONTAINER_FINISHED
2022-11-24 07:00:06,680 INFO org.apache.hadoop.yarn.server.resourcemanager.rmapp.RMAppImpl: application_1669272252091_0003 State change from FINISHING to FINISHED on event = ATTEMPT_FINISHED
2022-11-24 07:00:06,680 INFO org.apache.hadoop.yarn.server.resourcemanager.RMAuditLogger: USER=hive	OPERATION=Application Finished - Succeeded	TARGET=RMAppManager	RESULT=SUCCESS	APPID=application_1669272252091_0003
2022-11-24 07:00:06,680 INFO org.apache.hadoop.yarn.server.resourcemanager.RMAppManager$ApplicationSummary: appId=application_1669272252091_0003,name=OrderedWordCount,user=hive,queue=default,state=FINISHED,trackingUrl=http://adh-hack-02-mnode1.ru-central1.internal:8088/proxy/application_1669272252091_0003/,appMasterHost=adh-hack-02-mnode1.ru-central1.internal,submitTime=1669273192076,startTime=1669273192077,finishTime=1669273206191,finalStatus=SUCCEEDED,memorySeconds=24386,vcoreSeconds=23,preemptedMemorySeconds=0,preemptedVcoreSeconds=0,preemptedAMContainers=0,preemptedNonAMContainers=0,preemptedResources=<memory:0\, vCores:0>,applicationType=TEZ,resourceSeconds=24386 MB-seconds\, 23 vcore-seconds,preemptedResourceSeconds=0 MB-seconds\, 0 vcore-seconds
2022-11-24 07:00:06,681 INFO org.apache.hadoop.yarn.server.resourcemanager.scheduler.capacity.CapacityScheduler: Application Attempt appattempt_1669272252091_0003_000001 is done. finalState=FINISHED
2022-11-24 07:00:06,681 INFO org.apache.hadoop.yarn.server.resourcemanager.scheduler.AppSchedulingInfo: Application application_1669272252091_0003 requests cleared
2022-11-24 07:00:06,681 INFO org.apache.hadoop.yarn.server.resourcemanager.scheduler.capacity.LeafQueue: Application removed - appId: application_1669272252091_0003 user: hive queue: default #user-pending-applications: 0 #user-active-applications: 2 #queue-pending-applications: 0 #queue-active-applications: 2
2022-11-24 07:00:06,681 INFO org.apache.hadoop.yarn.server.resourcemanager.scheduler.capacity.ParentQueue: Application removed - appId: application_1669272252091_0003 user: hive leaf-queue of parent: root #applications: 2
2022-11-24 07:00:06,686 INFO org.apache.hadoop.yarn.server.resourcemanager.amlauncher.AMLauncher: Cleaning master appattempt_1669272252091_0003_000001
2022-11-24 07:00:07,079 INFO org.apache.hadoop.yarn.server.resourcemanager.rmapp.attempt.RMAppAttemptImpl: Updating application attempt appattempt_1669272252091_0005_000001 with final state: FINISHING, and exit status: -1000
2022-11-24 07:00:07,079 INFO org.apache.hadoop.yarn.server.resourcemanager.rmapp.attempt.RMAppAttemptImpl: appattempt_1669272252091_0005_000001 State change from RUNNING to FINAL_SAVING on event = UNREGISTERED
2022-11-24 07:00:07,079 INFO org.apache.hadoop.yarn.server.resourcemanager.rmapp.RMAppImpl: Updating application application_1669272252091_0005 with final state: FINISHING
2022-11-24 07:00:07,079 INFO org.apache.hadoop.yarn.server.resourcemanager.rmapp.RMAppImpl: application_1669272252091_0005 State change from RUNNING to FINAL_SAVING on event = ATTEMPT_UNREGISTERED
2022-11-24 07:00:07,079 INFO org.apache.hadoop.yarn.server.resourcemanager.recovery.RMStateStore: Updating info for app: application_1669272252091_0005
2022-11-24 07:00:07,079 INFO org.apache.hadoop.yarn.server.resourcemanager.rmapp.attempt.RMAppAttemptImpl: appattempt_1669272252091_0005_000001 State change from FINAL_SAVING to FINISHING on event = ATTEMPT_UPDATE_SAVED
2022-11-24 07:00:07,080 INFO org.apache.hadoop.yarn.server.resourcemanager.rmcontainer.RMContainerImpl: container_1669272252091_0005_01_000002 Container Transitioned from RUNNING to COMPLETED
2022-11-24 07:00:07,080 INFO org.apache.hadoop.yarn.server.resourcemanager.RMAuditLogger: USER=hive	OPERATION=AM Released Container	TARGET=SchedulerApp	RESULT=SUCCESS	APPID=application_1669272252091_0005	CONTAINERID=container_1669272252091_0005_01_000002	RESOURCE=<memory:1024, vCores:1>	QUEUENAME=default
2022-11-24 07:00:07,081 INFO org.apache.hadoop.yarn.server.resourcemanager.rmapp.RMAppImpl: application_1669272252091_0005 State change from FINAL_SAVING to FINISHING on event = APP_UPDATE_SAVED
2022-11-24 07:00:07,182 INFO org.apache.hadoop.yarn.server.resourcemanager.ApplicationMasterService: application_1669272252091_0005 unregistered successfully. 
2022-11-24 07:00:07,555 INFO org.apache.hadoop.yarn.server.resourcemanager.ApplicationMasterService: Unregistering app attempt : appattempt_1669272252091_0005_000001
2022-11-24 07:00:07,555 INFO org.apache.hadoop.yarn.server.resourcemanager.rmcontainer.RMContainerImpl: container_1669272252091_0005_01_000001 Container Transitioned from RUNNING to COMPLETED
2022-11-24 07:00:07,556 INFO org.apache.hadoop.yarn.server.resourcemanager.security.AMRMTokenSecretManager: Application finished, removing password for appattempt_1669272252091_0005_000001
2022-11-24 07:00:07,556 INFO org.apache.hadoop.yarn.server.resourcemanager.RMAuditLogger: USER=hive	OPERATION=AM Released Container	TARGET=SchedulerApp	RESULT=SUCCESS	APPID=application_1669272252091_0005	CONTAINERID=container_1669272252091_0005_01_000001	RESOURCE=<memory:1024, vCores:1>	QUEUENAME=default
2022-11-24 07:00:07,556 INFO org.apache.hadoop.yarn.server.resourcemanager.rmapp.attempt.RMAppAttemptImpl: appattempt_1669272252091_0005_000001 State change from FINISHING to FINISHED on event = CONTAINER_FINISHED
2022-11-24 07:00:07,557 INFO org.apache.hadoop.yarn.server.resourcemanager.rmapp.RMAppImpl: application_1669272252091_0005 State change from FINISHING to FINISHED on event = ATTEMPT_FINISHED
2022-11-24 07:00:07,557 INFO org.apache.hadoop.yarn.server.resourcemanager.scheduler.capacity.CapacityScheduler: Application Attempt appattempt_1669272252091_0005_000001 is done. finalState=FINISHED
2022-11-24 07:00:07,557 INFO org.apache.hadoop.yarn.server.resourcemanager.RMAuditLogger: USER=hive	OPERATION=Application Finished - Succeeded	TARGET=RMAppManager	RESULT=SUCCESS	APPID=application_1669272252091_0005
2022-11-24 07:00:07,557 INFO org.apache.hadoop.yarn.server.resourcemanager.scheduler.AppSchedulingInfo: Application application_1669272252091_0005 requests cleared
2022-11-24 07:00:07,557 INFO org.apache.hadoop.yarn.server.resourcemanager.scheduler.capacity.LeafQueue: Application removed - appId: application_1669272252091_0005 user: hive queue: default #user-pending-applications: 0 #user-active-applications: 1 #queue-pending-applications: 0 #queue-active-applications: 1
2022-11-24 07:00:07,557 INFO org.apache.hadoop.yarn.server.resourcemanager.scheduler.capacity.ParentQueue: Application removed - appId: application_1669272252091_0005 user: hive leaf-queue of parent: root #applications: 1
2022-11-24 07:00:07,557 INFO org.apache.hadoop.yarn.server.resourcemanager.amlauncher.AMLauncher: Cleaning master appattempt_1669272252091_0005_000001
2022-11-24 07:00:07,557 INFO org.apache.hadoop.yarn.server.resourcemanager.RMAppManager$ApplicationSummary: appId=application_1669272252091_0005,name=OrderedWordCount,user=hive,queue=default,state=FINISHED,trackingUrl=http://adh-hack-02-mnode1.ru-central1.internal:8088/proxy/application_1669272252091_0005/,appMasterHost=adh-hack-02-mnode2.ru-central1.internal,submitTime=1669273192227,startTime=1669273192227,finishTime=1669273207079,finalStatus=SUCCEEDED,memorySeconds=24604,vcoreSeconds=23,preemptedMemorySeconds=0,preemptedVcoreSeconds=0,preemptedAMContainers=0,preemptedNonAMContainers=0,preemptedResources=<memory:0\, vCores:0>,applicationType=TEZ,resourceSeconds=24604 MB-seconds\, 23 vcore-seconds,preemptedResourceSeconds=0 MB-seconds\, 0 vcore-seconds
2022-11-24 07:02:54,629 INFO org.apache.hadoop.yarn.server.resourcemanager.rmapp.attempt.RMAppAttemptImpl: Updating application attempt appattempt_1669272252091_0002_000001 with final state: FINISHING, and exit status: -1000
2022-11-24 07:02:54,629 INFO org.apache.hadoop.yarn.server.resourcemanager.rmapp.attempt.RMAppAttemptImpl: appattempt_1669272252091_0002_000001 State change from RUNNING to FINAL_SAVING on event = UNREGISTERED
2022-11-24 07:02:54,629 INFO org.apache.hadoop.yarn.server.resourcemanager.rmapp.RMAppImpl: Updating application application_1669272252091_0002 with final state: FINISHING
2022-11-24 07:02:54,629 INFO org.apache.hadoop.yarn.server.resourcemanager.rmapp.RMAppImpl: application_1669272252091_0002 State change from RUNNING to FINAL_SAVING on event = ATTEMPT_UNREGISTERED
2022-11-24 07:02:54,630 INFO org.apache.hadoop.yarn.server.resourcemanager.recovery.RMStateStore: Updating info for app: application_1669272252091_0002
2022-11-24 07:02:54,630 INFO org.apache.hadoop.yarn.server.resourcemanager.rmapp.attempt.RMAppAttemptImpl: appattempt_1669272252091_0002_000001 State change from FINAL_SAVING to FINISHING on event = ATTEMPT_UPDATE_SAVED
2022-11-24 07:02:54,631 INFO org.apache.hadoop.yarn.server.resourcemanager.rmapp.RMAppImpl: application_1669272252091_0002 State change from FINAL_SAVING to FINISHING on event = APP_UPDATE_SAVED
2022-11-24 07:02:54,731 INFO org.apache.hadoop.yarn.server.resourcemanager.ApplicationMasterService: application_1669272252091_0002 unregistered successfully. 
2022-11-24 07:02:55,130 INFO org.apache.hadoop.yarn.server.resourcemanager.rmcontainer.RMContainerImpl: container_1669272252091_0002_01_000001 Container Transitioned from RUNNING to COMPLETED
2022-11-24 07:02:55,130 INFO org.apache.hadoop.yarn.server.resourcemanager.ApplicationMasterService: Unregistering app attempt : appattempt_1669272252091_0002_000001
2022-11-24 07:02:55,130 INFO org.apache.hadoop.yarn.server.resourcemanager.RMAuditLogger: USER=hive	OPERATION=AM Released Container	TARGET=SchedulerApp	RESULT=SUCCESS	APPID=application_1669272252091_0002	CONTAINERID=container_1669272252091_0002_01_000001	RESOURCE=<memory:1024, vCores:1>	QUEUENAME=default
2022-11-24 07:02:55,130 INFO org.apache.hadoop.yarn.server.resourcemanager.security.AMRMTokenSecretManager: Application finished, removing password for appattempt_1669272252091_0002_000001
2022-11-24 07:02:55,130 INFO org.apache.hadoop.yarn.server.resourcemanager.rmapp.attempt.RMAppAttemptImpl: appattempt_1669272252091_0002_000001 State change from FINISHING to FINISHED on event = CONTAINER_FINISHED
2022-11-24 07:02:55,131 INFO org.apache.hadoop.yarn.server.resourcemanager.rmapp.RMAppImpl: application_1669272252091_0002 State change from FINISHING to FINISHED on event = ATTEMPT_FINISHED
2022-11-24 07:02:55,131 INFO org.apache.hadoop.yarn.server.resourcemanager.scheduler.capacity.CapacityScheduler: Application Attempt appattempt_1669272252091_0002_000001 is done. finalState=FINISHED
2022-11-24 07:02:55,131 INFO org.apache.hadoop.yarn.server.resourcemanager.RMAuditLogger: USER=hive	OPERATION=Application Finished - Succeeded	TARGET=RMAppManager	RESULT=SUCCESS	APPID=application_1669272252091_0002
2022-11-24 07:02:55,131 INFO org.apache.hadoop.yarn.server.resourcemanager.scheduler.AppSchedulingInfo: Application application_1669272252091_0002 requests cleared
2022-11-24 07:02:55,131 INFO org.apache.hadoop.yarn.server.resourcemanager.scheduler.capacity.LeafQueue: Application removed - appId: application_1669272252091_0002 user: hive queue: default #user-pending-applications: 0 #user-active-applications: 0 #queue-pending-applications: 0 #queue-active-applications: 0
2022-11-24 07:02:55,131 INFO org.apache.hadoop.yarn.server.resourcemanager.scheduler.capacity.ParentQueue: Application removed - appId: application_1669272252091_0002 user: hive leaf-queue of parent: root #applications: 0
2022-11-24 07:02:55,132 INFO org.apache.hadoop.yarn.server.resourcemanager.RMAppManager$ApplicationSummary: appId=application_1669272252091_0002,name=HIVE-efb08ec9-e9fa-482c-8e36-cc9e49ad4871,user=hive,queue=default,state=FINISHED,trackingUrl=http://adh-hack-02-mnode1.ru-central1.internal:8088/proxy/application_1669272252091_0002/,appMasterHost=adh-hack-02-mnode1.ru-central1.internal,submitTime=1669273065765,startTime=1669273065766,finishTime=1669273374629,finalStatus=SUCCEEDED,memorySeconds=316517,vcoreSeconds=309,preemptedMemorySeconds=0,preemptedVcoreSeconds=0,preemptedAMContainers=0,preemptedNonAMContainers=0,preemptedResources=<memory:0\, vCores:0>,applicationType=TEZ,resourceSeconds=316517 MB-seconds\, 309 vcore-seconds,preemptedResourceSeconds=0 MB-seconds\, 0 vcore-seconds
2022-11-24 07:02:55,132 INFO org.apache.hadoop.yarn.server.resourcemanager.amlauncher.AMLauncher: Cleaning master appattempt_1669272252091_0002_000001
2022-11-24 07:11:58,427 INFO org.apache.hadoop.yarn.server.resourcemanager.ClientRMService: Allocated new applicationId: 6
2022-11-24 07:11:59,075 INFO org.apache.hadoop.yarn.server.resourcemanager.scheduler.capacity.CapacityScheduler: Application 'application_1669272252091_0006' is submitted without priority hence considering default queue/cluster priority: 0
2022-11-24 07:11:59,075 INFO org.apache.hadoop.yarn.server.resourcemanager.scheduler.capacity.CapacityScheduler: Priority '0' is acceptable in queue : default for application: application_1669272252091_0006
2022-11-24 07:11:59,075 WARN org.apache.hadoop.yarn.server.resourcemanager.rmapp.RMAppImpl: The specific max attempts: 0 for application: 6 is invalid, because it is out of the range [1, 2]. Use the global max attempts instead.
2022-11-24 07:11:59,076 INFO org.apache.hadoop.yarn.server.resourcemanager.ClientRMService: Application with id 6 submitted by user spark
2022-11-24 07:11:59,076 INFO org.apache.hadoop.yarn.server.resourcemanager.RMAuditLogger: USER=spark	IP=10.129.0.155	OPERATION=Submit Application Request	TARGET=ClientRMService	RESULT=SUCCESS	APPID=application_1669272252091_0006	QUEUENAME=default
2022-11-24 07:11:59,077 INFO org.apache.hadoop.yarn.server.resourcemanager.rmapp.RMAppImpl: Storing application with id application_1669272252091_0006
2022-11-24 07:11:59,077 INFO org.apache.hadoop.yarn.server.resourcemanager.rmapp.RMAppImpl: application_1669272252091_0006 State change from NEW to NEW_SAVING on event = START
2022-11-24 07:11:59,077 INFO org.apache.hadoop.yarn.server.resourcemanager.recovery.RMStateStore: Storing info for app: application_1669272252091_0006
2022-11-24 07:11:59,078 INFO org.apache.hadoop.yarn.server.resourcemanager.rmapp.RMAppImpl: application_1669272252091_0006 State change from NEW_SAVING to SUBMITTED on event = APP_NEW_SAVED
2022-11-24 07:11:59,078 INFO org.apache.hadoop.yarn.server.resourcemanager.scheduler.capacity.ParentQueue: Application added - appId: application_1669272252091_0006 user: spark leaf-queue of parent: root #applications: 1
2022-11-24 07:11:59,078 INFO org.apache.hadoop.yarn.server.resourcemanager.scheduler.capacity.CapacityScheduler: Accepted application application_1669272252091_0006 from user: spark, in queue: default
2022-11-24 07:11:59,078 INFO org.apache.hadoop.yarn.server.resourcemanager.rmapp.RMAppImpl: application_1669272252091_0006 State change from SUBMITTED to ACCEPTED on event = APP_ACCEPTED
2022-11-24 07:11:59,078 INFO org.apache.hadoop.yarn.server.resourcemanager.ApplicationMasterService: Registering app attempt : appattempt_1669272252091_0006_000001
2022-11-24 07:11:59,078 INFO org.apache.hadoop.yarn.server.resourcemanager.rmapp.attempt.RMAppAttemptImpl: appattempt_1669272252091_0006_000001 State change from NEW to SUBMITTED on event = START
2022-11-24 07:11:59,079 INFO org.apache.hadoop.yarn.server.resourcemanager.scheduler.capacity.LeafQueue: Application application_1669272252091_0006 from user: spark activated in queue: default
2022-11-24 07:11:59,079 INFO org.apache.hadoop.yarn.server.resourcemanager.scheduler.capacity.LeafQueue: Application added - appId: application_1669272252091_0006 user: spark, leaf-queue: default #user-pending-applications: 0 #user-active-applications: 1 #queue-pending-applications: 0 #queue-active-applications: 1
2022-11-24 07:11:59,079 INFO org.apache.hadoop.yarn.server.resourcemanager.scheduler.capacity.CapacityScheduler: Added Application Attempt appattempt_1669272252091_0006_000001 to scheduler from user spark in queue default
2022-11-24 07:11:59,079 INFO org.apache.hadoop.yarn.server.resourcemanager.rmapp.attempt.RMAppAttemptImpl: appattempt_1669272252091_0006_000001 State change from SUBMITTED to SCHEDULED on event = ATTEMPT_ADDED
2022-11-24 07:11:59,352 INFO org.apache.hadoop.yarn.server.resourcemanager.scheduler.capacity.allocator.AbstractContainerAllocator: assignedContainer application attempt=appattempt_1669272252091_0006_000001 container=null queue=default clusterResource=<memory:21171, vCores:6> type=OFF_SWITCH requestedPartition=
2022-11-24 07:11:59,353 INFO org.apache.hadoop.yarn.server.resourcemanager.rmcontainer.RMContainerImpl: container_1669272252091_0006_01_000001 Container Transitioned from NEW to ALLOCATED
2022-11-24 07:11:59,353 INFO org.apache.hadoop.yarn.server.resourcemanager.scheduler.common.fica.FiCaSchedulerNode: Assigned container container_1669272252091_0006_01_000001 of capacity <memory:1024, vCores:1> on host adh-hack-02-mnode3.ru-central1.internal:8041, which has 1 containers, <memory:1024, vCores:1> used and <memory:6033, vCores:1> available after allocation
2022-11-24 07:11:59,353 INFO org.apache.hadoop.yarn.server.resourcemanager.RMAuditLogger: USER=spark	OPERATION=AM Allocated Container	TARGET=SchedulerApp	RESULT=SUCCESS	APPID=application_1669272252091_0006	CONTAINERID=container_1669272252091_0006_01_000001	RESOURCE=<memory:1024, vCores:1>	QUEUENAME=default
2022-11-24 07:11:59,353 INFO org.apache.hadoop.yarn.server.resourcemanager.scheduler.capacity.ParentQueue: assignedContainer queue=root usedCapacity=0.04836805 absoluteUsedCapacity=0.04836805 used=<memory:1024, vCores:1> cluster=<memory:21171, vCores:6>
2022-11-24 07:11:59,353 INFO org.apache.hadoop.yarn.server.resourcemanager.scheduler.capacity.CapacityScheduler: Allocation proposal accepted
2022-11-24 07:11:59,356 INFO org.apache.hadoop.yarn.server.resourcemanager.security.NMTokenSecretManagerInRM: Sending NMToken for nodeId : adh-hack-02-mnode3.ru-central1.internal:8041 for container : container_1669272252091_0006_01_000001
2022-11-24 07:11:59,357 INFO org.apache.hadoop.yarn.server.resourcemanager.rmcontainer.RMContainerImpl: container_1669272252091_0006_01_000001 Container Transitioned from ALLOCATED to ACQUIRED
2022-11-24 07:11:59,357 INFO org.apache.hadoop.yarn.server.resourcemanager.security.NMTokenSecretManagerInRM: Clear node set for appattempt_1669272252091_0006_000001
2022-11-24 07:11:59,357 INFO org.apache.hadoop.yarn.server.resourcemanager.rmapp.attempt.RMAppAttemptImpl: Storing attempt: AppId: application_1669272252091_0006 AttemptId: appattempt_1669272252091_0006_000001 MasterContainer: Container: [ContainerId: container_1669272252091_0006_01_000001, AllocationRequestId: -1, Version: 0, NodeId: adh-hack-02-mnode3.ru-central1.internal:8041, NodeHttpAddress: adh-hack-02-mnode3.ru-central1.internal:8042, Resource: <memory:1024, vCores:1>, Priority: 0, Token: Token { kind: ContainerToken, service: 10.129.0.155:8041 }, ExecutionType: GUARANTEED, ]
2022-11-24 07:11:59,357 INFO org.apache.hadoop.yarn.server.resourcemanager.rmapp.attempt.RMAppAttemptImpl: appattempt_1669272252091_0006_000001 State change from SCHEDULED to ALLOCATED_SAVING on event = CONTAINER_ALLOCATED
2022-11-24 07:11:59,358 INFO org.apache.hadoop.yarn.server.resourcemanager.rmapp.attempt.RMAppAttemptImpl: appattempt_1669272252091_0006_000001 State change from ALLOCATED_SAVING to ALLOCATED on event = ATTEMPT_NEW_SAVED
2022-11-24 07:11:59,358 INFO org.apache.hadoop.yarn.server.resourcemanager.amlauncher.AMLauncher: Launching masterappattempt_1669272252091_0006_000001
2022-11-24 07:11:59,360 INFO org.apache.hadoop.yarn.server.resourcemanager.amlauncher.AMLauncher: Setting up container Container: [ContainerId: container_1669272252091_0006_01_000001, AllocationRequestId: -1, Version: 0, NodeId: adh-hack-02-mnode3.ru-central1.internal:8041, NodeHttpAddress: adh-hack-02-mnode3.ru-central1.internal:8042, Resource: <memory:1024, vCores:1>, Priority: 0, Token: Token { kind: ContainerToken, service: 10.129.0.155:8041 }, ExecutionType: GUARANTEED, ] for AM appattempt_1669272252091_0006_000001
2022-11-24 07:11:59,360 INFO org.apache.hadoop.yarn.server.resourcemanager.security.AMRMTokenSecretManager: Create AMRMToken for ApplicationAttempt: appattempt_1669272252091_0006_000001
2022-11-24 07:11:59,360 INFO org.apache.hadoop.yarn.server.resourcemanager.security.AMRMTokenSecretManager: Creating password for appattempt_1669272252091_0006_000001
2022-11-24 07:11:59,377 INFO org.apache.hadoop.yarn.server.resourcemanager.amlauncher.AMLauncher: Done launching container Container: [ContainerId: container_1669272252091_0006_01_000001, AllocationRequestId: -1, Version: 0, NodeId: adh-hack-02-mnode3.ru-central1.internal:8041, NodeHttpAddress: adh-hack-02-mnode3.ru-central1.internal:8042, Resource: <memory:1024, vCores:1>, Priority: 0, Token: Token { kind: ContainerToken, service: 10.129.0.155:8041 }, ExecutionType: GUARANTEED, ] for AM appattempt_1669272252091_0006_000001
2022-11-24 07:11:59,378 INFO org.apache.hadoop.yarn.server.resourcemanager.rmapp.attempt.RMAppAttemptImpl: appattempt_1669272252091_0006_000001 State change from ALLOCATED to LAUNCHED on event = LAUNCHED
2022-11-24 07:12:00,354 INFO org.apache.hadoop.yarn.server.resourcemanager.rmcontainer.RMContainerImpl: container_1669272252091_0006_01_000001 Container Transitioned from ACQUIRED to RUNNING
2022-11-24 07:12:03,903 INFO SecurityLogger.org.apache.hadoop.ipc.Server: Auth successful for appattempt_1669272252091_0006_000001 (auth:SIMPLE)
2022-11-24 07:12:03,906 INFO org.apache.hadoop.yarn.server.resourcemanager.DefaultAMSProcessor: AM registration appattempt_1669272252091_0006_000001
2022-11-24 07:12:03,906 INFO org.apache.hadoop.yarn.server.resourcemanager.RMAuditLogger: USER=spark	IP=10.129.0.155	OPERATION=Register App Master	TARGET=ApplicationMasterService	RESULT=SUCCESS	APPID=application_1669272252091_0006	APPATTEMPTID=appattempt_1669272252091_0006_000001
2022-11-24 07:12:03,906 INFO org.apache.hadoop.yarn.server.resourcemanager.rmapp.attempt.RMAppAttemptImpl: appattempt_1669272252091_0006_000001 State change from LAUNCHED to RUNNING on event = REGISTERED
2022-11-24 07:12:03,906 INFO org.apache.hadoop.yarn.server.resourcemanager.rmapp.RMAppImpl: application_1669272252091_0006 State change from ACCEPTED to RUNNING on event = ATTEMPT_REGISTERED
2022-11-24 07:12:04,368 INFO org.apache.hadoop.yarn.server.resourcemanager.scheduler.capacity.allocator.AbstractContainerAllocator: assignedContainer application attempt=appattempt_1669272252091_0006_000001 container=null queue=default clusterResource=<memory:21171, vCores:6> type=OFF_SWITCH requestedPartition=
2022-11-24 07:12:04,368 INFO org.apache.hadoop.yarn.server.resourcemanager.rmcontainer.RMContainerImpl: container_1669272252091_0006_01_000002 Container Transitioned from NEW to ALLOCATED
2022-11-24 07:12:04,369 INFO org.apache.hadoop.yarn.server.resourcemanager.scheduler.common.fica.FiCaSchedulerNode: Assigned container container_1669272252091_0006_01_000002 of capacity <memory:2048, vCores:1> on host adh-hack-02-mnode3.ru-central1.internal:8041, which has 2 containers, <memory:3072, vCores:2> used and <memory:3985, vCores:0> available after allocation
2022-11-24 07:12:04,369 INFO org.apache.hadoop.yarn.server.resourcemanager.RMAuditLogger: USER=spark	OPERATION=AM Allocated Container	TARGET=SchedulerApp	RESULT=SUCCESS	APPID=application_1669272252091_0006	CONTAINERID=container_1669272252091_0006_01_000002	RESOURCE=<memory:2048, vCores:1>	QUEUENAME=default
2022-11-24 07:12:04,369 INFO org.apache.hadoop.yarn.server.resourcemanager.scheduler.capacity.ParentQueue: assignedContainer queue=root usedCapacity=0.14510415 absoluteUsedCapacity=0.14510415 used=<memory:3072, vCores:2> cluster=<memory:21171, vCores:6>
2022-11-24 07:12:04,369 INFO org.apache.hadoop.yarn.server.resourcemanager.scheduler.capacity.CapacityScheduler: Allocation proposal accepted
2022-11-24 07:12:04,697 INFO org.apache.hadoop.yarn.server.resourcemanager.security.NMTokenSecretManagerInRM: Sending NMToken for nodeId : adh-hack-02-mnode3.ru-central1.internal:8041 for container : container_1669272252091_0006_01_000002
2022-11-24 07:12:04,698 INFO org.apache.hadoop.yarn.server.resourcemanager.rmcontainer.RMContainerImpl: container_1669272252091_0006_01_000002 Container Transitioned from ALLOCATED to ACQUIRED
2022-11-24 07:12:04,779 INFO org.apache.hadoop.yarn.server.resourcemanager.scheduler.capacity.allocator.AbstractContainerAllocator: assignedContainer application attempt=appattempt_1669272252091_0006_000001 container=null queue=default clusterResource=<memory:21171, vCores:6> type=OFF_SWITCH requestedPartition=
2022-11-24 07:12:04,779 INFO org.apache.hadoop.yarn.server.resourcemanager.rmcontainer.RMContainerImpl: container_1669272252091_0006_01_000003 Container Transitioned from NEW to ALLOCATED
2022-11-24 07:12:04,779 INFO org.apache.hadoop.yarn.server.resourcemanager.scheduler.common.fica.FiCaSchedulerNode: Assigned container container_1669272252091_0006_01_000003 of capacity <memory:2048, vCores:1> on host adh-hack-02-mnode1.ru-central1.internal:8041, which has 1 containers, <memory:2048, vCores:1> used and <memory:5009, vCores:1> available after allocation
2022-11-24 07:12:04,779 INFO org.apache.hadoop.yarn.server.resourcemanager.RMAuditLogger: USER=spark	OPERATION=AM Allocated Container	TARGET=SchedulerApp	RESULT=SUCCESS	APPID=application_1669272252091_0006	CONTAINERID=container_1669272252091_0006_01_000003	RESOURCE=<memory:2048, vCores:1>	QUEUENAME=default
2022-11-24 07:12:04,779 INFO org.apache.hadoop.yarn.server.resourcemanager.scheduler.capacity.ParentQueue: assignedContainer queue=root usedCapacity=0.24184026 absoluteUsedCapacity=0.24184026 used=<memory:5120, vCores:3> cluster=<memory:21171, vCores:6>
2022-11-24 07:12:04,779 INFO org.apache.hadoop.yarn.server.resourcemanager.scheduler.capacity.CapacityScheduler: Allocation proposal accepted
2022-11-24 07:12:05,379 INFO org.apache.hadoop.yarn.server.resourcemanager.rmcontainer.RMContainerImpl: container_1669272252091_0006_01_000002 Container Transitioned from ACQUIRED to RUNNING
2022-11-24 07:12:05,520 INFO org.apache.hadoop.yarn.server.resourcemanager.security.NMTokenSecretManagerInRM: Sending NMToken for nodeId : adh-hack-02-mnode1.ru-central1.internal:8041 for container : container_1669272252091_0006_01_000003
2022-11-24 07:12:05,522 INFO org.apache.hadoop.yarn.server.resourcemanager.rmcontainer.RMContainerImpl: container_1669272252091_0006_01_000003 Container Transitioned from ALLOCATED to ACQUIRED
2022-11-24 07:12:05,779 INFO org.apache.hadoop.yarn.server.resourcemanager.rmcontainer.RMContainerImpl: container_1669272252091_0006_01_000003 Container Transitioned from ACQUIRED to RUNNING
2022-11-24 07:12:05,780 INFO org.apache.hadoop.yarn.server.resourcemanager.scheduler.capacity.allocator.AbstractContainerAllocator: assignedContainer application attempt=appattempt_1669272252091_0006_000001 container=null queue=default clusterResource=<memory:21171, vCores:6> type=OFF_SWITCH requestedPartition=
2022-11-24 07:12:05,780 INFO org.apache.hadoop.yarn.server.resourcemanager.rmcontainer.RMContainerImpl: container_1669272252091_0006_01_000004 Container Transitioned from NEW to ALLOCATED
2022-11-24 07:12:05,780 INFO org.apache.hadoop.yarn.server.resourcemanager.scheduler.common.fica.FiCaSchedulerNode: Assigned container container_1669272252091_0006_01_000004 of capacity <memory:2048, vCores:1> on host adh-hack-02-mnode1.ru-central1.internal:8041, which has 2 containers, <memory:4096, vCores:2> used and <memory:2961, vCores:0> available after allocation
2022-11-24 07:12:05,780 INFO org.apache.hadoop.yarn.server.resourcemanager.RMAuditLogger: USER=spark	OPERATION=AM Allocated Container	TARGET=SchedulerApp	RESULT=SUCCESS	APPID=application_1669272252091_0006	CONTAINERID=container_1669272252091_0006_01_000004	RESOURCE=<memory:2048, vCores:1>	QUEUENAME=default
2022-11-24 07:12:05,781 INFO org.apache.hadoop.yarn.server.resourcemanager.scheduler.capacity.ParentQueue: assignedContainer queue=root usedCapacity=0.33857635 absoluteUsedCapacity=0.33857635 used=<memory:7168, vCores:4> cluster=<memory:21171, vCores:6>
2022-11-24 07:12:05,781 INFO org.apache.hadoop.yarn.server.resourcemanager.scheduler.capacity.CapacityScheduler: Allocation proposal accepted
2022-11-24 07:12:08,528 INFO org.apache.hadoop.yarn.server.resourcemanager.scheduler.AppSchedulingInfo: checking for deactivate of application :application_1669272252091_0006
2022-11-24 07:12:08,530 INFO org.apache.hadoop.yarn.server.resourcemanager.rmcontainer.RMContainerImpl: container_1669272252091_0006_01_000004 Container Transitioned from ALLOCATED to ACQUIRED
2022-11-24 07:12:11,539 INFO org.apache.hadoop.yarn.server.resourcemanager.rmcontainer.RMContainerImpl: container_1669272252091_0006_01_000004 Container Transitioned from ACQUIRED to RELEASED
2022-11-24 07:12:11,540 INFO org.apache.hadoop.yarn.server.resourcemanager.RMAuditLogger: USER=spark	IP=10.129.0.155	OPERATION=AM Released Container	TARGET=SchedulerApp	RESULT=SUCCESS	APPID=application_1669272252091_0006	CONTAINERID=container_1669272252091_0006_01_000004	RESOURCE=<memory:2048, vCores:1>	QUEUENAME=default
2022-11-24 07:12:12,353 INFO org.apache.hadoop.yarn.server.resourcemanager.rmcontainer.RMContainerImpl: container_1669272252091_0006_01_000003 Container Transitioned from RUNNING to COMPLETED
2022-11-24 07:12:12,353 INFO org.apache.hadoop.yarn.server.resourcemanager.RMAuditLogger: USER=spark	OPERATION=AM Released Container	TARGET=SchedulerApp	RESULT=SUCCESS	APPID=application_1669272252091_0006	CONTAINERID=container_1669272252091_0006_01_000003	RESOURCE=<memory:2048, vCores:1>	QUEUENAME=default
2022-11-24 07:12:12,407 INFO org.apache.hadoop.yarn.server.resourcemanager.rmcontainer.RMContainerImpl: container_1669272252091_0006_01_000002 Container Transitioned from RUNNING to COMPLETED
2022-11-24 07:12:12,407 INFO org.apache.hadoop.yarn.server.resourcemanager.RMAuditLogger: USER=spark	OPERATION=AM Released Container	TARGET=SchedulerApp	RESULT=SUCCESS	APPID=application_1669272252091_0006	CONTAINERID=container_1669272252091_0006_01_000002	RESOURCE=<memory:2048, vCores:1>	QUEUENAME=default
2022-11-24 07:12:12,451 INFO org.apache.hadoop.yarn.server.resourcemanager.rmapp.attempt.RMAppAttemptImpl: Updating application attempt appattempt_1669272252091_0006_000001 with final state: FINISHING, and exit status: -1000
2022-11-24 07:12:12,451 INFO org.apache.hadoop.yarn.server.resourcemanager.rmapp.attempt.RMAppAttemptImpl: appattempt_1669272252091_0006_000001 State change from RUNNING to FINAL_SAVING on event = UNREGISTERED
2022-11-24 07:12:12,451 INFO org.apache.hadoop.yarn.server.resourcemanager.rmapp.RMAppImpl: Updating application application_1669272252091_0006 with final state: FINISHING
2022-11-24 07:12:12,451 INFO org.apache.hadoop.yarn.server.resourcemanager.rmapp.RMAppImpl: application_1669272252091_0006 State change from RUNNING to FINAL_SAVING on event = ATTEMPT_UNREGISTERED
2022-11-24 07:12:12,451 INFO org.apache.hadoop.yarn.server.resourcemanager.recovery.RMStateStore: Updating info for app: application_1669272252091_0006
2022-11-24 07:12:12,451 INFO org.apache.hadoop.yarn.server.resourcemanager.rmapp.attempt.RMAppAttemptImpl: appattempt_1669272252091_0006_000001 State change from FINAL_SAVING to FINISHING on event = ATTEMPT_UPDATE_SAVED
2022-11-24 07:12:12,452 INFO org.apache.hadoop.yarn.server.resourcemanager.rmapp.RMAppImpl: application_1669272252091_0006 State change from FINAL_SAVING to FINISHING on event = APP_UPDATE_SAVED
2022-11-24 07:12:12,554 INFO org.apache.hadoop.yarn.server.resourcemanager.ApplicationMasterService: application_1669272252091_0006 unregistered successfully. 
2022-11-24 07:12:12,935 INFO org.apache.hadoop.yarn.server.resourcemanager.ApplicationMasterService: Unregistering app attempt : appattempt_1669272252091_0006_000001
2022-11-24 07:12:12,935 INFO org.apache.hadoop.yarn.server.resourcemanager.rmcontainer.RMContainerImpl: container_1669272252091_0006_01_000001 Container Transitioned from RUNNING to COMPLETED
2022-11-24 07:12:12,935 INFO org.apache.hadoop.yarn.server.resourcemanager.security.AMRMTokenSecretManager: Application finished, removing password for appattempt_1669272252091_0006_000001
2022-11-24 07:12:12,935 INFO org.apache.hadoop.yarn.server.resourcemanager.RMAuditLogger: USER=spark	OPERATION=AM Released Container	TARGET=SchedulerApp	RESULT=SUCCESS	APPID=application_1669272252091_0006	CONTAINERID=container_1669272252091_0006_01_000001	RESOURCE=<memory:1024, vCores:1>	QUEUENAME=default
2022-11-24 07:12:12,935 INFO org.apache.hadoop.yarn.server.resourcemanager.rmapp.attempt.RMAppAttemptImpl: appattempt_1669272252091_0006_000001 State change from FINISHING to FINISHED on event = CONTAINER_FINISHED
2022-11-24 07:12:12,936 INFO org.apache.hadoop.yarn.server.resourcemanager.rmapp.RMAppImpl: application_1669272252091_0006 State change from FINISHING to FINISHED on event = ATTEMPT_FINISHED
2022-11-24 07:12:12,936 INFO org.apache.hadoop.yarn.server.resourcemanager.RMAuditLogger: USER=spark	OPERATION=Application Finished - Succeeded	TARGET=RMAppManager	RESULT=SUCCESS	APPID=application_1669272252091_0006
2022-11-24 07:12:12,936 INFO org.apache.hadoop.yarn.server.resourcemanager.RMAppManager$ApplicationSummary: appId=application_1669272252091_0006,name=Spark shell,user=spark,queue=default,state=FINISHED,trackingUrl=http://adh-hack-02-mnode1.ru-central1.internal:8088/proxy/application_1669272252091_0006/,appMasterHost=10.129.0.155,submitTime=1669273919074,startTime=1669273919075,finishTime=1669273932451,finalStatus=SUCCEEDED,memorySeconds=57678,vcoreSeconds=33,preemptedMemorySeconds=0,preemptedVcoreSeconds=0,preemptedAMContainers=0,preemptedNonAMContainers=0,preemptedResources=<memory:0\, vCores:0>,applicationType=SPARK,resourceSeconds=57678 MB-seconds\, 33 vcore-seconds,preemptedResourceSeconds=0 MB-seconds\, 0 vcore-seconds
2022-11-24 07:12:12,936 INFO org.apache.hadoop.yarn.server.resourcemanager.scheduler.capacity.CapacityScheduler: Application Attempt appattempt_1669272252091_0006_000001 is done. finalState=FINISHED
2022-11-24 07:12:12,936 INFO org.apache.hadoop.yarn.server.resourcemanager.scheduler.AppSchedulingInfo: Application application_1669272252091_0006 requests cleared
2022-11-24 07:12:12,936 INFO org.apache.hadoop.yarn.server.resourcemanager.amlauncher.AMLauncher: Cleaning master appattempt_1669272252091_0006_000001
2022-11-24 07:12:12,936 INFO org.apache.hadoop.yarn.server.resourcemanager.scheduler.capacity.LeafQueue: Application removed - appId: application_1669272252091_0006 user: spark queue: default #user-pending-applications: 0 #user-active-applications: 0 #queue-pending-applications: 0 #queue-active-applications: 0
2022-11-24 07:12:12,937 INFO org.apache.hadoop.yarn.server.resourcemanager.scheduler.capacity.ParentQueue: Application removed - appId: application_1669272252091_0006 user: spark leaf-queue of parent: root #applications: 0
2022-11-24 07:16:58,917 INFO org.apache.hadoop.yarn.server.resourcemanager.ClientRMService: Allocated new applicationId: 7
2022-11-24 07:16:58,959 INFO org.apache.hadoop.yarn.server.resourcemanager.ClientRMService: Allocated new applicationId: 8
2022-11-24 07:16:58,993 INFO org.apache.hadoop.yarn.server.resourcemanager.ClientRMService: Allocated new applicationId: 9
2022-11-24 07:17:00,239 INFO org.apache.hadoop.yarn.server.resourcemanager.scheduler.capacity.CapacityScheduler: Application 'application_1669272252091_0007' is submitted without priority hence considering default queue/cluster priority: 0
2022-11-24 07:17:00,239 INFO org.apache.hadoop.yarn.server.resourcemanager.scheduler.capacity.CapacityScheduler: Priority '0' is acceptable in queue : default for application: application_1669272252091_0007
2022-11-24 07:17:00,239 WARN org.apache.hadoop.yarn.server.resourcemanager.rmapp.RMAppImpl: The specific max attempts: 0 for application: 7 is invalid, because it is out of the range [1, 2]. Use the global max attempts instead.
2022-11-24 07:17:00,240 INFO org.apache.hadoop.yarn.server.resourcemanager.ClientRMService: Application with id 7 submitted by user spark
2022-11-24 07:17:00,240 INFO org.apache.hadoop.yarn.server.resourcemanager.RMAuditLogger: USER=spark	IP=10.129.0.155	OPERATION=Submit Application Request	TARGET=ClientRMService	RESULT=SUCCESS	APPID=application_1669272252091_0007	QUEUENAME=default
2022-11-24 07:17:00,241 INFO org.apache.hadoop.yarn.server.resourcemanager.rmapp.RMAppImpl: Storing application with id application_1669272252091_0007
2022-11-24 07:17:00,241 INFO org.apache.hadoop.yarn.server.resourcemanager.recovery.RMStateStore: Storing info for app: application_1669272252091_0007
2022-11-24 07:17:00,241 INFO org.apache.hadoop.yarn.server.resourcemanager.rmapp.RMAppImpl: application_1669272252091_0007 State change from NEW to NEW_SAVING on event = START
2022-11-24 07:17:00,242 INFO org.apache.hadoop.yarn.server.resourcemanager.rmapp.RMAppImpl: application_1669272252091_0007 State change from NEW_SAVING to SUBMITTED on event = APP_NEW_SAVED
2022-11-24 07:17:00,242 INFO org.apache.hadoop.yarn.server.resourcemanager.scheduler.capacity.ParentQueue: Application added - appId: application_1669272252091_0007 user: spark leaf-queue of parent: root #applications: 1
2022-11-24 07:17:00,242 INFO org.apache.hadoop.yarn.server.resourcemanager.scheduler.capacity.CapacityScheduler: Accepted application application_1669272252091_0007 from user: spark, in queue: default
2022-11-24 07:17:00,242 INFO org.apache.hadoop.yarn.server.resourcemanager.rmapp.RMAppImpl: application_1669272252091_0007 State change from SUBMITTED to ACCEPTED on event = APP_ACCEPTED
2022-11-24 07:17:00,242 INFO org.apache.hadoop.yarn.server.resourcemanager.ApplicationMasterService: Registering app attempt : appattempt_1669272252091_0007_000001
2022-11-24 07:17:00,242 INFO org.apache.hadoop.yarn.server.resourcemanager.rmapp.attempt.RMAppAttemptImpl: appattempt_1669272252091_0007_000001 State change from NEW to SUBMITTED on event = START
2022-11-24 07:17:00,243 INFO org.apache.hadoop.yarn.server.resourcemanager.scheduler.capacity.LeafQueue: Application application_1669272252091_0007 from user: spark activated in queue: default
2022-11-24 07:17:00,243 INFO org.apache.hadoop.yarn.server.resourcemanager.scheduler.capacity.LeafQueue: Application added - appId: application_1669272252091_0007 user: spark, leaf-queue: default #user-pending-applications: 0 #user-active-applications: 1 #queue-pending-applications: 0 #queue-active-applications: 1
2022-11-24 07:17:00,243 INFO org.apache.hadoop.yarn.server.resourcemanager.scheduler.capacity.CapacityScheduler: Added Application Attempt appattempt_1669272252091_0007_000001 to scheduler from user spark in queue default
2022-11-24 07:17:00,246 INFO org.apache.hadoop.yarn.server.resourcemanager.rmapp.attempt.RMAppAttemptImpl: appattempt_1669272252091_0007_000001 State change from SUBMITTED to SCHEDULED on event = ATTEMPT_ADDED
2022-11-24 07:17:00,274 INFO org.apache.hadoop.yarn.server.resourcemanager.scheduler.capacity.CapacityScheduler: Application 'application_1669272252091_0009' is submitted without priority hence considering default queue/cluster priority: 0
2022-11-24 07:17:00,274 INFO org.apache.hadoop.yarn.server.resourcemanager.scheduler.capacity.CapacityScheduler: Priority '0' is acceptable in queue : default for application: application_1669272252091_0009
2022-11-24 07:17:00,274 WARN org.apache.hadoop.yarn.server.resourcemanager.rmapp.RMAppImpl: The specific max attempts: 0 for application: 9 is invalid, because it is out of the range [1, 2]. Use the global max attempts instead.
2022-11-24 07:17:00,274 INFO org.apache.hadoop.yarn.server.resourcemanager.ClientRMService: Application with id 9 submitted by user spark
2022-11-24 07:17:00,274 INFO org.apache.hadoop.yarn.server.resourcemanager.RMAuditLogger: USER=spark	IP=10.129.0.153	OPERATION=Submit Application Request	TARGET=ClientRMService	RESULT=SUCCESS	APPID=application_1669272252091_0009	QUEUENAME=default
2022-11-24 07:17:00,275 INFO org.apache.hadoop.yarn.server.resourcemanager.rmapp.RMAppImpl: Storing application with id application_1669272252091_0009
2022-11-24 07:17:00,275 INFO org.apache.hadoop.yarn.server.resourcemanager.recovery.RMStateStore: Storing info for app: application_1669272252091_0009
2022-11-24 07:17:00,275 INFO org.apache.hadoop.yarn.server.resourcemanager.rmapp.RMAppImpl: application_1669272252091_0009 State change from NEW to NEW_SAVING on event = START
2022-11-24 07:17:00,276 INFO org.apache.hadoop.yarn.server.resourcemanager.rmapp.RMAppImpl: application_1669272252091_0009 State change from NEW_SAVING to SUBMITTED on event = APP_NEW_SAVED
2022-11-24 07:17:00,276 INFO org.apache.hadoop.yarn.server.resourcemanager.scheduler.capacity.ParentQueue: Application added - appId: application_1669272252091_0009 user: spark leaf-queue of parent: root #applications: 2
2022-11-24 07:17:00,276 INFO org.apache.hadoop.yarn.server.resourcemanager.scheduler.capacity.CapacityScheduler: Accepted application application_1669272252091_0009 from user: spark, in queue: default
2022-11-24 07:17:00,277 INFO org.apache.hadoop.yarn.server.resourcemanager.rmapp.RMAppImpl: application_1669272252091_0009 State change from SUBMITTED to ACCEPTED on event = APP_ACCEPTED
2022-11-24 07:17:00,277 INFO org.apache.hadoop.yarn.server.resourcemanager.ApplicationMasterService: Registering app attempt : appattempt_1669272252091_0009_000001
2022-11-24 07:17:00,277 INFO org.apache.hadoop.yarn.server.resourcemanager.rmapp.attempt.RMAppAttemptImpl: appattempt_1669272252091_0009_000001 State change from NEW to SUBMITTED on event = START
2022-11-24 07:17:00,277 INFO org.apache.hadoop.yarn.server.resourcemanager.scheduler.capacity.LeafQueue: Application application_1669272252091_0009 from user: spark activated in queue: default
2022-11-24 07:17:00,277 INFO org.apache.hadoop.yarn.server.resourcemanager.scheduler.capacity.LeafQueue: Application added - appId: application_1669272252091_0009 user: spark, leaf-queue: default #user-pending-applications: 0 #user-active-applications: 2 #queue-pending-applications: 0 #queue-active-applications: 2
2022-11-24 07:17:00,277 INFO org.apache.hadoop.yarn.server.resourcemanager.scheduler.capacity.CapacityScheduler: Added Application Attempt appattempt_1669272252091_0009_000001 to scheduler from user spark in queue default
2022-11-24 07:17:00,278 INFO org.apache.hadoop.yarn.server.resourcemanager.rmapp.attempt.RMAppAttemptImpl: appattempt_1669272252091_0009_000001 State change from SUBMITTED to SCHEDULED on event = ATTEMPT_ADDED
2022-11-24 07:17:00,281 INFO org.apache.hadoop.yarn.server.resourcemanager.scheduler.capacity.CapacityScheduler: Application 'application_1669272252091_0008' is submitted without priority hence considering default queue/cluster priority: 0
2022-11-24 07:17:00,281 INFO org.apache.hadoop.yarn.server.resourcemanager.scheduler.capacity.CapacityScheduler: Priority '0' is acceptable in queue : default for application: application_1669272252091_0008
2022-11-24 07:17:00,281 WARN org.apache.hadoop.yarn.server.resourcemanager.rmapp.RMAppImpl: The specific max attempts: 0 for application: 8 is invalid, because it is out of the range [1, 2]. Use the global max attempts instead.
2022-11-24 07:17:00,281 INFO org.apache.hadoop.yarn.server.resourcemanager.ClientRMService: Application with id 8 submitted by user spark
2022-11-24 07:17:00,281 INFO org.apache.hadoop.yarn.server.resourcemanager.RMAuditLogger: USER=spark	IP=10.129.0.154	OPERATION=Submit Application Request	TARGET=ClientRMService	RESULT=SUCCESS	APPID=application_1669272252091_0008	QUEUENAME=default
2022-11-24 07:17:00,282 INFO org.apache.hadoop.yarn.server.resourcemanager.rmapp.RMAppImpl: Storing application with id application_1669272252091_0008
2022-11-24 07:17:00,282 INFO org.apache.hadoop.yarn.server.resourcemanager.rmapp.RMAppImpl: application_1669272252091_0008 State change from NEW to NEW_SAVING on event = START
2022-11-24 07:17:00,282 INFO org.apache.hadoop.yarn.server.resourcemanager.recovery.RMStateStore: Storing info for app: application_1669272252091_0008
2022-11-24 07:17:00,283 INFO org.apache.hadoop.yarn.server.resourcemanager.rmapp.RMAppImpl: application_1669272252091_0008 State change from NEW_SAVING to SUBMITTED on event = APP_NEW_SAVED
2022-11-24 07:17:00,283 INFO org.apache.hadoop.yarn.server.resourcemanager.scheduler.capacity.ParentQueue: Application added - appId: application_1669272252091_0008 user: spark leaf-queue of parent: root #applications: 3
2022-11-24 07:17:00,283 INFO org.apache.hadoop.yarn.server.resourcemanager.scheduler.capacity.CapacityScheduler: Accepted application application_1669272252091_0008 from user: spark, in queue: default
2022-11-24 07:17:00,284 INFO org.apache.hadoop.yarn.server.resourcemanager.rmapp.RMAppImpl: application_1669272252091_0008 State change from SUBMITTED to ACCEPTED on event = APP_ACCEPTED
2022-11-24 07:17:00,284 INFO org.apache.hadoop.yarn.server.resourcemanager.ApplicationMasterService: Registering app attempt : appattempt_1669272252091_0008_000001
2022-11-24 07:17:00,284 INFO org.apache.hadoop.yarn.server.resourcemanager.rmapp.attempt.RMAppAttemptImpl: appattempt_1669272252091_0008_000001 State change from NEW to SUBMITTED on event = START
2022-11-24 07:17:00,284 INFO org.apache.hadoop.yarn.server.resourcemanager.scheduler.capacity.LeafQueue: Application application_1669272252091_0008 from user: spark activated in queue: default
2022-11-24 07:17:00,284 INFO org.apache.hadoop.yarn.server.resourcemanager.scheduler.capacity.LeafQueue: Application added - appId: application_1669272252091_0008 user: spark, leaf-queue: default #user-pending-applications: 0 #user-active-applications: 3 #queue-pending-applications: 0 #queue-active-applications: 3
2022-11-24 07:17:00,284 INFO org.apache.hadoop.yarn.server.resourcemanager.scheduler.capacity.CapacityScheduler: Added Application Attempt appattempt_1669272252091_0008_000001 to scheduler from user spark in queue default
2022-11-24 07:17:00,285 INFO org.apache.hadoop.yarn.server.resourcemanager.rmapp.attempt.RMAppAttemptImpl: appattempt_1669272252091_0008_000001 State change from SUBMITTED to SCHEDULED on event = ATTEMPT_ADDED
2022-11-24 07:17:00,448 INFO org.apache.hadoop.yarn.server.resourcemanager.scheduler.capacity.allocator.AbstractContainerAllocator: assignedContainer application attempt=appattempt_1669272252091_0007_000001 container=null queue=default clusterResource=<memory:21171, vCores:6> type=OFF_SWITCH requestedPartition=
2022-11-24 07:17:00,449 INFO org.apache.hadoop.yarn.server.resourcemanager.rmcontainer.RMContainerImpl: container_1669272252091_0007_01_000001 Container Transitioned from NEW to ALLOCATED
2022-11-24 07:17:00,449 INFO org.apache.hadoop.yarn.server.resourcemanager.scheduler.common.fica.FiCaSchedulerNode: Assigned container container_1669272252091_0007_01_000001 of capacity <memory:1024, vCores:1> on host adh-hack-02-mnode2.ru-central1.internal:8041, which has 1 containers, <memory:1024, vCores:1> used and <memory:6033, vCores:1> available after allocation
2022-11-24 07:17:00,449 INFO org.apache.hadoop.yarn.server.resourcemanager.RMAuditLogger: USER=spark	OPERATION=AM Allocated Container	TARGET=SchedulerApp	RESULT=SUCCESS	APPID=application_1669272252091_0007	CONTAINERID=container_1669272252091_0007_01_000001	RESOURCE=<memory:1024, vCores:1>	QUEUENAME=default
2022-11-24 07:17:00,450 INFO org.apache.hadoop.yarn.server.resourcemanager.security.NMTokenSecretManagerInRM: Sending NMToken for nodeId : adh-hack-02-mnode2.ru-central1.internal:8041 for container : container_1669272252091_0007_01_000001
2022-11-24 07:17:00,453 INFO org.apache.hadoop.yarn.server.resourcemanager.rmcontainer.RMContainerImpl: container_1669272252091_0007_01_000001 Container Transitioned from ALLOCATED to ACQUIRED
2022-11-24 07:17:00,453 INFO org.apache.hadoop.yarn.server.resourcemanager.security.NMTokenSecretManagerInRM: Clear node set for appattempt_1669272252091_0007_000001
2022-11-24 07:17:00,453 INFO org.apache.hadoop.yarn.server.resourcemanager.rmapp.attempt.RMAppAttemptImpl: Storing attempt: AppId: application_1669272252091_0007 AttemptId: appattempt_1669272252091_0007_000001 MasterContainer: Container: [ContainerId: container_1669272252091_0007_01_000001, AllocationRequestId: -1, Version: 0, NodeId: adh-hack-02-mnode2.ru-central1.internal:8041, NodeHttpAddress: adh-hack-02-mnode2.ru-central1.internal:8042, Resource: <memory:1024, vCores:1>, Priority: 0, Token: Token { kind: ContainerToken, service: 10.129.0.154:8041 }, ExecutionType: GUARANTEED, ]
2022-11-24 07:17:00,453 INFO org.apache.hadoop.yarn.server.resourcemanager.scheduler.capacity.ParentQueue: assignedContainer queue=root usedCapacity=0.04836805 absoluteUsedCapacity=0.04836805 used=<memory:1024, vCores:1> cluster=<memory:21171, vCores:6>
2022-11-24 07:17:00,453 INFO org.apache.hadoop.yarn.server.resourcemanager.scheduler.capacity.CapacityScheduler: Allocation proposal accepted
2022-11-24 07:17:00,454 INFO org.apache.hadoop.yarn.server.resourcemanager.rmapp.attempt.RMAppAttemptImpl: appattempt_1669272252091_0007_000001 State change from SCHEDULED to ALLOCATED_SAVING on event = CONTAINER_ALLOCATED
2022-11-24 07:17:00,457 INFO org.apache.hadoop.yarn.server.resourcemanager.rmapp.attempt.RMAppAttemptImpl: appattempt_1669272252091_0007_000001 State change from ALLOCATED_SAVING to ALLOCATED on event = ATTEMPT_NEW_SAVED
2022-11-24 07:17:00,457 INFO org.apache.hadoop.yarn.server.resourcemanager.amlauncher.AMLauncher: Launching masterappattempt_1669272252091_0007_000001
2022-11-24 07:17:00,457 INFO org.apache.hadoop.yarn.server.resourcemanager.scheduler.capacity.allocator.AbstractContainerAllocator: assignedContainer application attempt=appattempt_1669272252091_0008_000001 container=null queue=default clusterResource=<memory:21171, vCores:6> type=OFF_SWITCH requestedPartition=
2022-11-24 07:17:00,458 INFO org.apache.hadoop.yarn.server.resourcemanager.rmcontainer.RMContainerImpl: container_1669272252091_0008_01_000001 Container Transitioned from NEW to ALLOCATED
2022-11-24 07:17:00,458 INFO org.apache.hadoop.yarn.server.resourcemanager.scheduler.common.fica.FiCaSchedulerNode: Assigned container container_1669272252091_0008_01_000001 of capacity <memory:1024, vCores:1> on host adh-hack-02-mnode3.ru-central1.internal:8041, which has 1 containers, <memory:1024, vCores:1> used and <memory:6033, vCores:1> available after allocation
2022-11-24 07:17:00,458 INFO org.apache.hadoop.yarn.server.resourcemanager.RMAuditLogger: USER=spark	OPERATION=AM Allocated Container	TARGET=SchedulerApp	RESULT=SUCCESS	APPID=application_1669272252091_0008	CONTAINERID=container_1669272252091_0008_01_000001	RESOURCE=<memory:1024, vCores:1>	QUEUENAME=default
2022-11-24 07:17:00,458 INFO org.apache.hadoop.yarn.server.resourcemanager.scheduler.capacity.ParentQueue: assignedContainer queue=root usedCapacity=0.0967361 absoluteUsedCapacity=0.0967361 used=<memory:2048, vCores:2> cluster=<memory:21171, vCores:6>
2022-11-24 07:17:00,458 INFO org.apache.hadoop.yarn.server.resourcemanager.scheduler.capacity.CapacityScheduler: Allocation proposal accepted
2022-11-24 07:17:00,459 INFO org.apache.hadoop.yarn.server.resourcemanager.amlauncher.AMLauncher: Setting up container Container: [ContainerId: container_1669272252091_0007_01_000001, AllocationRequestId: -1, Version: 0, NodeId: adh-hack-02-mnode2.ru-central1.internal:8041, NodeHttpAddress: adh-hack-02-mnode2.ru-central1.internal:8042, Resource: <memory:1024, vCores:1>, Priority: 0, Token: Token { kind: ContainerToken, service: 10.129.0.154:8041 }, ExecutionType: GUARANTEED, ] for AM appattempt_1669272252091_0007_000001
2022-11-24 07:17:00,459 INFO org.apache.hadoop.yarn.server.resourcemanager.security.AMRMTokenSecretManager: Create AMRMToken for ApplicationAttempt: appattempt_1669272252091_0007_000001
2022-11-24 07:17:00,459 INFO org.apache.hadoop.yarn.server.resourcemanager.security.AMRMTokenSecretManager: Creating password for appattempt_1669272252091_0007_000001
2022-11-24 07:17:00,460 INFO org.apache.hadoop.yarn.server.resourcemanager.security.NMTokenSecretManagerInRM: Sending NMToken for nodeId : adh-hack-02-mnode3.ru-central1.internal:8041 for container : container_1669272252091_0008_01_000001
2022-11-24 07:17:00,463 INFO org.apache.hadoop.yarn.server.resourcemanager.rmcontainer.RMContainerImpl: container_1669272252091_0008_01_000001 Container Transitioned from ALLOCATED to ACQUIRED
2022-11-24 07:17:00,463 INFO org.apache.hadoop.yarn.server.resourcemanager.security.NMTokenSecretManagerInRM: Clear node set for appattempt_1669272252091_0008_000001
2022-11-24 07:17:00,463 INFO org.apache.hadoop.yarn.server.resourcemanager.rmapp.attempt.RMAppAttemptImpl: Storing attempt: AppId: application_1669272252091_0008 AttemptId: appattempt_1669272252091_0008_000001 MasterContainer: Container: [ContainerId: container_1669272252091_0008_01_000001, AllocationRequestId: -1, Version: 0, NodeId: adh-hack-02-mnode3.ru-central1.internal:8041, NodeHttpAddress: adh-hack-02-mnode3.ru-central1.internal:8042, Resource: <memory:1024, vCores:1>, Priority: 0, Token: Token { kind: ContainerToken, service: 10.129.0.155:8041 }, ExecutionType: GUARANTEED, ]
2022-11-24 07:17:00,463 INFO org.apache.hadoop.yarn.server.resourcemanager.rmapp.attempt.RMAppAttemptImpl: appattempt_1669272252091_0008_000001 State change from SCHEDULED to ALLOCATED_SAVING on event = CONTAINER_ALLOCATED
2022-11-24 07:17:00,464 INFO org.apache.hadoop.yarn.server.resourcemanager.rmapp.attempt.RMAppAttemptImpl: appattempt_1669272252091_0008_000001 State change from ALLOCATED_SAVING to ALLOCATED on event = ATTEMPT_NEW_SAVED
2022-11-24 07:17:00,464 INFO org.apache.hadoop.yarn.server.resourcemanager.amlauncher.AMLauncher: Launching masterappattempt_1669272252091_0008_000001
2022-11-24 07:17:00,466 INFO org.apache.hadoop.yarn.server.resourcemanager.amlauncher.AMLauncher: Setting up container Container: [ContainerId: container_1669272252091_0008_01_000001, AllocationRequestId: -1, Version: 0, NodeId: adh-hack-02-mnode3.ru-central1.internal:8041, NodeHttpAddress: adh-hack-02-mnode3.ru-central1.internal:8042, Resource: <memory:1024, vCores:1>, Priority: 0, Token: Token { kind: ContainerToken, service: 10.129.0.155:8041 }, ExecutionType: GUARANTEED, ] for AM appattempt_1669272252091_0008_000001
2022-11-24 07:17:00,466 INFO org.apache.hadoop.yarn.server.resourcemanager.security.AMRMTokenSecretManager: Create AMRMToken for ApplicationAttempt: appattempt_1669272252091_0008_000001
2022-11-24 07:17:00,466 INFO org.apache.hadoop.yarn.server.resourcemanager.security.AMRMTokenSecretManager: Creating password for appattempt_1669272252091_0008_000001
2022-11-24 07:17:00,490 INFO org.apache.hadoop.yarn.server.resourcemanager.amlauncher.AMLauncher: Done launching container Container: [ContainerId: container_1669272252091_0007_01_000001, AllocationRequestId: -1, Version: 0, NodeId: adh-hack-02-mnode2.ru-central1.internal:8041, NodeHttpAddress: adh-hack-02-mnode2.ru-central1.internal:8042, Resource: <memory:1024, vCores:1>, Priority: 0, Token: Token { kind: ContainerToken, service: 10.129.0.154:8041 }, ExecutionType: GUARANTEED, ] for AM appattempt_1669272252091_0007_000001
2022-11-24 07:17:00,490 INFO org.apache.hadoop.yarn.server.resourcemanager.rmapp.attempt.RMAppAttemptImpl: appattempt_1669272252091_0007_000001 State change from ALLOCATED to LAUNCHED on event = LAUNCHED
2022-11-24 07:17:00,492 INFO org.apache.hadoop.yarn.server.resourcemanager.amlauncher.AMLauncher: Done launching container Container: [ContainerId: container_1669272252091_0008_01_000001, AllocationRequestId: -1, Version: 0, NodeId: adh-hack-02-mnode3.ru-central1.internal:8041, NodeHttpAddress: adh-hack-02-mnode3.ru-central1.internal:8042, Resource: <memory:1024, vCores:1>, Priority: 0, Token: Token { kind: ContainerToken, service: 10.129.0.155:8041 }, ExecutionType: GUARANTEED, ] for AM appattempt_1669272252091_0008_000001
2022-11-24 07:17:00,493 INFO org.apache.hadoop.yarn.server.resourcemanager.rmapp.attempt.RMAppAttemptImpl: appattempt_1669272252091_0008_000001 State change from ALLOCATED to LAUNCHED on event = LAUNCHED
2022-11-24 07:17:00,728 INFO org.apache.hadoop.yarn.server.resourcemanager.scheduler.capacity.allocator.AbstractContainerAllocator: assignedContainer application attempt=appattempt_1669272252091_0009_000001 container=null queue=default clusterResource=<memory:21171, vCores:6> type=OFF_SWITCH requestedPartition=
2022-11-24 07:17:00,729 INFO org.apache.hadoop.yarn.server.resourcemanager.rmcontainer.RMContainerImpl: container_1669272252091_0009_01_000001 Container Transitioned from NEW to ALLOCATED
2022-11-24 07:17:00,729 INFO org.apache.hadoop.yarn.server.resourcemanager.scheduler.common.fica.FiCaSchedulerNode: Assigned container container_1669272252091_0009_01_000001 of capacity <memory:1024, vCores:1> on host adh-hack-02-mnode1.ru-central1.internal:8041, which has 1 containers, <memory:1024, vCores:1> used and <memory:6033, vCores:1> available after allocation
2022-11-24 07:17:00,729 INFO org.apache.hadoop.yarn.server.resourcemanager.RMAuditLogger: USER=spark	OPERATION=AM Allocated Container	TARGET=SchedulerApp	RESULT=SUCCESS	APPID=application_1669272252091_0009	CONTAINERID=container_1669272252091_0009_01_000001	RESOURCE=<memory:1024, vCores:1>	QUEUENAME=default
2022-11-24 07:17:00,734 INFO org.apache.hadoop.yarn.server.resourcemanager.security.NMTokenSecretManagerInRM: Sending NMToken for nodeId : adh-hack-02-mnode1.ru-central1.internal:8041 for container : container_1669272252091_0009_01_000001
2022-11-24 07:17:00,735 INFO org.apache.hadoop.yarn.server.resourcemanager.rmcontainer.RMContainerImpl: container_1669272252091_0009_01_000001 Container Transitioned from ALLOCATED to ACQUIRED
2022-11-24 07:17:00,735 INFO org.apache.hadoop.yarn.server.resourcemanager.security.NMTokenSecretManagerInRM: Clear node set for appattempt_1669272252091_0009_000001
2022-11-24 07:17:00,735 INFO org.apache.hadoop.yarn.server.resourcemanager.rmapp.attempt.RMAppAttemptImpl: Storing attempt: AppId: application_1669272252091_0009 AttemptId: appattempt_1669272252091_0009_000001 MasterContainer: Container: [ContainerId: container_1669272252091_0009_01_000001, AllocationRequestId: -1, Version: 0, NodeId: adh-hack-02-mnode1.ru-central1.internal:8041, NodeHttpAddress: adh-hack-02-mnode1.ru-central1.internal:8042, Resource: <memory:1024, vCores:1>, Priority: 0, Token: Token { kind: ContainerToken, service: 10.129.0.153:8041 }, ExecutionType: GUARANTEED, ]
2022-11-24 07:17:00,735 INFO org.apache.hadoop.yarn.server.resourcemanager.scheduler.capacity.ParentQueue: assignedContainer queue=root usedCapacity=0.14510415 absoluteUsedCapacity=0.14510415 used=<memory:3072, vCores:3> cluster=<memory:21171, vCores:6>
2022-11-24 07:17:00,735 INFO org.apache.hadoop.yarn.server.resourcemanager.scheduler.capacity.CapacityScheduler: Allocation proposal accepted
2022-11-24 07:17:00,735 INFO org.apache.hadoop.yarn.server.resourcemanager.rmapp.attempt.RMAppAttemptImpl: appattempt_1669272252091_0009_000001 State change from SCHEDULED to ALLOCATED_SAVING on event = CONTAINER_ALLOCATED
2022-11-24 07:17:00,737 INFO org.apache.hadoop.yarn.server.resourcemanager.rmapp.attempt.RMAppAttemptImpl: appattempt_1669272252091_0009_000001 State change from ALLOCATED_SAVING to ALLOCATED on event = ATTEMPT_NEW_SAVED
2022-11-24 07:17:00,738 INFO org.apache.hadoop.yarn.server.resourcemanager.amlauncher.AMLauncher: Launching masterappattempt_1669272252091_0009_000001
2022-11-24 07:17:00,740 INFO org.apache.hadoop.yarn.server.resourcemanager.amlauncher.AMLauncher: Setting up container Container: [ContainerId: container_1669272252091_0009_01_000001, AllocationRequestId: -1, Version: 0, NodeId: adh-hack-02-mnode1.ru-central1.internal:8041, NodeHttpAddress: adh-hack-02-mnode1.ru-central1.internal:8042, Resource: <memory:1024, vCores:1>, Priority: 0, Token: Token { kind: ContainerToken, service: 10.129.0.153:8041 }, ExecutionType: GUARANTEED, ] for AM appattempt_1669272252091_0009_000001
2022-11-24 07:17:00,740 INFO org.apache.hadoop.yarn.server.resourcemanager.security.AMRMTokenSecretManager: Create AMRMToken for ApplicationAttempt: appattempt_1669272252091_0009_000001
2022-11-24 07:17:00,740 INFO org.apache.hadoop.yarn.server.resourcemanager.security.AMRMTokenSecretManager: Creating password for appattempt_1669272252091_0009_000001
2022-11-24 07:17:00,754 INFO org.apache.hadoop.yarn.server.resourcemanager.amlauncher.AMLauncher: Done launching container Container: [ContainerId: container_1669272252091_0009_01_000001, AllocationRequestId: -1, Version: 0, NodeId: adh-hack-02-mnode1.ru-central1.internal:8041, NodeHttpAddress: adh-hack-02-mnode1.ru-central1.internal:8042, Resource: <memory:1024, vCores:1>, Priority: 0, Token: Token { kind: ContainerToken, service: 10.129.0.153:8041 }, ExecutionType: GUARANTEED, ] for AM appattempt_1669272252091_0009_000001
2022-11-24 07:17:00,754 INFO org.apache.hadoop.yarn.server.resourcemanager.rmapp.attempt.RMAppAttemptImpl: appattempt_1669272252091_0009_000001 State change from ALLOCATED to LAUNCHED on event = LAUNCHED
2022-11-24 07:17:01,450 INFO org.apache.hadoop.yarn.server.resourcemanager.rmcontainer.RMContainerImpl: container_1669272252091_0007_01_000001 Container Transitioned from ACQUIRED to RUNNING
2022-11-24 07:17:01,454 INFO org.apache.hadoop.yarn.server.resourcemanager.rmcontainer.RMContainerImpl: container_1669272252091_0008_01_000001 Container Transitioned from ACQUIRED to RUNNING
2022-11-24 07:17:01,730 INFO org.apache.hadoop.yarn.server.resourcemanager.rmcontainer.RMContainerImpl: container_1669272252091_0009_01_000001 Container Transitioned from ACQUIRED to RUNNING
2022-11-24 07:17:05,023 INFO SecurityLogger.org.apache.hadoop.ipc.Server: Auth successful for appattempt_1669272252091_0008_000001 (auth:SIMPLE)
2022-11-24 07:17:05,038 INFO org.apache.hadoop.yarn.server.resourcemanager.DefaultAMSProcessor: AM registration appattempt_1669272252091_0008_000001
2022-11-24 07:17:05,038 INFO org.apache.hadoop.yarn.server.resourcemanager.RMAuditLogger: USER=spark	IP=10.129.0.155	OPERATION=Register App Master	TARGET=ApplicationMasterService	RESULT=SUCCESS	APPID=application_1669272252091_0008	APPATTEMPTID=appattempt_1669272252091_0008_000001
2022-11-24 07:17:05,038 INFO org.apache.hadoop.yarn.server.resourcemanager.rmapp.attempt.RMAppAttemptImpl: appattempt_1669272252091_0008_000001 State change from LAUNCHED to RUNNING on event = REGISTERED
2022-11-24 07:17:05,038 INFO org.apache.hadoop.yarn.server.resourcemanager.rmapp.RMAppImpl: application_1669272252091_0008 State change from ACCEPTED to RUNNING on event = ATTEMPT_REGISTERED
2022-11-24 07:17:05,159 INFO SecurityLogger.org.apache.hadoop.ipc.Server: Auth successful for appattempt_1669272252091_0007_000001 (auth:SIMPLE)
2022-11-24 07:17:05,172 INFO org.apache.hadoop.yarn.server.resourcemanager.DefaultAMSProcessor: AM registration appattempt_1669272252091_0007_000001
2022-11-24 07:17:05,172 INFO org.apache.hadoop.yarn.server.resourcemanager.RMAuditLogger: USER=spark	IP=10.129.0.154	OPERATION=Register App Master	TARGET=ApplicationMasterService	RESULT=SUCCESS	APPID=application_1669272252091_0007	APPATTEMPTID=appattempt_1669272252091_0007_000001
2022-11-24 07:17:05,173 INFO org.apache.hadoop.yarn.server.resourcemanager.rmapp.attempt.RMAppAttemptImpl: appattempt_1669272252091_0007_000001 State change from LAUNCHED to RUNNING on event = REGISTERED
2022-11-24 07:17:05,173 INFO org.apache.hadoop.yarn.server.resourcemanager.rmapp.RMAppImpl: application_1669272252091_0007 State change from ACCEPTED to RUNNING on event = ATTEMPT_REGISTERED
2022-11-24 07:17:05,272 INFO SecurityLogger.org.apache.hadoop.ipc.Server: Auth successful for appattempt_1669272252091_0009_000001 (auth:SIMPLE)
2022-11-24 07:17:05,284 INFO org.apache.hadoop.yarn.server.resourcemanager.DefaultAMSProcessor: AM registration appattempt_1669272252091_0009_000001
2022-11-24 07:17:05,284 INFO org.apache.hadoop.yarn.server.resourcemanager.RMAuditLogger: USER=spark	IP=10.129.0.153	OPERATION=Register App Master	TARGET=ApplicationMasterService	RESULT=SUCCESS	APPID=application_1669272252091_0009	APPATTEMPTID=appattempt_1669272252091_0009_000001
2022-11-24 07:17:05,284 INFO org.apache.hadoop.yarn.server.resourcemanager.rmapp.attempt.RMAppAttemptImpl: appattempt_1669272252091_0009_000001 State change from LAUNCHED to RUNNING on event = REGISTERED
2022-11-24 07:17:05,284 INFO org.apache.hadoop.yarn.server.resourcemanager.rmapp.RMAppImpl: application_1669272252091_0009 State change from ACCEPTED to RUNNING on event = ATTEMPT_REGISTERED
2022-11-24 07:17:06,746 INFO org.apache.hadoop.yarn.server.resourcemanager.scheduler.capacity.allocator.AbstractContainerAllocator: assignedContainer application attempt=appattempt_1669272252091_0007_000001 container=null queue=default clusterResource=<memory:21171, vCores:6> type=OFF_SWITCH requestedPartition=
2022-11-24 07:17:06,746 INFO org.apache.hadoop.yarn.server.resourcemanager.rmcontainer.RMContainerImpl: container_1669272252091_0007_01_000002 Container Transitioned from NEW to ALLOCATED
2022-11-24 07:17:06,746 INFO org.apache.hadoop.yarn.server.resourcemanager.scheduler.common.fica.FiCaSchedulerNode: Assigned container container_1669272252091_0007_01_000002 of capacity <memory:2048, vCores:1> on host adh-hack-02-mnode1.ru-central1.internal:8041, which has 2 containers, <memory:3072, vCores:2> used and <memory:3985, vCores:0> available after allocation
2022-11-24 07:17:06,747 INFO org.apache.hadoop.yarn.server.resourcemanager.RMAuditLogger: USER=spark	OPERATION=AM Allocated Container	TARGET=SchedulerApp	RESULT=SUCCESS	APPID=application_1669272252091_0007	CONTAINERID=container_1669272252091_0007_01_000002	RESOURCE=<memory:2048, vCores:1>	QUEUENAME=default
2022-11-24 07:17:06,747 INFO org.apache.hadoop.yarn.server.resourcemanager.scheduler.capacity.ParentQueue: assignedContainer queue=root usedCapacity=0.24184026 absoluteUsedCapacity=0.24184026 used=<memory:5120, vCores:4> cluster=<memory:21171, vCores:6>
2022-11-24 07:17:06,747 INFO org.apache.hadoop.yarn.server.resourcemanager.scheduler.capacity.CapacityScheduler: Allocation proposal accepted
2022-11-24 07:17:06,947 INFO org.apache.hadoop.yarn.server.resourcemanager.security.NMTokenSecretManagerInRM: Sending NMToken for nodeId : adh-hack-02-mnode1.ru-central1.internal:8041 for container : container_1669272252091_0007_01_000002
2022-11-24 07:17:06,948 INFO org.apache.hadoop.yarn.server.resourcemanager.rmcontainer.RMContainerImpl: container_1669272252091_0007_01_000002 Container Transitioned from ALLOCATED to ACQUIRED
2022-11-24 07:17:07,478 INFO org.apache.hadoop.yarn.server.resourcemanager.scheduler.capacity.allocator.AbstractContainerAllocator: assignedContainer application attempt=appattempt_1669272252091_0007_000001 container=null queue=default clusterResource=<memory:21171, vCores:6> type=OFF_SWITCH requestedPartition=
2022-11-24 07:17:07,479 INFO org.apache.hadoop.yarn.server.resourcemanager.rmcontainer.RMContainerImpl: container_1669272252091_0007_01_000003 Container Transitioned from NEW to ALLOCATED
2022-11-24 07:17:07,480 INFO org.apache.hadoop.yarn.server.resourcemanager.scheduler.common.fica.FiCaSchedulerNode: Assigned container container_1669272252091_0007_01_000003 of capacity <memory:2048, vCores:1> on host adh-hack-02-mnode3.ru-central1.internal:8041, which has 2 containers, <memory:3072, vCores:2> used and <memory:3985, vCores:0> available after allocation
2022-11-24 07:17:07,480 INFO org.apache.hadoop.yarn.server.resourcemanager.RMAuditLogger: USER=spark	OPERATION=AM Allocated Container	TARGET=SchedulerApp	RESULT=SUCCESS	APPID=application_1669272252091_0007	CONTAINERID=container_1669272252091_0007_01_000003	RESOURCE=<memory:2048, vCores:1>	QUEUENAME=default
2022-11-24 07:17:07,480 INFO org.apache.hadoop.yarn.server.resourcemanager.scheduler.capacity.ParentQueue: assignedContainer queue=root usedCapacity=0.33857635 absoluteUsedCapacity=0.33857635 used=<memory:7168, vCores:5> cluster=<memory:21171, vCores:6>
2022-11-24 07:17:07,480 INFO org.apache.hadoop.yarn.server.resourcemanager.scheduler.capacity.CapacityScheduler: Allocation proposal accepted
2022-11-24 07:17:07,481 INFO org.apache.hadoop.yarn.server.resourcemanager.scheduler.capacity.allocator.AbstractContainerAllocator: assignedContainer application attempt=appattempt_1669272252091_0008_000001 container=null queue=default clusterResource=<memory:21171, vCores:6> type=OFF_SWITCH requestedPartition=
2022-11-24 07:17:07,481 INFO org.apache.hadoop.yarn.server.resourcemanager.rmcontainer.RMContainerImpl: container_1669272252091_0008_01_000002 Container Transitioned from NEW to ALLOCATED
2022-11-24 07:17:07,481 INFO org.apache.hadoop.yarn.server.resourcemanager.scheduler.common.fica.FiCaSchedulerNode: Assigned container container_1669272252091_0008_01_000002 of capacity <memory:2048, vCores:1> on host adh-hack-02-mnode2.ru-central1.internal:8041, which has 2 containers, <memory:3072, vCores:2> used and <memory:3985, vCores:0> available after allocation
2022-11-24 07:17:07,481 INFO org.apache.hadoop.yarn.server.resourcemanager.RMAuditLogger: USER=spark	OPERATION=AM Allocated Container	TARGET=SchedulerApp	RESULT=SUCCESS	APPID=application_1669272252091_0008	CONTAINERID=container_1669272252091_0008_01_000002	RESOURCE=<memory:2048, vCores:1>	QUEUENAME=default
2022-11-24 07:17:07,481 INFO org.apache.hadoop.yarn.server.resourcemanager.scheduler.capacity.ParentQueue: assignedContainer queue=root usedCapacity=0.43531245 absoluteUsedCapacity=0.43531245 used=<memory:9216, vCores:6> cluster=<memory:21171, vCores:6>
2022-11-24 07:17:07,481 INFO org.apache.hadoop.yarn.server.resourcemanager.scheduler.capacity.CapacityScheduler: Allocation proposal accepted
2022-11-24 07:17:07,586 INFO org.apache.hadoop.yarn.server.resourcemanager.security.NMTokenSecretManagerInRM: Sending NMToken for nodeId : adh-hack-02-mnode3.ru-central1.internal:8041 for container : container_1669272252091_0007_01_000003
2022-11-24 07:17:07,587 INFO org.apache.hadoop.yarn.server.resourcemanager.rmcontainer.RMContainerImpl: container_1669272252091_0007_01_000003 Container Transitioned from ALLOCATED to ACQUIRED
2022-11-24 07:17:07,746 INFO org.apache.hadoop.yarn.server.resourcemanager.rmcontainer.RMContainerImpl: container_1669272252091_0007_01_000002 Container Transitioned from ACQUIRED to RUNNING
2022-11-24 07:17:07,747 INFO org.apache.hadoop.yarn.server.resourcemanager.scheduler.capacity.allocator.AbstractContainerAllocator: assignedContainer application attempt=appattempt_1669272252091_0008_000001 container=null queue=default clusterResource=<memory:21171, vCores:6> type=OFF_SWITCH requestedPartition=
2022-11-24 07:17:07,747 INFO org.apache.hadoop.yarn.server.resourcemanager.rmcontainer.RMContainerImpl: container_1669272252091_0008_01_000003 Container Transitioned from NEW to ALLOCATED
2022-11-24 07:17:07,747 INFO org.apache.hadoop.yarn.server.resourcemanager.scheduler.common.fica.FiCaSchedulerNode: Assigned container container_1669272252091_0008_01_000003 of capacity <memory:2048, vCores:1> on host adh-hack-02-mnode1.ru-central1.internal:8041, which has 3 containers, <memory:5120, vCores:3> used and <memory:1937, vCores:-1> available after allocation
2022-11-24 07:17:07,747 INFO org.apache.hadoop.yarn.server.resourcemanager.RMAuditLogger: USER=spark	OPERATION=AM Allocated Container	TARGET=SchedulerApp	RESULT=SUCCESS	APPID=application_1669272252091_0008	CONTAINERID=container_1669272252091_0008_01_000003	RESOURCE=<memory:2048, vCores:1>	QUEUENAME=default
2022-11-24 07:17:07,747 INFO org.apache.hadoop.yarn.server.resourcemanager.scheduler.capacity.ParentQueue: assignedContainer queue=root usedCapacity=0.5320486 absoluteUsedCapacity=0.5320486 used=<memory:11264, vCores:7> cluster=<memory:21171, vCores:6>
2022-11-24 07:17:07,747 INFO org.apache.hadoop.yarn.server.resourcemanager.scheduler.capacity.CapacityScheduler: Allocation proposal accepted
2022-11-24 07:17:08,236 INFO org.apache.hadoop.yarn.server.resourcemanager.security.NMTokenSecretManagerInRM: Sending NMToken for nodeId : adh-hack-02-mnode2.ru-central1.internal:8041 for container : container_1669272252091_0008_01_000002
2022-11-24 07:17:08,239 INFO org.apache.hadoop.yarn.server.resourcemanager.rmcontainer.RMContainerImpl: container_1669272252091_0008_01_000002 Container Transitioned from ALLOCATED to ACQUIRED
2022-11-24 07:17:08,240 INFO org.apache.hadoop.yarn.server.resourcemanager.security.NMTokenSecretManagerInRM: Sending NMToken for nodeId : adh-hack-02-mnode1.ru-central1.internal:8041 for container : container_1669272252091_0008_01_000003
2022-11-24 07:17:08,245 INFO org.apache.hadoop.yarn.server.resourcemanager.rmcontainer.RMContainerImpl: container_1669272252091_0008_01_000003 Container Transitioned from ALLOCATED to ACQUIRED
2022-11-24 07:17:08,482 INFO org.apache.hadoop.yarn.server.resourcemanager.rmcontainer.RMContainerImpl: container_1669272252091_0007_01_000003 Container Transitioned from ACQUIRED to RUNNING
2022-11-24 07:17:08,484 INFO org.apache.hadoop.yarn.server.resourcemanager.scheduler.capacity.allocator.AbstractContainerAllocator: assignedContainer application attempt=appattempt_1669272252091_0009_000001 container=null queue=default clusterResource=<memory:21171, vCores:6> type=OFF_SWITCH requestedPartition=
2022-11-24 07:17:08,485 INFO org.apache.hadoop.yarn.server.resourcemanager.rmcontainer.RMContainerImpl: container_1669272252091_0009_01_000002 Container Transitioned from NEW to ALLOCATED
2022-11-24 07:17:08,485 INFO org.apache.hadoop.yarn.server.resourcemanager.scheduler.common.fica.FiCaSchedulerNode: Assigned container container_1669272252091_0009_01_000002 of capacity <memory:2048, vCores:1> on host adh-hack-02-mnode3.ru-central1.internal:8041, which has 3 containers, <memory:5120, vCores:3> used and <memory:1937, vCores:-1> available after allocation
2022-11-24 07:17:08,485 INFO org.apache.hadoop.yarn.server.resourcemanager.RMAuditLogger: USER=spark	OPERATION=AM Allocated Container	TARGET=SchedulerApp	RESULT=SUCCESS	APPID=application_1669272252091_0009	CONTAINERID=container_1669272252091_0009_01_000002	RESOURCE=<memory:2048, vCores:1>	QUEUENAME=default
2022-11-24 07:17:08,485 INFO org.apache.hadoop.yarn.server.resourcemanager.scheduler.capacity.ParentQueue: assignedContainer queue=root usedCapacity=0.62878466 absoluteUsedCapacity=0.62878466 used=<memory:13312, vCores:8> cluster=<memory:21171, vCores:6>
2022-11-24 07:17:08,485 INFO org.apache.hadoop.yarn.server.resourcemanager.scheduler.capacity.CapacityScheduler: Allocation proposal accepted
2022-11-24 07:17:08,486 INFO org.apache.hadoop.yarn.server.resourcemanager.rmcontainer.RMContainerImpl: container_1669272252091_0008_01_000002 Container Transitioned from ACQUIRED to RUNNING
2022-11-24 07:17:08,486 INFO org.apache.hadoop.yarn.server.resourcemanager.scheduler.capacity.allocator.AbstractContainerAllocator: assignedContainer application attempt=appattempt_1669272252091_0009_000001 container=null queue=default clusterResource=<memory:21171, vCores:6> type=OFF_SWITCH requestedPartition=
2022-11-24 07:17:08,486 INFO org.apache.hadoop.yarn.server.resourcemanager.rmcontainer.RMContainerImpl: container_1669272252091_0009_01_000003 Container Transitioned from NEW to ALLOCATED
2022-11-24 07:17:08,486 INFO org.apache.hadoop.yarn.server.resourcemanager.scheduler.common.fica.FiCaSchedulerNode: Assigned container container_1669272252091_0009_01_000003 of capacity <memory:2048, vCores:1> on host adh-hack-02-mnode2.ru-central1.internal:8041, which has 3 containers, <memory:5120, vCores:3> used and <memory:1937, vCores:-1> available after allocation
2022-11-24 07:17:08,486 INFO org.apache.hadoop.yarn.server.resourcemanager.RMAuditLogger: USER=spark	OPERATION=AM Allocated Container	TARGET=SchedulerApp	RESULT=SUCCESS	APPID=application_1669272252091_0009	CONTAINERID=container_1669272252091_0009_01_000003	RESOURCE=<memory:2048, vCores:1>	QUEUENAME=default
2022-11-24 07:17:08,486 INFO org.apache.hadoop.yarn.server.resourcemanager.scheduler.capacity.ParentQueue: assignedContainer queue=root usedCapacity=0.72552073 absoluteUsedCapacity=0.72552073 used=<memory:15360, vCores:9> cluster=<memory:21171, vCores:6>
2022-11-24 07:17:08,486 INFO org.apache.hadoop.yarn.server.resourcemanager.scheduler.capacity.CapacityScheduler: Allocation proposal accepted
2022-11-24 07:17:08,749 INFO org.apache.hadoop.yarn.server.resourcemanager.rmcontainer.RMContainerImpl: container_1669272252091_0008_01_000003 Container Transitioned from ACQUIRED to RUNNING
2022-11-24 07:17:09,971 INFO org.apache.hadoop.yarn.server.resourcemanager.security.NMTokenSecretManagerInRM: Sending NMToken for nodeId : adh-hack-02-mnode3.ru-central1.internal:8041 for container : container_1669272252091_0009_01_000002
2022-11-24 07:17:09,974 INFO org.apache.hadoop.yarn.server.resourcemanager.rmcontainer.RMContainerImpl: container_1669272252091_0009_01_000002 Container Transitioned from ALLOCATED to ACQUIRED
2022-11-24 07:17:09,975 INFO org.apache.hadoop.yarn.server.resourcemanager.security.NMTokenSecretManagerInRM: Sending NMToken for nodeId : adh-hack-02-mnode2.ru-central1.internal:8041 for container : container_1669272252091_0009_01_000003
2022-11-24 07:17:09,976 INFO org.apache.hadoop.yarn.server.resourcemanager.rmcontainer.RMContainerImpl: container_1669272252091_0009_01_000003 Container Transitioned from ALLOCATED to ACQUIRED
2022-11-24 07:17:10,494 INFO org.apache.hadoop.yarn.server.resourcemanager.rmcontainer.RMContainerImpl: container_1669272252091_0009_01_000002 Container Transitioned from ACQUIRED to RUNNING
2022-11-24 07:17:10,495 INFO org.apache.hadoop.yarn.server.resourcemanager.rmcontainer.RMContainerImpl: container_1669272252091_0009_01_000003 Container Transitioned from ACQUIRED to RUNNING
2022-11-24 07:17:10,616 INFO org.apache.hadoop.yarn.server.resourcemanager.scheduler.AppSchedulingInfo: checking for deactivate of application :application_1669272252091_0007
2022-11-24 07:17:11,296 INFO org.apache.hadoop.yarn.server.resourcemanager.scheduler.AppSchedulingInfo: checking for deactivate of application :application_1669272252091_0008
2022-11-24 07:17:13,053 INFO org.apache.hadoop.yarn.server.resourcemanager.scheduler.AppSchedulingInfo: checking for deactivate of application :application_1669272252091_0009
2022-11-24 07:17:14,539 INFO org.apache.hadoop.yarn.server.resourcemanager.rmcontainer.RMContainerImpl: container_1669272252091_0007_01_000002 Container Transitioned from RUNNING to COMPLETED
2022-11-24 07:17:14,539 INFO org.apache.hadoop.yarn.server.resourcemanager.RMAuditLogger: USER=spark	OPERATION=AM Released Container	TARGET=SchedulerApp	RESULT=SUCCESS	APPID=application_1669272252091_0007	CONTAINERID=container_1669272252091_0007_01_000002	RESOURCE=<memory:2048, vCores:1>	QUEUENAME=default
2022-11-24 07:17:14,585 INFO org.apache.hadoop.yarn.server.resourcemanager.rmcontainer.RMContainerImpl: container_1669272252091_0007_01_000003 Container Transitioned from RUNNING to COMPLETED
2022-11-24 07:17:14,585 INFO org.apache.hadoop.yarn.server.resourcemanager.RMAuditLogger: USER=spark	OPERATION=AM Released Container	TARGET=SchedulerApp	RESULT=SUCCESS	APPID=application_1669272252091_0007	CONTAINERID=container_1669272252091_0007_01_000003	RESOURCE=<memory:2048, vCores:1>	QUEUENAME=default
2022-11-24 07:17:14,670 INFO org.apache.hadoop.yarn.server.resourcemanager.rmapp.attempt.RMAppAttemptImpl: Updating application attempt appattempt_1669272252091_0007_000001 with final state: FINISHING, and exit status: -1000
2022-11-24 07:17:14,670 INFO org.apache.hadoop.yarn.server.resourcemanager.rmapp.attempt.RMAppAttemptImpl: appattempt_1669272252091_0007_000001 State change from RUNNING to FINAL_SAVING on event = UNREGISTERED
2022-11-24 07:17:14,670 INFO org.apache.hadoop.yarn.server.resourcemanager.rmapp.RMAppImpl: Updating application application_1669272252091_0007 with final state: FINISHING
2022-11-24 07:17:14,670 INFO org.apache.hadoop.yarn.server.resourcemanager.rmapp.RMAppImpl: application_1669272252091_0007 State change from RUNNING to FINAL_SAVING on event = ATTEMPT_UNREGISTERED
2022-11-24 07:17:14,670 INFO org.apache.hadoop.yarn.server.resourcemanager.recovery.RMStateStore: Updating info for app: application_1669272252091_0007
2022-11-24 07:17:14,675 INFO org.apache.hadoop.yarn.server.resourcemanager.rmapp.attempt.RMAppAttemptImpl: appattempt_1669272252091_0007_000001 State change from FINAL_SAVING to FINISHING on event = ATTEMPT_UPDATE_SAVED
2022-11-24 07:17:14,675 INFO org.apache.hadoop.yarn.server.resourcemanager.rmapp.RMAppImpl: application_1669272252091_0007 State change from FINAL_SAVING to FINISHING on event = APP_UPDATE_SAVED
2022-11-24 07:17:14,776 INFO org.apache.hadoop.yarn.server.resourcemanager.ApplicationMasterService: application_1669272252091_0007 unregistered successfully. 
2022-11-24 07:17:15,187 INFO org.apache.hadoop.yarn.server.resourcemanager.rmcontainer.RMContainerImpl: container_1669272252091_0007_01_000001 Container Transitioned from RUNNING to COMPLETED
2022-11-24 07:17:15,187 INFO org.apache.hadoop.yarn.server.resourcemanager.RMAuditLogger: USER=spark	OPERATION=AM Released Container	TARGET=SchedulerApp	RESULT=SUCCESS	APPID=application_1669272252091_0007	CONTAINERID=container_1669272252091_0007_01_000001	RESOURCE=<memory:1024, vCores:1>	QUEUENAME=default
2022-11-24 07:17:15,187 INFO org.apache.hadoop.yarn.server.resourcemanager.ApplicationMasterService: Unregistering app attempt : appattempt_1669272252091_0007_000001
2022-11-24 07:17:15,187 INFO org.apache.hadoop.yarn.server.resourcemanager.security.AMRMTokenSecretManager: Application finished, removing password for appattempt_1669272252091_0007_000001
2022-11-24 07:17:15,187 INFO org.apache.hadoop.yarn.server.resourcemanager.rmapp.attempt.RMAppAttemptImpl: appattempt_1669272252091_0007_000001 State change from FINISHING to FINISHED on event = CONTAINER_FINISHED
2022-11-24 07:17:15,188 INFO org.apache.hadoop.yarn.server.resourcemanager.rmapp.RMAppImpl: application_1669272252091_0007 State change from FINISHING to FINISHED on event = ATTEMPT_FINISHED
2022-11-24 07:17:15,189 INFO org.apache.hadoop.yarn.server.resourcemanager.RMAuditLogger: USER=spark	OPERATION=Application Finished - Succeeded	TARGET=RMAppManager	RESULT=SUCCESS	APPID=application_1669272252091_0007
2022-11-24 07:17:15,189 INFO org.apache.hadoop.yarn.server.resourcemanager.RMAppManager$ApplicationSummary: appId=application_1669272252091_0007,name=Spark Pi,user=spark,queue=default,state=FINISHED,trackingUrl=http://adh-hack-02-mnode1.ru-central1.internal:8088/proxy/application_1669272252091_0007/,appMasterHost=10.129.0.154,submitTime=1669274220239,startTime=1669274220239,finishTime=1669274234670,finalStatus=SUCCEEDED,memorySeconds=45606,vcoreSeconds=28,preemptedMemorySeconds=0,preemptedVcoreSeconds=0,preemptedAMContainers=0,preemptedNonAMContainers=0,preemptedResources=<memory:0\, vCores:0>,applicationType=SPARK,resourceSeconds=45606 MB-seconds\, 28 vcore-seconds,preemptedResourceSeconds=0 MB-seconds\, 0 vcore-seconds
2022-11-24 07:17:15,189 INFO org.apache.hadoop.yarn.server.resourcemanager.scheduler.capacity.CapacityScheduler: Application Attempt appattempt_1669272252091_0007_000001 is done. finalState=FINISHED
2022-11-24 07:17:15,190 INFO org.apache.hadoop.yarn.server.resourcemanager.scheduler.AppSchedulingInfo: Application application_1669272252091_0007 requests cleared
2022-11-24 07:17:15,190 INFO org.apache.hadoop.yarn.server.resourcemanager.scheduler.capacity.LeafQueue: Application removed - appId: application_1669272252091_0007 user: spark queue: default #user-pending-applications: 0 #user-active-applications: 2 #queue-pending-applications: 0 #queue-active-applications: 2
2022-11-24 07:17:15,190 INFO org.apache.hadoop.yarn.server.resourcemanager.scheduler.capacity.ParentQueue: Application removed - appId: application_1669272252091_0007 user: spark leaf-queue of parent: root #applications: 2
2022-11-24 07:17:15,211 INFO org.apache.hadoop.yarn.server.resourcemanager.amlauncher.AMLauncher: Cleaning master appattempt_1669272252091_0007_000001
2022-11-24 07:17:15,510 INFO org.apache.hadoop.yarn.server.resourcemanager.rmcontainer.RMContainerImpl: container_1669272252091_0008_01_000002 Container Transitioned from RUNNING to COMPLETED
2022-11-24 07:17:15,510 INFO org.apache.hadoop.yarn.server.resourcemanager.RMAuditLogger: USER=spark	OPERATION=AM Released Container	TARGET=SchedulerApp	RESULT=SUCCESS	APPID=application_1669272252091_0008	CONTAINERID=container_1669272252091_0008_01_000002	RESOURCE=<memory:2048, vCores:1>	QUEUENAME=default
2022-11-24 07:17:15,689 INFO org.apache.hadoop.yarn.server.resourcemanager.rmapp.attempt.RMAppAttemptImpl: Updating application attempt appattempt_1669272252091_0008_000001 with final state: FINISHING, and exit status: -1000
2022-11-24 07:17:15,689 INFO org.apache.hadoop.yarn.server.resourcemanager.rmapp.attempt.RMAppAttemptImpl: appattempt_1669272252091_0008_000001 State change from RUNNING to FINAL_SAVING on event = UNREGISTERED
2022-11-24 07:17:15,689 INFO org.apache.hadoop.yarn.server.resourcemanager.rmapp.RMAppImpl: Updating application application_1669272252091_0008 with final state: FINISHING
2022-11-24 07:17:15,689 INFO org.apache.hadoop.yarn.server.resourcemanager.rmapp.RMAppImpl: application_1669272252091_0008 State change from RUNNING to FINAL_SAVING on event = ATTEMPT_UNREGISTERED
2022-11-24 07:17:15,690 INFO org.apache.hadoop.yarn.server.resourcemanager.recovery.RMStateStore: Updating info for app: application_1669272252091_0008
2022-11-24 07:17:15,690 INFO org.apache.hadoop.yarn.server.resourcemanager.rmapp.attempt.RMAppAttemptImpl: appattempt_1669272252091_0008_000001 State change from FINAL_SAVING to FINISHING on event = ATTEMPT_UPDATE_SAVED
2022-11-24 07:17:15,691 INFO org.apache.hadoop.yarn.server.resourcemanager.rmapp.RMAppImpl: application_1669272252091_0008 State change from FINAL_SAVING to FINISHING on event = APP_UPDATE_SAVED
2022-11-24 07:17:15,797 INFO org.apache.hadoop.yarn.server.resourcemanager.ApplicationMasterService: application_1669272252091_0008 unregistered successfully. 
2022-11-24 07:17:16,175 INFO org.apache.hadoop.yarn.server.resourcemanager.ApplicationMasterService: Unregistering app attempt : appattempt_1669272252091_0008_000001
2022-11-24 07:17:16,175 INFO org.apache.hadoop.yarn.server.resourcemanager.rmcontainer.RMContainerImpl: container_1669272252091_0008_01_000001 Container Transitioned from RUNNING to COMPLETED
2022-11-24 07:17:16,175 INFO org.apache.hadoop.yarn.server.resourcemanager.security.AMRMTokenSecretManager: Application finished, removing password for appattempt_1669272252091_0008_000001
2022-11-24 07:17:16,175 INFO org.apache.hadoop.yarn.server.resourcemanager.RMAuditLogger: USER=spark	OPERATION=AM Released Container	TARGET=SchedulerApp	RESULT=SUCCESS	APPID=application_1669272252091_0008	CONTAINERID=container_1669272252091_0008_01_000001	RESOURCE=<memory:1024, vCores:1>	QUEUENAME=default
2022-11-24 07:17:16,175 INFO org.apache.hadoop.yarn.server.resourcemanager.rmapp.attempt.RMAppAttemptImpl: appattempt_1669272252091_0008_000001 State change from FINISHING to FINISHED on event = CONTAINER_FINISHED
2022-11-24 07:17:16,177 INFO org.apache.hadoop.yarn.server.resourcemanager.rmapp.RMAppImpl: application_1669272252091_0008 State change from FINISHING to FINISHED on event = ATTEMPT_FINISHED
2022-11-24 07:17:16,177 INFO org.apache.hadoop.yarn.server.resourcemanager.scheduler.capacity.CapacityScheduler: Application Attempt appattempt_1669272252091_0008_000001 is done. finalState=FINISHED
2022-11-24 07:17:16,177 INFO org.apache.hadoop.yarn.server.resourcemanager.RMAuditLogger: USER=spark	OPERATION=Application Finished - Succeeded	TARGET=RMAppManager	RESULT=SUCCESS	APPID=application_1669272252091_0008
2022-11-24 07:17:16,177 INFO org.apache.hadoop.yarn.server.resourcemanager.rmcontainer.RMContainerImpl: container_1669272252091_0008_01_000003 Container Transitioned from RUNNING to KILLED
2022-11-24 07:17:16,177 INFO org.apache.hadoop.yarn.server.resourcemanager.RMAuditLogger: USER=spark	OPERATION=AM Released Container	TARGET=SchedulerApp	RESULT=SUCCESS	APPID=application_1669272252091_0008	CONTAINERID=container_1669272252091_0008_01_000003	RESOURCE=<memory:2048, vCores:1>	QUEUENAME=default
2022-11-24 07:17:16,177 INFO org.apache.hadoop.yarn.server.resourcemanager.RMAppManager$ApplicationSummary: appId=application_1669272252091_0008,name=Spark Pi,user=spark,queue=default,state=FINISHED,trackingUrl=http://adh-hack-02-mnode1.ru-central1.internal:8088/proxy/application_1669272252091_0008/,appMasterHost=10.129.0.155,submitTime=1669274220281,startTime=1669274220281,finishTime=1669274235689,finalStatus=SUCCEEDED,memorySeconds=49800,vcoreSeconds=31,preemptedMemorySeconds=0,preemptedVcoreSeconds=0,preemptedAMContainers=0,preemptedNonAMContainers=0,preemptedResources=<memory:0\, vCores:0>,applicationType=SPARK,resourceSeconds=49800 MB-seconds\, 31 vcore-seconds,preemptedResourceSeconds=0 MB-seconds\, 0 vcore-seconds
2022-11-24 07:17:16,177 INFO org.apache.hadoop.yarn.server.resourcemanager.scheduler.AppSchedulingInfo: Application application_1669272252091_0008 requests cleared
2022-11-24 07:17:16,177 INFO org.apache.hadoop.yarn.server.resourcemanager.scheduler.capacity.LeafQueue: Application removed - appId: application_1669272252091_0008 user: spark queue: default #user-pending-applications: 0 #user-active-applications: 1 #queue-pending-applications: 0 #queue-active-applications: 1
2022-11-24 07:17:16,177 INFO org.apache.hadoop.yarn.server.resourcemanager.scheduler.capacity.ParentQueue: Application removed - appId: application_1669272252091_0008 user: spark leaf-queue of parent: root #applications: 1
2022-11-24 07:17:16,178 INFO org.apache.hadoop.yarn.server.resourcemanager.amlauncher.AMLauncher: Cleaning master appattempt_1669272252091_0008_000001
2022-11-24 07:17:16,550 INFO org.apache.hadoop.yarn.server.resourcemanager.scheduler.AbstractYarnScheduler: Container container_1669272252091_0008_01_000003 completed with event FINISHED, but corresponding RMContainer doesn't exist.
2022-11-24 07:17:17,389 INFO org.apache.hadoop.yarn.server.resourcemanager.rmcontainer.RMContainerImpl: container_1669272252091_0009_01_000003 Container Transitioned from RUNNING to COMPLETED
2022-11-24 07:17:17,389 INFO org.apache.hadoop.yarn.server.resourcemanager.RMAuditLogger: USER=spark	OPERATION=AM Released Container	TARGET=SchedulerApp	RESULT=SUCCESS	APPID=application_1669272252091_0009	CONTAINERID=container_1669272252091_0009_01_000003	RESOURCE=<memory:2048, vCores:1>	QUEUENAME=default
2022-11-24 07:17:17,394 INFO org.apache.hadoop.yarn.server.resourcemanager.rmcontainer.RMContainerImpl: container_1669272252091_0009_01_000002 Container Transitioned from RUNNING to COMPLETED
2022-11-24 07:17:17,394 INFO org.apache.hadoop.yarn.server.resourcemanager.RMAuditLogger: USER=spark	OPERATION=AM Released Container	TARGET=SchedulerApp	RESULT=SUCCESS	APPID=application_1669272252091_0009	CONTAINERID=container_1669272252091_0009_01_000002	RESOURCE=<memory:2048, vCores:1>	QUEUENAME=default
2022-11-24 07:17:17,433 INFO org.apache.hadoop.yarn.server.resourcemanager.rmapp.attempt.RMAppAttemptImpl: Updating application attempt appattempt_1669272252091_0009_000001 with final state: FINISHING, and exit status: -1000
2022-11-24 07:17:17,433 INFO org.apache.hadoop.yarn.server.resourcemanager.rmapp.attempt.RMAppAttemptImpl: appattempt_1669272252091_0009_000001 State change from RUNNING to FINAL_SAVING on event = UNREGISTERED
2022-11-24 07:17:17,433 INFO org.apache.hadoop.yarn.server.resourcemanager.rmapp.RMAppImpl: Updating application application_1669272252091_0009 with final state: FINISHING
2022-11-24 07:17:17,433 INFO org.apache.hadoop.yarn.server.resourcemanager.rmapp.RMAppImpl: application_1669272252091_0009 State change from RUNNING to FINAL_SAVING on event = ATTEMPT_UNREGISTERED
2022-11-24 07:17:17,434 INFO org.apache.hadoop.yarn.server.resourcemanager.recovery.RMStateStore: Updating info for app: application_1669272252091_0009
2022-11-24 07:17:17,434 INFO org.apache.hadoop.yarn.server.resourcemanager.rmapp.attempt.RMAppAttemptImpl: appattempt_1669272252091_0009_000001 State change from FINAL_SAVING to FINISHING on event = ATTEMPT_UPDATE_SAVED
2022-11-24 07:17:17,434 INFO org.apache.hadoop.yarn.server.resourcemanager.rmapp.RMAppImpl: application_1669272252091_0009 State change from FINAL_SAVING to FINISHING on event = APP_UPDATE_SAVED
2022-11-24 07:17:17,537 INFO org.apache.hadoop.yarn.server.resourcemanager.ApplicationMasterService: application_1669272252091_0009 unregistered successfully. 
2022-11-24 07:17:17,552 INFO org.apache.hadoop.yarn.server.resourcemanager.scheduler.AbstractYarnScheduler: Container container_1669272252091_0008_01_000003 completed with event FINISHED, but corresponding RMContainer doesn't exist.
2022-11-24 07:17:17,911 INFO org.apache.hadoop.yarn.server.resourcemanager.ApplicationMasterService: Unregistering app attempt : appattempt_1669272252091_0009_000001
2022-11-24 07:17:17,911 INFO org.apache.hadoop.yarn.server.resourcemanager.rmcontainer.RMContainerImpl: container_1669272252091_0009_01_000001 Container Transitioned from RUNNING to COMPLETED
2022-11-24 07:17:17,911 INFO org.apache.hadoop.yarn.server.resourcemanager.security.AMRMTokenSecretManager: Application finished, removing password for appattempt_1669272252091_0009_000001
2022-11-24 07:17:17,911 INFO org.apache.hadoop.yarn.server.resourcemanager.RMAuditLogger: USER=spark	OPERATION=AM Released Container	TARGET=SchedulerApp	RESULT=SUCCESS	APPID=application_1669272252091_0009	CONTAINERID=container_1669272252091_0009_01_000001	RESOURCE=<memory:1024, vCores:1>	QUEUENAME=default
2022-11-24 07:17:17,911 INFO org.apache.hadoop.yarn.server.resourcemanager.rmapp.attempt.RMAppAttemptImpl: appattempt_1669272252091_0009_000001 State change from FINISHING to FINISHED on event = CONTAINER_FINISHED
2022-11-24 07:17:17,912 INFO org.apache.hadoop.yarn.server.resourcemanager.rmapp.RMAppImpl: application_1669272252091_0009 State change from FINISHING to FINISHED on event = ATTEMPT_FINISHED
2022-11-24 07:17:17,912 INFO org.apache.hadoop.yarn.server.resourcemanager.scheduler.capacity.CapacityScheduler: Application Attempt appattempt_1669272252091_0009_000001 is done. finalState=FINISHED
2022-11-24 07:17:17,912 INFO org.apache.hadoop.yarn.server.resourcemanager.scheduler.AppSchedulingInfo: Application application_1669272252091_0009 requests cleared
2022-11-24 07:17:17,912 INFO org.apache.hadoop.yarn.server.resourcemanager.RMAuditLogger: USER=spark	OPERATION=Application Finished - Succeeded	TARGET=RMAppManager	RESULT=SUCCESS	APPID=application_1669272252091_0009
2022-11-24 07:17:17,912 INFO org.apache.hadoop.yarn.server.resourcemanager.scheduler.capacity.LeafQueue: Application removed - appId: application_1669272252091_0009 user: spark queue: default #user-pending-applications: 0 #user-active-applications: 0 #queue-pending-applications: 0 #queue-active-applications: 0
2022-11-24 07:17:17,912 INFO org.apache.hadoop.yarn.server.resourcemanager.scheduler.capacity.ParentQueue: Application removed - appId: application_1669272252091_0009 user: spark leaf-queue of parent: root #applications: 0
2022-11-24 07:17:17,913 INFO org.apache.hadoop.yarn.server.resourcemanager.amlauncher.AMLauncher: Cleaning master appattempt_1669272252091_0009_000001
2022-11-24 07:17:17,913 INFO org.apache.hadoop.yarn.server.resourcemanager.RMAppManager$ApplicationSummary: appId=application_1669272252091_0009,name=Spark Pi,user=spark,queue=default,state=FINISHED,trackingUrl=http://adh-hack-02-mnode1.ru-central1.internal:8088/proxy/application_1669272252091_0009/,appMasterHost=10.129.0.153,submitTime=1669274220274,startTime=1669274220274,finishTime=1669274237433,finalStatus=SUCCEEDED,memorySeconds=54075,vcoreSeconds=33,preemptedMemorySeconds=0,preemptedVcoreSeconds=0,preemptedAMContainers=0,preemptedNonAMContainers=0,preemptedResources=<memory:0\, vCores:0>,applicationType=SPARK,resourceSeconds=54075 MB-seconds\, 33 vcore-seconds,preemptedResourceSeconds=0 MB-seconds\, 0 vcore-seconds
2022-11-24 07:17:32,138 INFO org.apache.hadoop.yarn.server.resourcemanager.ClientRMService: Allocated new applicationId: 10
2022-11-24 07:17:33,376 INFO org.apache.hadoop.yarn.server.resourcemanager.ClientRMService: Allocated new applicationId: 11
2022-11-24 07:17:33,449 INFO org.apache.hadoop.yarn.server.resourcemanager.ClientRMService: Allocated new applicationId: 12
2022-11-24 07:17:33,510 INFO org.apache.hadoop.yarn.server.resourcemanager.scheduler.capacity.CapacityScheduler: Application 'application_1669272252091_0010' is submitted without priority hence considering default queue/cluster priority: 0
2022-11-24 07:17:33,510 INFO org.apache.hadoop.yarn.server.resourcemanager.scheduler.capacity.CapacityScheduler: Priority '0' is acceptable in queue : default for application: application_1669272252091_0010
2022-11-24 07:17:33,510 WARN org.apache.hadoop.yarn.server.resourcemanager.rmapp.RMAppImpl: The specific max attempts: 0 for application: 10 is invalid, because it is out of the range [1, 2]. Use the global max attempts instead.
2022-11-24 07:17:33,510 INFO org.apache.hadoop.yarn.server.resourcemanager.ClientRMService: Application with id 10 submitted by user spark
2022-11-24 07:17:33,510 INFO org.apache.hadoop.yarn.server.resourcemanager.RMAuditLogger: USER=spark	IP=10.129.0.154	OPERATION=Submit Application Request	TARGET=ClientRMService	RESULT=SUCCESS	APPID=application_1669272252091_0010	QUEUENAME=default
2022-11-24 07:17:33,511 INFO org.apache.hadoop.yarn.server.resourcemanager.rmapp.RMAppImpl: Storing application with id application_1669272252091_0010
2022-11-24 07:17:33,511 INFO org.apache.hadoop.yarn.server.resourcemanager.rmapp.RMAppImpl: application_1669272252091_0010 State change from NEW to NEW_SAVING on event = START
2022-11-24 07:17:33,511 INFO org.apache.hadoop.yarn.server.resourcemanager.recovery.RMStateStore: Storing info for app: application_1669272252091_0010
2022-11-24 07:17:33,512 INFO org.apache.hadoop.yarn.server.resourcemanager.rmapp.RMAppImpl: application_1669272252091_0010 State change from NEW_SAVING to SUBMITTED on event = APP_NEW_SAVED
2022-11-24 07:17:33,512 INFO org.apache.hadoop.yarn.server.resourcemanager.scheduler.capacity.ParentQueue: Application added - appId: application_1669272252091_0010 user: spark leaf-queue of parent: root #applications: 1
2022-11-24 07:17:33,512 INFO org.apache.hadoop.yarn.server.resourcemanager.scheduler.capacity.CapacityScheduler: Accepted application application_1669272252091_0010 from user: spark, in queue: default
2022-11-24 07:17:33,512 INFO org.apache.hadoop.yarn.server.resourcemanager.rmapp.RMAppImpl: application_1669272252091_0010 State change from SUBMITTED to ACCEPTED on event = APP_ACCEPTED
2022-11-24 07:17:33,512 INFO org.apache.hadoop.yarn.server.resourcemanager.ApplicationMasterService: Registering app attempt : appattempt_1669272252091_0010_000001
2022-11-24 07:17:33,512 INFO org.apache.hadoop.yarn.server.resourcemanager.rmapp.attempt.RMAppAttemptImpl: appattempt_1669272252091_0010_000001 State change from NEW to SUBMITTED on event = START
2022-11-24 07:17:33,513 INFO org.apache.hadoop.yarn.server.resourcemanager.scheduler.capacity.LeafQueue: Application application_1669272252091_0010 from user: spark activated in queue: default
2022-11-24 07:17:33,513 INFO org.apache.hadoop.yarn.server.resourcemanager.scheduler.capacity.LeafQueue: Application added - appId: application_1669272252091_0010 user: spark, leaf-queue: default #user-pending-applications: 0 #user-active-applications: 1 #queue-pending-applications: 0 #queue-active-applications: 1
2022-11-24 07:17:33,513 INFO org.apache.hadoop.yarn.server.resourcemanager.scheduler.capacity.CapacityScheduler: Added Application Attempt appattempt_1669272252091_0010_000001 to scheduler from user spark in queue default
2022-11-24 07:17:33,515 INFO org.apache.hadoop.yarn.server.resourcemanager.rmapp.attempt.RMAppAttemptImpl: appattempt_1669272252091_0010_000001 State change from SUBMITTED to SCHEDULED on event = ATTEMPT_ADDED
2022-11-24 07:17:33,527 INFO org.apache.hadoop.yarn.server.resourcemanager.scheduler.capacity.allocator.AbstractContainerAllocator: assignedContainer application attempt=appattempt_1669272252091_0010_000001 container=null queue=default clusterResource=<memory:21171, vCores:6> type=OFF_SWITCH requestedPartition=
2022-11-24 07:17:33,528 INFO org.apache.hadoop.yarn.server.resourcemanager.rmcontainer.RMContainerImpl: container_1669272252091_0010_01_000001 Container Transitioned from NEW to ALLOCATED
2022-11-24 07:17:33,528 INFO org.apache.hadoop.yarn.server.resourcemanager.scheduler.common.fica.FiCaSchedulerNode: Assigned container container_1669272252091_0010_01_000001 of capacity <memory:1024, vCores:1> on host adh-hack-02-mnode3.ru-central1.internal:8041, which has 1 containers, <memory:1024, vCores:1> used and <memory:6033, vCores:1> available after allocation
2022-11-24 07:17:33,528 INFO org.apache.hadoop.yarn.server.resourcemanager.RMAuditLogger: USER=spark	OPERATION=AM Allocated Container	TARGET=SchedulerApp	RESULT=SUCCESS	APPID=application_1669272252091_0010	CONTAINERID=container_1669272252091_0010_01_000001	RESOURCE=<memory:1024, vCores:1>	QUEUENAME=default
2022-11-24 07:17:33,529 INFO org.apache.hadoop.yarn.server.resourcemanager.security.NMTokenSecretManagerInRM: Sending NMToken for nodeId : adh-hack-02-mnode3.ru-central1.internal:8041 for container : container_1669272252091_0010_01_000001
2022-11-24 07:17:33,529 INFO org.apache.hadoop.yarn.server.resourcemanager.rmcontainer.RMContainerImpl: container_1669272252091_0010_01_000001 Container Transitioned from ALLOCATED to ACQUIRED
2022-11-24 07:17:33,529 INFO org.apache.hadoop.yarn.server.resourcemanager.security.NMTokenSecretManagerInRM: Clear node set for appattempt_1669272252091_0010_000001
2022-11-24 07:17:33,529 INFO org.apache.hadoop.yarn.server.resourcemanager.rmapp.attempt.RMAppAttemptImpl: Storing attempt: AppId: application_1669272252091_0010 AttemptId: appattempt_1669272252091_0010_000001 MasterContainer: Container: [ContainerId: container_1669272252091_0010_01_000001, AllocationRequestId: -1, Version: 0, NodeId: adh-hack-02-mnode3.ru-central1.internal:8041, NodeHttpAddress: adh-hack-02-mnode3.ru-central1.internal:8042, Resource: <memory:1024, vCores:1>, Priority: 0, Token: Token { kind: ContainerToken, service: 10.129.0.155:8041 }, ExecutionType: GUARANTEED, ]
2022-11-24 07:17:33,529 INFO org.apache.hadoop.yarn.server.resourcemanager.scheduler.capacity.ParentQueue: assignedContainer queue=root usedCapacity=0.04836805 absoluteUsedCapacity=0.04836805 used=<memory:1024, vCores:1> cluster=<memory:21171, vCores:6>
2022-11-24 07:17:33,529 INFO org.apache.hadoop.yarn.server.resourcemanager.scheduler.capacity.CapacityScheduler: Allocation proposal accepted
2022-11-24 07:17:33,530 INFO org.apache.hadoop.yarn.server.resourcemanager.rmapp.attempt.RMAppAttemptImpl: appattempt_1669272252091_0010_000001 State change from SCHEDULED to ALLOCATED_SAVING on event = CONTAINER_ALLOCATED
2022-11-24 07:17:33,530 INFO org.apache.hadoop.yarn.server.resourcemanager.rmapp.attempt.RMAppAttemptImpl: appattempt_1669272252091_0010_000001 State change from ALLOCATED_SAVING to ALLOCATED on event = ATTEMPT_NEW_SAVED
2022-11-24 07:17:33,531 INFO org.apache.hadoop.yarn.server.resourcemanager.amlauncher.AMLauncher: Launching masterappattempt_1669272252091_0010_000001
2022-11-24 07:17:33,532 INFO org.apache.hadoop.yarn.server.resourcemanager.amlauncher.AMLauncher: Setting up container Container: [ContainerId: container_1669272252091_0010_01_000001, AllocationRequestId: -1, Version: 0, NodeId: adh-hack-02-mnode3.ru-central1.internal:8041, NodeHttpAddress: adh-hack-02-mnode3.ru-central1.internal:8042, Resource: <memory:1024, vCores:1>, Priority: 0, Token: Token { kind: ContainerToken, service: 10.129.0.155:8041 }, ExecutionType: GUARANTEED, ] for AM appattempt_1669272252091_0010_000001
2022-11-24 07:17:33,532 INFO org.apache.hadoop.yarn.server.resourcemanager.security.AMRMTokenSecretManager: Create AMRMToken for ApplicationAttempt: appattempt_1669272252091_0010_000001
2022-11-24 07:17:33,532 INFO org.apache.hadoop.yarn.server.resourcemanager.security.AMRMTokenSecretManager: Creating password for appattempt_1669272252091_0010_000001
2022-11-24 07:17:33,547 INFO org.apache.hadoop.yarn.server.resourcemanager.amlauncher.AMLauncher: Done launching container Container: [ContainerId: container_1669272252091_0010_01_000001, AllocationRequestId: -1, Version: 0, NodeId: adh-hack-02-mnode3.ru-central1.internal:8041, NodeHttpAddress: adh-hack-02-mnode3.ru-central1.internal:8042, Resource: <memory:1024, vCores:1>, Priority: 0, Token: Token { kind: ContainerToken, service: 10.129.0.155:8041 }, ExecutionType: GUARANTEED, ] for AM appattempt_1669272252091_0010_000001
2022-11-24 07:17:33,547 INFO org.apache.hadoop.yarn.server.resourcemanager.rmapp.attempt.RMAppAttemptImpl: appattempt_1669272252091_0010_000001 State change from ALLOCATED to LAUNCHED on event = LAUNCHED
2022-11-24 07:17:34,547 INFO org.apache.hadoop.yarn.server.resourcemanager.rmcontainer.RMContainerImpl: container_1669272252091_0010_01_000001 Container Transitioned from ACQUIRED to RUNNING
2022-11-24 07:17:35,054 INFO org.apache.hadoop.yarn.server.resourcemanager.scheduler.capacity.CapacityScheduler: Application 'application_1669272252091_0012' is submitted without priority hence considering default queue/cluster priority: 0
2022-11-24 07:17:35,054 INFO org.apache.hadoop.yarn.server.resourcemanager.scheduler.capacity.CapacityScheduler: Priority '0' is acceptable in queue : default for application: application_1669272252091_0012
2022-11-24 07:17:35,054 WARN org.apache.hadoop.yarn.server.resourcemanager.rmapp.RMAppImpl: The specific max attempts: 0 for application: 12 is invalid, because it is out of the range [1, 2]. Use the global max attempts instead.
2022-11-24 07:17:35,054 INFO org.apache.hadoop.yarn.server.resourcemanager.ClientRMService: Application with id 12 submitted by user spark
2022-11-24 07:17:35,054 INFO org.apache.hadoop.yarn.server.resourcemanager.RMAuditLogger: USER=spark	IP=10.129.0.153	OPERATION=Submit Application Request	TARGET=ClientRMService	RESULT=SUCCESS	APPID=application_1669272252091_0012	QUEUENAME=default
2022-11-24 07:17:35,055 INFO org.apache.hadoop.yarn.server.resourcemanager.rmapp.RMAppImpl: Storing application with id application_1669272252091_0012
2022-11-24 07:17:35,055 INFO org.apache.hadoop.yarn.server.resourcemanager.recovery.RMStateStore: Storing info for app: application_1669272252091_0012
2022-11-24 07:17:35,055 INFO org.apache.hadoop.yarn.server.resourcemanager.rmapp.RMAppImpl: application_1669272252091_0012 State change from NEW to NEW_SAVING on event = START
2022-11-24 07:17:35,056 INFO org.apache.hadoop.yarn.server.resourcemanager.rmapp.RMAppImpl: application_1669272252091_0012 State change from NEW_SAVING to SUBMITTED on event = APP_NEW_SAVED
2022-11-24 07:17:35,056 INFO org.apache.hadoop.yarn.server.resourcemanager.scheduler.capacity.ParentQueue: Application added - appId: application_1669272252091_0012 user: spark leaf-queue of parent: root #applications: 2
2022-11-24 07:17:35,056 INFO org.apache.hadoop.yarn.server.resourcemanager.scheduler.capacity.CapacityScheduler: Accepted application application_1669272252091_0012 from user: spark, in queue: default
2022-11-24 07:17:35,056 INFO org.apache.hadoop.yarn.server.resourcemanager.rmapp.RMAppImpl: application_1669272252091_0012 State change from SUBMITTED to ACCEPTED on event = APP_ACCEPTED
2022-11-24 07:17:35,056 INFO org.apache.hadoop.yarn.server.resourcemanager.ApplicationMasterService: Registering app attempt : appattempt_1669272252091_0012_000001
2022-11-24 07:17:35,056 INFO org.apache.hadoop.yarn.server.resourcemanager.rmapp.attempt.RMAppAttemptImpl: appattempt_1669272252091_0012_000001 State change from NEW to SUBMITTED on event = START
2022-11-24 07:17:35,057 INFO org.apache.hadoop.yarn.server.resourcemanager.scheduler.capacity.LeafQueue: Application application_1669272252091_0012 from user: spark activated in queue: default
2022-11-24 07:17:35,057 INFO org.apache.hadoop.yarn.server.resourcemanager.scheduler.capacity.LeafQueue: Application added - appId: application_1669272252091_0012 user: spark, leaf-queue: default #user-pending-applications: 0 #user-active-applications: 2 #queue-pending-applications: 0 #queue-active-applications: 2
2022-11-24 07:17:35,057 INFO org.apache.hadoop.yarn.server.resourcemanager.scheduler.capacity.CapacityScheduler: Added Application Attempt appattempt_1669272252091_0012_000001 to scheduler from user spark in queue default
2022-11-24 07:17:35,058 INFO org.apache.hadoop.yarn.server.resourcemanager.rmapp.attempt.RMAppAttemptImpl: appattempt_1669272252091_0012_000001 State change from SUBMITTED to SCHEDULED on event = ATTEMPT_ADDED
2022-11-24 07:17:35,291 INFO org.apache.hadoop.yarn.server.resourcemanager.scheduler.capacity.CapacityScheduler: Application 'application_1669272252091_0011' is submitted without priority hence considering default queue/cluster priority: 0
2022-11-24 07:17:35,291 INFO org.apache.hadoop.yarn.server.resourcemanager.scheduler.capacity.CapacityScheduler: Priority '0' is acceptable in queue : default for application: application_1669272252091_0011
2022-11-24 07:17:35,291 WARN org.apache.hadoop.yarn.server.resourcemanager.rmapp.RMAppImpl: The specific max attempts: 0 for application: 11 is invalid, because it is out of the range [1, 2]. Use the global max attempts instead.
2022-11-24 07:17:35,292 INFO org.apache.hadoop.yarn.server.resourcemanager.ClientRMService: Application with id 11 submitted by user spark
2022-11-24 07:17:35,292 INFO org.apache.hadoop.yarn.server.resourcemanager.RMAuditLogger: USER=spark	IP=10.129.0.155	OPERATION=Submit Application Request	TARGET=ClientRMService	RESULT=SUCCESS	APPID=application_1669272252091_0011	QUEUENAME=default
2022-11-24 07:17:35,292 INFO org.apache.hadoop.yarn.server.resourcemanager.rmapp.RMAppImpl: Storing application with id application_1669272252091_0011
2022-11-24 07:17:35,293 INFO org.apache.hadoop.yarn.server.resourcemanager.rmapp.RMAppImpl: application_1669272252091_0011 State change from NEW to NEW_SAVING on event = START
2022-11-24 07:17:35,293 INFO org.apache.hadoop.yarn.server.resourcemanager.recovery.RMStateStore: Storing info for app: application_1669272252091_0011
2022-11-24 07:17:35,293 INFO org.apache.hadoop.yarn.server.resourcemanager.rmapp.RMAppImpl: application_1669272252091_0011 State change from NEW_SAVING to SUBMITTED on event = APP_NEW_SAVED
2022-11-24 07:17:35,293 INFO org.apache.hadoop.yarn.server.resourcemanager.scheduler.capacity.ParentQueue: Application added - appId: application_1669272252091_0011 user: spark leaf-queue of parent: root #applications: 3
2022-11-24 07:17:35,293 INFO org.apache.hadoop.yarn.server.resourcemanager.scheduler.capacity.CapacityScheduler: Accepted application application_1669272252091_0011 from user: spark, in queue: default
2022-11-24 07:17:35,294 INFO org.apache.hadoop.yarn.server.resourcemanager.rmapp.RMAppImpl: application_1669272252091_0011 State change from SUBMITTED to ACCEPTED on event = APP_ACCEPTED
2022-11-24 07:17:35,294 INFO org.apache.hadoop.yarn.server.resourcemanager.ApplicationMasterService: Registering app attempt : appattempt_1669272252091_0011_000001
2022-11-24 07:17:35,294 INFO org.apache.hadoop.yarn.server.resourcemanager.rmapp.attempt.RMAppAttemptImpl: appattempt_1669272252091_0011_000001 State change from NEW to SUBMITTED on event = START
2022-11-24 07:17:35,295 INFO org.apache.hadoop.yarn.server.resourcemanager.scheduler.capacity.LeafQueue: Application application_1669272252091_0011 from user: spark activated in queue: default
2022-11-24 07:17:35,295 INFO org.apache.hadoop.yarn.server.resourcemanager.scheduler.capacity.LeafQueue: Application added - appId: application_1669272252091_0011 user: spark, leaf-queue: default #user-pending-applications: 0 #user-active-applications: 3 #queue-pending-applications: 0 #queue-active-applications: 3
2022-11-24 07:17:35,295 INFO org.apache.hadoop.yarn.server.resourcemanager.scheduler.capacity.CapacityScheduler: Added Application Attempt appattempt_1669272252091_0011_000001 to scheduler from user spark in queue default
2022-11-24 07:17:35,296 INFO org.apache.hadoop.yarn.server.resourcemanager.rmapp.attempt.RMAppAttemptImpl: appattempt_1669272252091_0011_000001 State change from SUBMITTED to SCHEDULED on event = ATTEMPT_ADDED
2022-11-24 07:17:35,507 INFO org.apache.hadoop.yarn.server.resourcemanager.scheduler.capacity.allocator.AbstractContainerAllocator: assignedContainer application attempt=appattempt_1669272252091_0011_000001 container=null queue=default clusterResource=<memory:21171, vCores:6> type=OFF_SWITCH requestedPartition=
2022-11-24 07:17:35,507 INFO org.apache.hadoop.yarn.server.resourcemanager.rmcontainer.RMContainerImpl: container_1669272252091_0011_01_000001 Container Transitioned from NEW to ALLOCATED
2022-11-24 07:17:35,507 INFO org.apache.hadoop.yarn.server.resourcemanager.scheduler.common.fica.FiCaSchedulerNode: Assigned container container_1669272252091_0011_01_000001 of capacity <memory:1024, vCores:1> on host adh-hack-02-mnode2.ru-central1.internal:8041, which has 1 containers, <memory:1024, vCores:1> used and <memory:6033, vCores:1> available after allocation
2022-11-24 07:17:35,507 INFO org.apache.hadoop.yarn.server.resourcemanager.RMAuditLogger: USER=spark	OPERATION=AM Allocated Container	TARGET=SchedulerApp	RESULT=SUCCESS	APPID=application_1669272252091_0011	CONTAINERID=container_1669272252091_0011_01_000001	RESOURCE=<memory:1024, vCores:1>	QUEUENAME=default
2022-11-24 07:17:35,507 INFO org.apache.hadoop.yarn.server.resourcemanager.scheduler.capacity.ParentQueue: assignedContainer queue=root usedCapacity=0.0967361 absoluteUsedCapacity=0.0967361 used=<memory:2048, vCores:2> cluster=<memory:21171, vCores:6>
2022-11-24 07:17:35,507 INFO org.apache.hadoop.yarn.server.resourcemanager.scheduler.capacity.CapacityScheduler: Allocation proposal accepted
2022-11-24 07:17:35,508 INFO org.apache.hadoop.yarn.server.resourcemanager.security.NMTokenSecretManagerInRM: Sending NMToken for nodeId : adh-hack-02-mnode2.ru-central1.internal:8041 for container : container_1669272252091_0011_01_000001
2022-11-24 07:17:35,509 INFO org.apache.hadoop.yarn.server.resourcemanager.rmcontainer.RMContainerImpl: container_1669272252091_0011_01_000001 Container Transitioned from ALLOCATED to ACQUIRED
2022-11-24 07:17:35,509 INFO org.apache.hadoop.yarn.server.resourcemanager.security.NMTokenSecretManagerInRM: Clear node set for appattempt_1669272252091_0011_000001
2022-11-24 07:17:35,509 INFO org.apache.hadoop.yarn.server.resourcemanager.rmapp.attempt.RMAppAttemptImpl: Storing attempt: AppId: application_1669272252091_0011 AttemptId: appattempt_1669272252091_0011_000001 MasterContainer: Container: [ContainerId: container_1669272252091_0011_01_000001, AllocationRequestId: -1, Version: 0, NodeId: adh-hack-02-mnode2.ru-central1.internal:8041, NodeHttpAddress: adh-hack-02-mnode2.ru-central1.internal:8042, Resource: <memory:1024, vCores:1>, Priority: 0, Token: Token { kind: ContainerToken, service: 10.129.0.154:8041 }, ExecutionType: GUARANTEED, ]
2022-11-24 07:17:35,509 INFO org.apache.hadoop.yarn.server.resourcemanager.rmapp.attempt.RMAppAttemptImpl: appattempt_1669272252091_0011_000001 State change from SCHEDULED to ALLOCATED_SAVING on event = CONTAINER_ALLOCATED
2022-11-24 07:17:35,510 INFO org.apache.hadoop.yarn.server.resourcemanager.rmapp.attempt.RMAppAttemptImpl: appattempt_1669272252091_0011_000001 State change from ALLOCATED_SAVING to ALLOCATED on event = ATTEMPT_NEW_SAVED
2022-11-24 07:17:35,511 INFO org.apache.hadoop.yarn.server.resourcemanager.amlauncher.AMLauncher: Launching masterappattempt_1669272252091_0011_000001
2022-11-24 07:17:35,512 INFO org.apache.hadoop.yarn.server.resourcemanager.amlauncher.AMLauncher: Setting up container Container: [ContainerId: container_1669272252091_0011_01_000001, AllocationRequestId: -1, Version: 0, NodeId: adh-hack-02-mnode2.ru-central1.internal:8041, NodeHttpAddress: adh-hack-02-mnode2.ru-central1.internal:8042, Resource: <memory:1024, vCores:1>, Priority: 0, Token: Token { kind: ContainerToken, service: 10.129.0.154:8041 }, ExecutionType: GUARANTEED, ] for AM appattempt_1669272252091_0011_000001
2022-11-24 07:17:35,512 INFO org.apache.hadoop.yarn.server.resourcemanager.security.AMRMTokenSecretManager: Create AMRMToken for ApplicationAttempt: appattempt_1669272252091_0011_000001
2022-11-24 07:17:35,512 INFO org.apache.hadoop.yarn.server.resourcemanager.security.AMRMTokenSecretManager: Creating password for appattempt_1669272252091_0011_000001
2022-11-24 07:17:35,532 INFO org.apache.hadoop.yarn.server.resourcemanager.amlauncher.AMLauncher: Done launching container Container: [ContainerId: container_1669272252091_0011_01_000001, AllocationRequestId: -1, Version: 0, NodeId: adh-hack-02-mnode2.ru-central1.internal:8041, NodeHttpAddress: adh-hack-02-mnode2.ru-central1.internal:8042, Resource: <memory:1024, vCores:1>, Priority: 0, Token: Token { kind: ContainerToken, service: 10.129.0.154:8041 }, ExecutionType: GUARANTEED, ] for AM appattempt_1669272252091_0011_000001
2022-11-24 07:17:35,532 INFO org.apache.hadoop.yarn.server.resourcemanager.rmapp.attempt.RMAppAttemptImpl: appattempt_1669272252091_0011_000001 State change from ALLOCATED to LAUNCHED on event = LAUNCHED
2022-11-24 07:17:35,553 INFO org.apache.hadoop.yarn.server.resourcemanager.scheduler.capacity.allocator.AbstractContainerAllocator: assignedContainer application attempt=appattempt_1669272252091_0012_000001 container=null queue=default clusterResource=<memory:21171, vCores:6> type=OFF_SWITCH requestedPartition=
2022-11-24 07:17:35,556 INFO org.apache.hadoop.yarn.server.resourcemanager.rmcontainer.RMContainerImpl: container_1669272252091_0012_01_000001 Container Transitioned from NEW to ALLOCATED
2022-11-24 07:17:35,556 INFO org.apache.hadoop.yarn.server.resourcemanager.scheduler.common.fica.FiCaSchedulerNode: Assigned container container_1669272252091_0012_01_000001 of capacity <memory:1024, vCores:1> on host adh-hack-02-mnode3.ru-central1.internal:8041, which has 2 containers, <memory:2048, vCores:2> used and <memory:5009, vCores:0> available after allocation
2022-11-24 07:17:35,556 INFO org.apache.hadoop.yarn.server.resourcemanager.RMAuditLogger: USER=spark	OPERATION=AM Allocated Container	TARGET=SchedulerApp	RESULT=SUCCESS	APPID=application_1669272252091_0012	CONTAINERID=container_1669272252091_0012_01_000001	RESOURCE=<memory:1024, vCores:1>	QUEUENAME=default
2022-11-24 07:17:35,557 INFO org.apache.hadoop.yarn.server.resourcemanager.security.NMTokenSecretManagerInRM: Sending NMToken for nodeId : adh-hack-02-mnode3.ru-central1.internal:8041 for container : container_1669272252091_0012_01_000001
2022-11-24 07:17:35,558 INFO org.apache.hadoop.yarn.server.resourcemanager.rmcontainer.RMContainerImpl: container_1669272252091_0012_01_000001 Container Transitioned from ALLOCATED to ACQUIRED
2022-11-24 07:17:35,558 INFO org.apache.hadoop.yarn.server.resourcemanager.security.NMTokenSecretManagerInRM: Clear node set for appattempt_1669272252091_0012_000001
2022-11-24 07:17:35,558 INFO org.apache.hadoop.yarn.server.resourcemanager.rmapp.attempt.RMAppAttemptImpl: Storing attempt: AppId: application_1669272252091_0012 AttemptId: appattempt_1669272252091_0012_000001 MasterContainer: Container: [ContainerId: container_1669272252091_0012_01_000001, AllocationRequestId: -1, Version: 0, NodeId: adh-hack-02-mnode3.ru-central1.internal:8041, NodeHttpAddress: adh-hack-02-mnode3.ru-central1.internal:8042, Resource: <memory:1024, vCores:1>, Priority: 0, Token: Token { kind: ContainerToken, service: 10.129.0.155:8041 }, ExecutionType: GUARANTEED, ]
2022-11-24 07:17:35,558 INFO org.apache.hadoop.yarn.server.resourcemanager.scheduler.capacity.ParentQueue: assignedContainer queue=root usedCapacity=0.14510415 absoluteUsedCapacity=0.14510415 used=<memory:3072, vCores:3> cluster=<memory:21171, vCores:6>
2022-11-24 07:17:35,558 INFO org.apache.hadoop.yarn.server.resourcemanager.scheduler.capacity.CapacityScheduler: Allocation proposal accepted
2022-11-24 07:17:35,558 INFO org.apache.hadoop.yarn.server.resourcemanager.rmapp.attempt.RMAppAttemptImpl: appattempt_1669272252091_0012_000001 State change from SCHEDULED to ALLOCATED_SAVING on event = CONTAINER_ALLOCATED
2022-11-24 07:17:35,560 INFO org.apache.hadoop.yarn.server.resourcemanager.rmapp.attempt.RMAppAttemptImpl: appattempt_1669272252091_0012_000001 State change from ALLOCATED_SAVING to ALLOCATED on event = ATTEMPT_NEW_SAVED
2022-11-24 07:17:35,560 INFO org.apache.hadoop.yarn.server.resourcemanager.amlauncher.AMLauncher: Launching masterappattempt_1669272252091_0012_000001
2022-11-24 07:17:35,561 INFO org.apache.hadoop.yarn.server.resourcemanager.amlauncher.AMLauncher: Setting up container Container: [ContainerId: container_1669272252091_0012_01_000001, AllocationRequestId: -1, Version: 0, NodeId: adh-hack-02-mnode3.ru-central1.internal:8041, NodeHttpAddress: adh-hack-02-mnode3.ru-central1.internal:8042, Resource: <memory:1024, vCores:1>, Priority: 0, Token: Token { kind: ContainerToken, service: 10.129.0.155:8041 }, ExecutionType: GUARANTEED, ] for AM appattempt_1669272252091_0012_000001
2022-11-24 07:17:35,561 INFO org.apache.hadoop.yarn.server.resourcemanager.security.AMRMTokenSecretManager: Create AMRMToken for ApplicationAttempt: appattempt_1669272252091_0012_000001
2022-11-24 07:17:35,561 INFO org.apache.hadoop.yarn.server.resourcemanager.security.AMRMTokenSecretManager: Creating password for appattempt_1669272252091_0012_000001
2022-11-24 07:17:35,576 INFO org.apache.hadoop.yarn.server.resourcemanager.amlauncher.AMLauncher: Done launching container Container: [ContainerId: container_1669272252091_0012_01_000001, AllocationRequestId: -1, Version: 0, NodeId: adh-hack-02-mnode3.ru-central1.internal:8041, NodeHttpAddress: adh-hack-02-mnode3.ru-central1.internal:8042, Resource: <memory:1024, vCores:1>, Priority: 0, Token: Token { kind: ContainerToken, service: 10.129.0.155:8041 }, ExecutionType: GUARANTEED, ] for AM appattempt_1669272252091_0012_000001
2022-11-24 07:17:35,577 INFO org.apache.hadoop.yarn.server.resourcemanager.rmapp.attempt.RMAppAttemptImpl: appattempt_1669272252091_0012_000001 State change from ALLOCATED to LAUNCHED on event = LAUNCHED
2022-11-24 07:17:36,508 INFO org.apache.hadoop.yarn.server.resourcemanager.rmcontainer.RMContainerImpl: container_1669272252091_0011_01_000001 Container Transitioned from ACQUIRED to RUNNING
2022-11-24 07:17:36,558 INFO org.apache.hadoop.yarn.server.resourcemanager.rmcontainer.RMContainerImpl: container_1669272252091_0012_01_000001 Container Transitioned from ACQUIRED to RUNNING
2022-11-24 07:17:37,083 INFO SecurityLogger.org.apache.hadoop.ipc.Server: Auth successful for appattempt_1669272252091_0010_000001 (auth:SIMPLE)
2022-11-24 07:17:37,116 INFO org.apache.hadoop.yarn.server.resourcemanager.DefaultAMSProcessor: AM registration appattempt_1669272252091_0010_000001
2022-11-24 07:17:37,116 INFO org.apache.hadoop.yarn.server.resourcemanager.RMAuditLogger: USER=spark	IP=10.129.0.155	OPERATION=Register App Master	TARGET=ApplicationMasterService	RESULT=SUCCESS	APPID=application_1669272252091_0010	APPATTEMPTID=appattempt_1669272252091_0010_000001
2022-11-24 07:17:37,116 INFO org.apache.hadoop.yarn.server.resourcemanager.rmapp.attempt.RMAppAttemptImpl: appattempt_1669272252091_0010_000001 State change from LAUNCHED to RUNNING on event = REGISTERED
2022-11-24 07:17:37,116 INFO org.apache.hadoop.yarn.server.resourcemanager.rmapp.RMAppImpl: application_1669272252091_0010 State change from ACCEPTED to RUNNING on event = ATTEMPT_REGISTERED
2022-11-24 07:17:38,203 INFO SecurityLogger.org.apache.hadoop.ipc.Server: Auth successful for appattempt_1669272252091_0011_000001 (auth:SIMPLE)
2022-11-24 07:17:38,218 INFO org.apache.hadoop.yarn.server.resourcemanager.DefaultAMSProcessor: AM registration appattempt_1669272252091_0011_000001
2022-11-24 07:17:38,218 INFO org.apache.hadoop.yarn.server.resourcemanager.RMAuditLogger: USER=spark	IP=10.129.0.154	OPERATION=Register App Master	TARGET=ApplicationMasterService	RESULT=SUCCESS	APPID=application_1669272252091_0011	APPATTEMPTID=appattempt_1669272252091_0011_000001
2022-11-24 07:17:38,218 INFO org.apache.hadoop.yarn.server.resourcemanager.rmapp.attempt.RMAppAttemptImpl: appattempt_1669272252091_0011_000001 State change from LAUNCHED to RUNNING on event = REGISTERED
2022-11-24 07:17:38,218 INFO org.apache.hadoop.yarn.server.resourcemanager.rmapp.RMAppImpl: application_1669272252091_0011 State change from ACCEPTED to RUNNING on event = ATTEMPT_REGISTERED
2022-11-24 07:17:39,524 INFO org.apache.hadoop.yarn.server.resourcemanager.scheduler.capacity.allocator.AbstractContainerAllocator: assignedContainer application attempt=appattempt_1669272252091_0010_000001 container=null queue=default clusterResource=<memory:21171, vCores:6> type=OFF_SWITCH requestedPartition=
2022-11-24 07:17:39,524 INFO org.apache.hadoop.yarn.server.resourcemanager.rmcontainer.RMContainerImpl: container_1669272252091_0010_01_000002 Container Transitioned from NEW to ALLOCATED
2022-11-24 07:17:39,525 INFO org.apache.hadoop.yarn.server.resourcemanager.scheduler.common.fica.FiCaSchedulerNode: Assigned container container_1669272252091_0010_01_000002 of capacity <memory:2048, vCores:1> on host adh-hack-02-mnode2.ru-central1.internal:8041, which has 2 containers, <memory:3072, vCores:2> used and <memory:3985, vCores:0> available after allocation
2022-11-24 07:17:39,525 INFO org.apache.hadoop.yarn.server.resourcemanager.RMAuditLogger: USER=spark	OPERATION=AM Allocated Container	TARGET=SchedulerApp	RESULT=SUCCESS	APPID=application_1669272252091_0010	CONTAINERID=container_1669272252091_0010_01_000002	RESOURCE=<memory:2048, vCores:1>	QUEUENAME=default
2022-11-24 07:17:39,525 INFO org.apache.hadoop.yarn.server.resourcemanager.scheduler.capacity.ParentQueue: assignedContainer queue=root usedCapacity=0.24184026 absoluteUsedCapacity=0.24184026 used=<memory:5120, vCores:4> cluster=<memory:21171, vCores:6>
2022-11-24 07:17:39,525 INFO org.apache.hadoop.yarn.server.resourcemanager.scheduler.capacity.CapacityScheduler: Allocation proposal accepted
2022-11-24 07:17:39,609 INFO org.apache.hadoop.yarn.server.resourcemanager.scheduler.capacity.allocator.AbstractContainerAllocator: assignedContainer application attempt=appattempt_1669272252091_0010_000001 container=null queue=default clusterResource=<memory:21171, vCores:6> type=OFF_SWITCH requestedPartition=
2022-11-24 07:17:39,610 INFO org.apache.hadoop.yarn.server.resourcemanager.rmcontainer.RMContainerImpl: container_1669272252091_0010_01_000003 Container Transitioned from NEW to ALLOCATED
2022-11-24 07:17:39,610 INFO org.apache.hadoop.yarn.server.resourcemanager.scheduler.common.fica.FiCaSchedulerNode: Assigned container container_1669272252091_0010_01_000003 of capacity <memory:2048, vCores:1> on host adh-hack-02-mnode3.ru-central1.internal:8041, which has 3 containers, <memory:4096, vCores:3> used and <memory:2961, vCores:-1> available after allocation
2022-11-24 07:17:39,610 INFO org.apache.hadoop.yarn.server.resourcemanager.RMAuditLogger: USER=spark	OPERATION=AM Allocated Container	TARGET=SchedulerApp	RESULT=SUCCESS	APPID=application_1669272252091_0010	CONTAINERID=container_1669272252091_0010_01_000003	RESOURCE=<memory:2048, vCores:1>	QUEUENAME=default
2022-11-24 07:17:39,610 INFO org.apache.hadoop.yarn.server.resourcemanager.scheduler.capacity.ParentQueue: assignedContainer queue=root usedCapacity=0.33857635 absoluteUsedCapacity=0.33857635 used=<memory:7168, vCores:5> cluster=<memory:21171, vCores:6>
2022-11-24 07:17:39,610 INFO org.apache.hadoop.yarn.server.resourcemanager.scheduler.capacity.CapacityScheduler: Allocation proposal accepted
2022-11-24 07:17:39,704 INFO org.apache.hadoop.yarn.server.resourcemanager.security.NMTokenSecretManagerInRM: Sending NMToken for nodeId : adh-hack-02-mnode2.ru-central1.internal:8041 for container : container_1669272252091_0010_01_000002
2022-11-24 07:17:39,705 INFO org.apache.hadoop.yarn.server.resourcemanager.rmcontainer.RMContainerImpl: container_1669272252091_0010_01_000002 Container Transitioned from ALLOCATED to ACQUIRED
2022-11-24 07:17:39,705 INFO org.apache.hadoop.yarn.server.resourcemanager.security.NMTokenSecretManagerInRM: Sending NMToken for nodeId : adh-hack-02-mnode3.ru-central1.internal:8041 for container : container_1669272252091_0010_01_000003
2022-11-24 07:17:39,706 INFO org.apache.hadoop.yarn.server.resourcemanager.rmcontainer.RMContainerImpl: container_1669272252091_0010_01_000003 Container Transitioned from ALLOCATED to ACQUIRED
2022-11-24 07:17:39,884 INFO SecurityLogger.org.apache.hadoop.ipc.Server: Auth successful for appattempt_1669272252091_0012_000001 (auth:SIMPLE)
2022-11-24 07:17:39,944 INFO org.apache.hadoop.yarn.server.resourcemanager.DefaultAMSProcessor: AM registration appattempt_1669272252091_0012_000001
2022-11-24 07:17:39,944 INFO org.apache.hadoop.yarn.server.resourcemanager.RMAuditLogger: USER=spark	IP=10.129.0.155	OPERATION=Register App Master	TARGET=ApplicationMasterService	RESULT=SUCCESS	APPID=application_1669272252091_0012	APPATTEMPTID=appattempt_1669272252091_0012_000001
2022-11-24 07:17:39,944 INFO org.apache.hadoop.yarn.server.resourcemanager.rmapp.attempt.RMAppAttemptImpl: appattempt_1669272252091_0012_000001 State change from LAUNCHED to RUNNING on event = REGISTERED
2022-11-24 07:17:39,944 INFO org.apache.hadoop.yarn.server.resourcemanager.rmapp.RMAppImpl: application_1669272252091_0012 State change from ACCEPTED to RUNNING on event = ATTEMPT_REGISTERED
2022-11-24 07:17:39,970 INFO org.apache.hadoop.yarn.server.resourcemanager.scheduler.capacity.allocator.AbstractContainerAllocator: assignedContainer application attempt=appattempt_1669272252091_0011_000001 container=null queue=default clusterResource=<memory:21171, vCores:6> type=OFF_SWITCH requestedPartition=
2022-11-24 07:17:39,970 INFO org.apache.hadoop.yarn.server.resourcemanager.rmcontainer.RMContainerImpl: container_1669272252091_0011_01_000002 Container Transitioned from NEW to ALLOCATED
2022-11-24 07:17:39,971 INFO org.apache.hadoop.yarn.server.resourcemanager.scheduler.common.fica.FiCaSchedulerNode: Assigned container container_1669272252091_0011_01_000002 of capacity <memory:2048, vCores:1> on host adh-hack-02-mnode1.ru-central1.internal:8041, which has 1 containers, <memory:2048, vCores:1> used and <memory:5009, vCores:1> available after allocation
2022-11-24 07:17:39,971 INFO org.apache.hadoop.yarn.server.resourcemanager.RMAuditLogger: USER=spark	OPERATION=AM Allocated Container	TARGET=SchedulerApp	RESULT=SUCCESS	APPID=application_1669272252091_0011	CONTAINERID=container_1669272252091_0011_01_000002	RESOURCE=<memory:2048, vCores:1>	QUEUENAME=default
2022-11-24 07:17:39,971 INFO org.apache.hadoop.yarn.server.resourcemanager.scheduler.capacity.ParentQueue: assignedContainer queue=root usedCapacity=0.43531245 absoluteUsedCapacity=0.43531245 used=<memory:9216, vCores:6> cluster=<memory:21171, vCores:6>
2022-11-24 07:17:39,971 INFO org.apache.hadoop.yarn.server.resourcemanager.scheduler.capacity.CapacityScheduler: Allocation proposal accepted
2022-11-24 07:17:40,128 INFO org.apache.hadoop.yarn.server.resourcemanager.security.NMTokenSecretManagerInRM: Sending NMToken for nodeId : adh-hack-02-mnode1.ru-central1.internal:8041 for container : container_1669272252091_0011_01_000002
2022-11-24 07:17:40,129 INFO org.apache.hadoop.yarn.server.resourcemanager.rmcontainer.RMContainerImpl: container_1669272252091_0011_01_000002 Container Transitioned from ALLOCATED to ACQUIRED
2022-11-24 07:17:40,534 INFO org.apache.hadoop.yarn.server.resourcemanager.rmcontainer.RMContainerImpl: container_1669272252091_0010_01_000002 Container Transitioned from ACQUIRED to RUNNING
2022-11-24 07:17:40,535 INFO org.apache.hadoop.yarn.server.resourcemanager.scheduler.capacity.allocator.AbstractContainerAllocator: assignedContainer application attempt=appattempt_1669272252091_0011_000001 container=null queue=default clusterResource=<memory:21171, vCores:6> type=OFF_SWITCH requestedPartition=
2022-11-24 07:17:40,536 INFO org.apache.hadoop.yarn.server.resourcemanager.rmcontainer.RMContainerImpl: container_1669272252091_0011_01_000003 Container Transitioned from NEW to ALLOCATED
2022-11-24 07:17:40,536 INFO org.apache.hadoop.yarn.server.resourcemanager.scheduler.common.fica.FiCaSchedulerNode: Assigned container container_1669272252091_0011_01_000003 of capacity <memory:2048, vCores:1> on host adh-hack-02-mnode2.ru-central1.internal:8041, which has 3 containers, <memory:5120, vCores:3> used and <memory:1937, vCores:-1> available after allocation
2022-11-24 07:17:40,536 INFO org.apache.hadoop.yarn.server.resourcemanager.RMAuditLogger: USER=spark	OPERATION=AM Allocated Container	TARGET=SchedulerApp	RESULT=SUCCESS	APPID=application_1669272252091_0011	CONTAINERID=container_1669272252091_0011_01_000003	RESOURCE=<memory:2048, vCores:1>	QUEUENAME=default
2022-11-24 07:17:40,536 INFO org.apache.hadoop.yarn.server.resourcemanager.scheduler.capacity.ParentQueue: assignedContainer queue=root usedCapacity=0.5320486 absoluteUsedCapacity=0.5320486 used=<memory:11264, vCores:7> cluster=<memory:21171, vCores:6>
2022-11-24 07:17:40,536 INFO org.apache.hadoop.yarn.server.resourcemanager.scheduler.capacity.CapacityScheduler: Allocation proposal accepted
2022-11-24 07:17:40,614 INFO org.apache.hadoop.yarn.server.resourcemanager.rmcontainer.RMContainerImpl: container_1669272252091_0010_01_000003 Container Transitioned from ACQUIRED to RUNNING
2022-11-24 07:17:40,792 INFO org.apache.hadoop.yarn.server.resourcemanager.security.NMTokenSecretManagerInRM: Sending NMToken for nodeId : adh-hack-02-mnode2.ru-central1.internal:8041 for container : container_1669272252091_0011_01_000003
2022-11-24 07:17:40,793 INFO org.apache.hadoop.yarn.server.resourcemanager.rmcontainer.RMContainerImpl: container_1669272252091_0011_01_000003 Container Transitioned from ALLOCATED to ACQUIRED
2022-11-24 07:17:40,971 INFO org.apache.hadoop.yarn.server.resourcemanager.rmcontainer.RMContainerImpl: container_1669272252091_0011_01_000002 Container Transitioned from ACQUIRED to RUNNING
2022-11-24 07:17:41,558 INFO org.apache.hadoop.yarn.server.resourcemanager.rmcontainer.RMContainerImpl: container_1669272252091_0011_01_000003 Container Transitioned from ACQUIRED to RUNNING
2022-11-24 07:17:41,998 INFO org.apache.hadoop.yarn.server.resourcemanager.scheduler.capacity.allocator.AbstractContainerAllocator: assignedContainer application attempt=appattempt_1669272252091_0012_000001 container=null queue=default clusterResource=<memory:21171, vCores:6> type=OFF_SWITCH requestedPartition=
2022-11-24 07:17:41,998 INFO org.apache.hadoop.yarn.server.resourcemanager.rmcontainer.RMContainerImpl: container_1669272252091_0012_01_000002 Container Transitioned from NEW to ALLOCATED
2022-11-24 07:17:41,998 INFO org.apache.hadoop.yarn.server.resourcemanager.scheduler.common.fica.FiCaSchedulerNode: Assigned container container_1669272252091_0012_01_000002 of capacity <memory:2048, vCores:1> on host adh-hack-02-mnode1.ru-central1.internal:8041, which has 2 containers, <memory:4096, vCores:2> used and <memory:2961, vCores:0> available after allocation
2022-11-24 07:17:41,998 INFO org.apache.hadoop.yarn.server.resourcemanager.RMAuditLogger: USER=spark	OPERATION=AM Allocated Container	TARGET=SchedulerApp	RESULT=SUCCESS	APPID=application_1669272252091_0012	CONTAINERID=container_1669272252091_0012_01_000002	RESOURCE=<memory:2048, vCores:1>	QUEUENAME=default
2022-11-24 07:17:41,998 INFO org.apache.hadoop.yarn.server.resourcemanager.scheduler.capacity.ParentQueue: assignedContainer queue=root usedCapacity=0.62878466 absoluteUsedCapacity=0.62878466 used=<memory:13312, vCores:8> cluster=<memory:21171, vCores:6>
2022-11-24 07:17:41,998 INFO org.apache.hadoop.yarn.server.resourcemanager.scheduler.capacity.CapacityScheduler: Allocation proposal accepted
2022-11-24 07:17:42,151 INFO org.apache.hadoop.yarn.server.resourcemanager.security.NMTokenSecretManagerInRM: Sending NMToken for nodeId : adh-hack-02-mnode1.ru-central1.internal:8041 for container : container_1669272252091_0012_01_000002
2022-11-24 07:17:42,152 INFO org.apache.hadoop.yarn.server.resourcemanager.rmcontainer.RMContainerImpl: container_1669272252091_0012_01_000002 Container Transitioned from ALLOCATED to ACQUIRED
2022-11-24 07:17:42,574 INFO org.apache.hadoop.yarn.server.resourcemanager.rmcontainer.RMContainerImpl: container_1669272252091_0012_01_000003 Container Transitioned from NEW to RESERVED
2022-11-24 07:17:42,574 INFO org.apache.hadoop.yarn.server.resourcemanager.scheduler.common.fica.FiCaSchedulerApp: Reserved container=container_1669272252091_0012_01_000003, on node=host: adh-hack-02-mnode2.ru-central1.internal:8041 #containers=3 available=<memory:1937, vCores:-1> used=<memory:5120, vCores:3> with resource=<memory:2048, vCores:1>
2022-11-24 07:17:42,574 INFO org.apache.hadoop.yarn.server.resourcemanager.scheduler.capacity.ParentQueue: assignedContainer queue=root usedCapacity=0.72552073 absoluteUsedCapacity=0.72552073 used=<memory:15360, vCores:9> cluster=<memory:21171, vCores:6>
2022-11-24 07:17:42,574 INFO org.apache.hadoop.yarn.server.resourcemanager.scheduler.capacity.CapacityScheduler: Allocation proposal accepted
2022-11-24 07:17:42,636 INFO org.apache.hadoop.yarn.server.resourcemanager.scheduler.capacity.allocator.AbstractContainerAllocator: assignedContainer application attempt=appattempt_1669272252091_0012_000001 container=null queue=default clusterResource=<memory:21171, vCores:6> type=OFF_SWITCH requestedPartition=
2022-11-24 07:17:42,637 INFO org.apache.hadoop.yarn.server.resourcemanager.rmcontainer.RMContainerImpl: container_1669272252091_0012_01_000004 Container Transitioned from NEW to ALLOCATED
2022-11-24 07:17:42,637 INFO org.apache.hadoop.yarn.server.resourcemanager.scheduler.common.fica.FiCaSchedulerNode: Assigned container container_1669272252091_0012_01_000004 of capacity <memory:2048, vCores:1> on host adh-hack-02-mnode3.ru-central1.internal:8041, which has 4 containers, <memory:6144, vCores:4> used and <memory:913, vCores:-2> available after allocation
2022-11-24 07:17:42,637 INFO org.apache.hadoop.yarn.server.resourcemanager.RMAuditLogger: USER=spark	OPERATION=AM Allocated Container	TARGET=SchedulerApp	RESULT=SUCCESS	APPID=application_1669272252091_0012	CONTAINERID=container_1669272252091_0012_01_000004	RESOURCE=<memory:2048, vCores:1>	QUEUENAME=default
2022-11-24 07:17:42,637 INFO org.apache.hadoop.yarn.server.resourcemanager.scheduler.common.fica.FiCaSchedulerApp: Application application_1669272252091_0012 unreserved  on node host: adh-hack-02-mnode2.ru-central1.internal:8041 #containers=3 available=<memory:1937, vCores:-1> used=<memory:5120, vCores:3>, currently has 0 at priority 0; currentReservation <memory:0, vCores:0> on node-label=
2022-11-24 07:17:42,638 INFO org.apache.hadoop.yarn.server.resourcemanager.scheduler.capacity.ParentQueue: assignedContainer queue=root usedCapacity=0.72552073 absoluteUsedCapacity=0.72552073 used=<memory:15360, vCores:9> cluster=<memory:21171, vCores:6>
2022-11-24 07:17:42,638 INFO org.apache.hadoop.yarn.server.resourcemanager.scheduler.capacity.CapacityScheduler: Allocation proposal accepted
2022-11-24 07:17:42,751 INFO org.apache.hadoop.yarn.server.resourcemanager.scheduler.AppSchedulingInfo: checking for deactivate of application :application_1669272252091_0010
2022-11-24 07:17:42,835 INFO org.apache.hadoop.yarn.server.resourcemanager.security.NMTokenSecretManagerInRM: Sending NMToken for nodeId : adh-hack-02-mnode3.ru-central1.internal:8041 for container : container_1669272252091_0012_01_000004
2022-11-24 07:17:42,836 INFO org.apache.hadoop.yarn.server.resourcemanager.rmcontainer.RMContainerImpl: container_1669272252091_0012_01_000004 Container Transitioned from ALLOCATED to ACQUIRED
2022-11-24 07:17:43,000 INFO org.apache.hadoop.yarn.server.resourcemanager.rmcontainer.RMContainerImpl: container_1669272252091_0012_01_000002 Container Transitioned from ACQUIRED to RUNNING
2022-11-24 07:17:43,645 INFO org.apache.hadoop.yarn.server.resourcemanager.rmcontainer.RMContainerImpl: container_1669272252091_0012_01_000004 Container Transitioned from ACQUIRED to RUNNING
2022-11-24 07:17:43,819 INFO org.apache.hadoop.yarn.server.resourcemanager.scheduler.AppSchedulingInfo: checking for deactivate of application :application_1669272252091_0011
2022-11-24 07:17:45,847 INFO org.apache.hadoop.yarn.server.resourcemanager.scheduler.AppSchedulingInfo: checking for deactivate of application :application_1669272252091_0012
2022-11-24 07:17:51,173 INFO org.apache.hadoop.yarn.server.resourcemanager.rmcontainer.RMContainerImpl: container_1669272252091_0010_01_000002 Container Transitioned from RUNNING to COMPLETED
2022-11-24 07:17:51,173 INFO org.apache.hadoop.yarn.server.resourcemanager.RMAuditLogger: USER=spark	OPERATION=AM Released Container	TARGET=SchedulerApp	RESULT=SUCCESS	APPID=application_1669272252091_0010	CONTAINERID=container_1669272252091_0010_01_000002	RESOURCE=<memory:2048, vCores:1>	QUEUENAME=default
2022-11-24 07:17:51,295 INFO org.apache.hadoop.yarn.server.resourcemanager.rmapp.attempt.RMAppAttemptImpl: Updating application attempt appattempt_1669272252091_0010_000001 with final state: FINISHING, and exit status: -1000
2022-11-24 07:17:51,295 INFO org.apache.hadoop.yarn.server.resourcemanager.rmapp.attempt.RMAppAttemptImpl: appattempt_1669272252091_0010_000001 State change from RUNNING to FINAL_SAVING on event = UNREGISTERED
2022-11-24 07:17:51,295 INFO org.apache.hadoop.yarn.server.resourcemanager.rmapp.RMAppImpl: Updating application application_1669272252091_0010 with final state: FINISHING
2022-11-24 07:17:51,295 INFO org.apache.hadoop.yarn.server.resourcemanager.rmapp.RMAppImpl: application_1669272252091_0010 State change from RUNNING to FINAL_SAVING on event = ATTEMPT_UNREGISTERED
2022-11-24 07:17:51,296 INFO org.apache.hadoop.yarn.server.resourcemanager.recovery.RMStateStore: Updating info for app: application_1669272252091_0010
2022-11-24 07:17:51,297 INFO org.apache.hadoop.yarn.server.resourcemanager.rmapp.attempt.RMAppAttemptImpl: appattempt_1669272252091_0010_000001 State change from FINAL_SAVING to FINISHING on event = ATTEMPT_UPDATE_SAVED
2022-11-24 07:17:51,297 INFO org.apache.hadoop.yarn.server.resourcemanager.rmapp.RMAppImpl: application_1669272252091_0010 State change from FINAL_SAVING to FINISHING on event = APP_UPDATE_SAVED
2022-11-24 07:17:51,316 INFO org.apache.hadoop.yarn.server.resourcemanager.rmcontainer.RMContainerImpl: container_1669272252091_0010_01_000003 Container Transitioned from RUNNING to COMPLETED
2022-11-24 07:17:51,317 INFO org.apache.hadoop.yarn.server.resourcemanager.RMAuditLogger: USER=spark	OPERATION=AM Released Container	TARGET=SchedulerApp	RESULT=SUCCESS	APPID=application_1669272252091_0010	CONTAINERID=container_1669272252091_0010_01_000003	RESOURCE=<memory:2048, vCores:1>	QUEUENAME=default
2022-11-24 07:17:51,407 INFO org.apache.hadoop.yarn.server.resourcemanager.ApplicationMasterService: application_1669272252091_0010 unregistered successfully. 
2022-11-24 07:17:51,942 INFO org.apache.hadoop.yarn.server.resourcemanager.rmcontainer.RMContainerImpl: container_1669272252091_0010_01_000001 Container Transitioned from RUNNING to COMPLETED
2022-11-24 07:17:51,942 INFO org.apache.hadoop.yarn.server.resourcemanager.RMAuditLogger: USER=spark	OPERATION=AM Released Container	TARGET=SchedulerApp	RESULT=SUCCESS	APPID=application_1669272252091_0010	CONTAINERID=container_1669272252091_0010_01_000001	RESOURCE=<memory:1024, vCores:1>	QUEUENAME=default
2022-11-24 07:17:51,942 INFO org.apache.hadoop.yarn.server.resourcemanager.ApplicationMasterService: Unregistering app attempt : appattempt_1669272252091_0010_000001
2022-11-24 07:17:51,942 INFO org.apache.hadoop.yarn.server.resourcemanager.security.AMRMTokenSecretManager: Application finished, removing password for appattempt_1669272252091_0010_000001
2022-11-24 07:17:51,943 INFO org.apache.hadoop.yarn.server.resourcemanager.rmapp.attempt.RMAppAttemptImpl: appattempt_1669272252091_0010_000001 State change from FINISHING to FINISHED on event = CONTAINER_FINISHED
2022-11-24 07:17:51,944 INFO org.apache.hadoop.yarn.server.resourcemanager.rmapp.RMAppImpl: application_1669272252091_0010 State change from FINISHING to FINISHED on event = ATTEMPT_FINISHED
2022-11-24 07:17:51,944 INFO org.apache.hadoop.yarn.server.resourcemanager.RMAuditLogger: USER=spark	OPERATION=Application Finished - Succeeded	TARGET=RMAppManager	RESULT=SUCCESS	APPID=application_1669272252091_0010
2022-11-24 07:17:51,944 INFO org.apache.hadoop.yarn.server.resourcemanager.RMAppManager$ApplicationSummary: appId=application_1669272252091_0010,name=Spark shell,user=spark,queue=default,state=FINISHED,trackingUrl=http://adh-hack-02-mnode1.ru-central1.internal:8088/proxy/application_1669272252091_0010/,appMasterHost=10.129.0.155,submitTime=1669274253510,startTime=1669274253510,finishTime=1669274271295,finalStatus=SUCCEEDED,memorySeconds=66687,vcoreSeconds=40,preemptedMemorySeconds=0,preemptedVcoreSeconds=0,preemptedAMContainers=0,preemptedNonAMContainers=0,preemptedResources=<memory:0\, vCores:0>,applicationType=SPARK,resourceSeconds=66687 MB-seconds\, 40 vcore-seconds,preemptedResourceSeconds=0 MB-seconds\, 0 vcore-seconds
2022-11-24 07:17:51,944 INFO org.apache.hadoop.yarn.server.resourcemanager.scheduler.capacity.CapacityScheduler: Application Attempt appattempt_1669272252091_0010_000001 is done. finalState=FINISHED
2022-11-24 07:17:51,945 INFO org.apache.hadoop.yarn.server.resourcemanager.scheduler.AppSchedulingInfo: Application application_1669272252091_0010 requests cleared
2022-11-24 07:17:51,945 INFO org.apache.hadoop.yarn.server.resourcemanager.scheduler.capacity.LeafQueue: Application removed - appId: application_1669272252091_0010 user: spark queue: default #user-pending-applications: 0 #user-active-applications: 2 #queue-pending-applications: 0 #queue-active-applications: 2
2022-11-24 07:17:51,945 INFO org.apache.hadoop.yarn.server.resourcemanager.scheduler.capacity.ParentQueue: Application removed - appId: application_1669272252091_0010 user: spark leaf-queue of parent: root #applications: 2
2022-11-24 07:17:51,947 INFO org.apache.hadoop.yarn.server.resourcemanager.amlauncher.AMLauncher: Cleaning master appattempt_1669272252091_0010_000001
2022-11-24 07:17:53,993 INFO org.apache.hadoop.yarn.server.resourcemanager.rmcontainer.RMContainerImpl: container_1669272252091_0011_01_000003 Container Transitioned from RUNNING to COMPLETED
2022-11-24 07:17:53,993 INFO org.apache.hadoop.yarn.server.resourcemanager.RMAuditLogger: USER=spark	OPERATION=AM Released Container	TARGET=SchedulerApp	RESULT=SUCCESS	APPID=application_1669272252091_0011	CONTAINERID=container_1669272252091_0011_01_000003	RESOURCE=<memory:2048, vCores:1>	QUEUENAME=default
2022-11-24 07:17:54,067 INFO org.apache.hadoop.yarn.server.resourcemanager.rmcontainer.RMContainerImpl: container_1669272252091_0011_01_000002 Container Transitioned from RUNNING to COMPLETED
2022-11-24 07:17:54,067 INFO org.apache.hadoop.yarn.server.resourcemanager.RMAuditLogger: USER=spark	OPERATION=AM Released Container	TARGET=SchedulerApp	RESULT=SUCCESS	APPID=application_1669272252091_0011	CONTAINERID=container_1669272252091_0011_01_000002	RESOURCE=<memory:2048, vCores:1>	QUEUENAME=default
2022-11-24 07:17:54,144 INFO org.apache.hadoop.yarn.server.resourcemanager.rmapp.attempt.RMAppAttemptImpl: Updating application attempt appattempt_1669272252091_0011_000001 with final state: FINISHING, and exit status: -1000
2022-11-24 07:17:54,144 INFO org.apache.hadoop.yarn.server.resourcemanager.rmapp.attempt.RMAppAttemptImpl: appattempt_1669272252091_0011_000001 State change from RUNNING to FINAL_SAVING on event = UNREGISTERED
2022-11-24 07:17:54,144 INFO org.apache.hadoop.yarn.server.resourcemanager.rmapp.RMAppImpl: Updating application application_1669272252091_0011 with final state: FINISHING
2022-11-24 07:17:54,144 INFO org.apache.hadoop.yarn.server.resourcemanager.rmapp.RMAppImpl: application_1669272252091_0011 State change from RUNNING to FINAL_SAVING on event = ATTEMPT_UNREGISTERED
2022-11-24 07:17:54,144 INFO org.apache.hadoop.yarn.server.resourcemanager.recovery.RMStateStore: Updating info for app: application_1669272252091_0011
2022-11-24 07:17:54,144 INFO org.apache.hadoop.yarn.server.resourcemanager.rmapp.attempt.RMAppAttemptImpl: appattempt_1669272252091_0011_000001 State change from FINAL_SAVING to FINISHING on event = ATTEMPT_UPDATE_SAVED
2022-11-24 07:17:54,145 INFO org.apache.hadoop.yarn.server.resourcemanager.rmapp.RMAppImpl: application_1669272252091_0011 State change from FINAL_SAVING to FINISHING on event = APP_UPDATE_SAVED
2022-11-24 07:17:54,164 INFO org.apache.hadoop.yarn.server.resourcemanager.rmcontainer.RMContainerImpl: container_1669272252091_0012_01_000002 Container Transitioned from RUNNING to COMPLETED
2022-11-24 07:17:54,164 INFO org.apache.hadoop.yarn.server.resourcemanager.RMAuditLogger: USER=spark	OPERATION=AM Released Container	TARGET=SchedulerApp	RESULT=SUCCESS	APPID=application_1669272252091_0012	CONTAINERID=container_1669272252091_0012_01_000002	RESOURCE=<memory:2048, vCores:1>	QUEUENAME=default
2022-11-24 07:17:54,165 INFO org.apache.hadoop.yarn.server.resourcemanager.rmcontainer.RMContainerImpl: container_1669272252091_0012_01_000004 Container Transitioned from RUNNING to COMPLETED
2022-11-24 07:17:54,166 INFO org.apache.hadoop.yarn.server.resourcemanager.RMAuditLogger: USER=spark	OPERATION=AM Released Container	TARGET=SchedulerApp	RESULT=SUCCESS	APPID=application_1669272252091_0012	CONTAINERID=container_1669272252091_0012_01_000004	RESOURCE=<memory:2048, vCores:1>	QUEUENAME=default
2022-11-24 07:17:54,203 INFO org.apache.hadoop.yarn.server.resourcemanager.rmapp.attempt.RMAppAttemptImpl: Updating application attempt appattempt_1669272252091_0012_000001 with final state: FINISHING, and exit status: -1000
2022-11-24 07:17:54,203 INFO org.apache.hadoop.yarn.server.resourcemanager.rmapp.attempt.RMAppAttemptImpl: appattempt_1669272252091_0012_000001 State change from RUNNING to FINAL_SAVING on event = UNREGISTERED
2022-11-24 07:17:54,203 INFO org.apache.hadoop.yarn.server.resourcemanager.rmapp.RMAppImpl: Updating application application_1669272252091_0012 with final state: FINISHING
2022-11-24 07:17:54,203 INFO org.apache.hadoop.yarn.server.resourcemanager.rmapp.RMAppImpl: application_1669272252091_0012 State change from RUNNING to FINAL_SAVING on event = ATTEMPT_UNREGISTERED
2022-11-24 07:17:54,203 INFO org.apache.hadoop.yarn.server.resourcemanager.recovery.RMStateStore: Updating info for app: application_1669272252091_0012
2022-11-24 07:17:54,203 INFO org.apache.hadoop.yarn.server.resourcemanager.rmapp.attempt.RMAppAttemptImpl: appattempt_1669272252091_0012_000001 State change from FINAL_SAVING to FINISHING on event = ATTEMPT_UPDATE_SAVED
2022-11-24 07:17:54,204 INFO org.apache.hadoop.yarn.server.resourcemanager.rmapp.RMAppImpl: application_1669272252091_0012 State change from FINAL_SAVING to FINISHING on event = APP_UPDATE_SAVED
2022-11-24 07:17:54,247 INFO org.apache.hadoop.yarn.server.resourcemanager.ApplicationMasterService: application_1669272252091_0011 unregistered successfully. 
2022-11-24 07:17:54,308 INFO org.apache.hadoop.yarn.server.resourcemanager.ApplicationMasterService: application_1669272252091_0012 unregistered successfully. 
2022-11-24 07:17:54,617 INFO org.apache.hadoop.yarn.server.resourcemanager.ApplicationMasterService: Unregistering app attempt : appattempt_1669272252091_0011_000001
2022-11-24 07:17:54,617 INFO org.apache.hadoop.yarn.server.resourcemanager.rmcontainer.RMContainerImpl: container_1669272252091_0011_01_000001 Container Transitioned from RUNNING to COMPLETED
2022-11-24 07:17:54,617 INFO org.apache.hadoop.yarn.server.resourcemanager.security.AMRMTokenSecretManager: Application finished, removing password for appattempt_1669272252091_0011_000001
2022-11-24 07:17:54,617 INFO org.apache.hadoop.yarn.server.resourcemanager.RMAuditLogger: USER=spark	OPERATION=AM Released Container	TARGET=SchedulerApp	RESULT=SUCCESS	APPID=application_1669272252091_0011	CONTAINERID=container_1669272252091_0011_01_000001	RESOURCE=<memory:1024, vCores:1>	QUEUENAME=default
2022-11-24 07:17:54,617 INFO org.apache.hadoop.yarn.server.resourcemanager.rmapp.attempt.RMAppAttemptImpl: appattempt_1669272252091_0011_000001 State change from FINISHING to FINISHED on event = CONTAINER_FINISHED
2022-11-24 07:17:54,620 INFO org.apache.hadoop.yarn.server.resourcemanager.rmapp.RMAppImpl: application_1669272252091_0011 State change from FINISHING to FINISHED on event = ATTEMPT_FINISHED
2022-11-24 07:17:54,620 INFO org.apache.hadoop.yarn.server.resourcemanager.scheduler.capacity.CapacityScheduler: Application Attempt appattempt_1669272252091_0011_000001 is done. finalState=FINISHED
2022-11-24 07:17:54,620 INFO org.apache.hadoop.yarn.server.resourcemanager.scheduler.AppSchedulingInfo: Application application_1669272252091_0011 requests cleared
2022-11-24 07:17:54,620 INFO org.apache.hadoop.yarn.server.resourcemanager.RMAuditLogger: USER=spark	OPERATION=Application Finished - Succeeded	TARGET=RMAppManager	RESULT=SUCCESS	APPID=application_1669272252091_0011
2022-11-24 07:17:54,620 INFO org.apache.hadoop.yarn.server.resourcemanager.scheduler.capacity.LeafQueue: Application removed - appId: application_1669272252091_0011 user: spark queue: default #user-pending-applications: 0 #user-active-applications: 1 #queue-pending-applications: 0 #queue-active-applications: 1
2022-11-24 07:17:54,620 INFO org.apache.hadoop.yarn.server.resourcemanager.scheduler.capacity.ParentQueue: Application removed - appId: application_1669272252091_0011 user: spark leaf-queue of parent: root #applications: 1
2022-11-24 07:17:54,620 INFO org.apache.hadoop.yarn.server.resourcemanager.amlauncher.AMLauncher: Cleaning master appattempt_1669272252091_0011_000001
2022-11-24 07:17:54,621 INFO org.apache.hadoop.yarn.server.resourcemanager.RMAppManager$ApplicationSummary: appId=application_1669272252091_0011,name=Spark shell,user=spark,queue=default,state=FINISHED,trackingUrl=http://adh-hack-02-mnode1.ru-central1.internal:8088/proxy/application_1669272252091_0011/,appMasterHost=10.129.0.154,submitTime=1669274255291,startTime=1669274255291,finishTime=1669274274144,finalStatus=SUCCEEDED,memorySeconds=75999,vcoreSeconds=46,preemptedMemorySeconds=0,preemptedVcoreSeconds=0,preemptedAMContainers=0,preemptedNonAMContainers=0,preemptedResources=<memory:0\, vCores:0>,applicationType=SPARK,resourceSeconds=75999 MB-seconds\, 46 vcore-seconds,preemptedResourceSeconds=0 MB-seconds\, 0 vcore-seconds
2022-11-24 07:17:54,695 INFO org.apache.hadoop.yarn.server.resourcemanager.ApplicationMasterService: Unregistering app attempt : appattempt_1669272252091_0012_000001
2022-11-24 07:17:54,695 INFO org.apache.hadoop.yarn.server.resourcemanager.rmcontainer.RMContainerImpl: container_1669272252091_0012_01_000001 Container Transitioned from RUNNING to COMPLETED
2022-11-24 07:17:54,695 INFO org.apache.hadoop.yarn.server.resourcemanager.security.AMRMTokenSecretManager: Application finished, removing password for appattempt_1669272252091_0012_000001
2022-11-24 07:17:54,696 INFO org.apache.hadoop.yarn.server.resourcemanager.RMAuditLogger: USER=spark	OPERATION=AM Released Container	TARGET=SchedulerApp	RESULT=SUCCESS	APPID=application_1669272252091_0012	CONTAINERID=container_1669272252091_0012_01_000001	RESOURCE=<memory:1024, vCores:1>	QUEUENAME=default
2022-11-24 07:17:54,696 INFO org.apache.hadoop.yarn.server.resourcemanager.rmapp.attempt.RMAppAttemptImpl: appattempt_1669272252091_0012_000001 State change from FINISHING to FINISHED on event = CONTAINER_FINISHED
2022-11-24 07:17:54,699 INFO org.apache.hadoop.yarn.server.resourcemanager.rmapp.RMAppImpl: application_1669272252091_0012 State change from FINISHING to FINISHED on event = ATTEMPT_FINISHED
2022-11-24 07:17:54,699 INFO org.apache.hadoop.yarn.server.resourcemanager.RMAuditLogger: USER=spark	OPERATION=Application Finished - Succeeded	TARGET=RMAppManager	RESULT=SUCCESS	APPID=application_1669272252091_0012
2022-11-24 07:17:54,699 INFO org.apache.hadoop.yarn.server.resourcemanager.RMAppManager$ApplicationSummary: appId=application_1669272252091_0012,name=Spark shell,user=spark,queue=default,state=FINISHED,trackingUrl=http://adh-hack-02-mnode1.ru-central1.internal:8088/proxy/application_1669272252091_0012/,appMasterHost=10.129.0.155,submitTime=1669274255053,startTime=1669274255054,finishTime=1669274274203,finalStatus=SUCCEEDED,memorySeconds=68127,vcoreSeconds=42,preemptedMemorySeconds=0,preemptedVcoreSeconds=0,preemptedAMContainers=0,preemptedNonAMContainers=0,preemptedResources=<memory:0\, vCores:0>,applicationType=SPARK,resourceSeconds=68127 MB-seconds\, 42 vcore-seconds,preemptedResourceSeconds=0 MB-seconds\, 0 vcore-seconds
2022-11-24 07:17:54,699 INFO org.apache.hadoop.yarn.server.resourcemanager.scheduler.capacity.CapacityScheduler: Application Attempt appattempt_1669272252091_0012_000001 is done. finalState=FINISHED
2022-11-24 07:17:54,699 INFO org.apache.hadoop.yarn.server.resourcemanager.scheduler.AppSchedulingInfo: Application application_1669272252091_0012 requests cleared
2022-11-24 07:17:54,700 INFO org.apache.hadoop.yarn.server.resourcemanager.amlauncher.AMLauncher: Cleaning master appattempt_1669272252091_0012_000001
2022-11-24 07:17:54,700 INFO org.apache.hadoop.yarn.server.resourcemanager.scheduler.capacity.LeafQueue: Application removed - appId: application_1669272252091_0012 user: spark queue: default #user-pending-applications: 0 #user-active-applications: 0 #queue-pending-applications: 0 #queue-active-applications: 0
2022-11-24 07:17:54,702 INFO org.apache.hadoop.yarn.server.resourcemanager.scheduler.capacity.ParentQueue: Application removed - appId: application_1669272252091_0012 user: spark leaf-queue of parent: root #applications: 0
2022-11-24 07:44:12,209 INFO org.apache.hadoop.yarn.server.resourcemanager.recovery.LeveldbRMStateStore: Starting full compaction cycle
2022-11-24 07:44:12,215 INFO org.apache.hadoop.yarn.server.resourcemanager.recovery.LeveldbRMStateStore: Full compaction cycle completed in 6 msec
2022-11-24 08:44:12,209 INFO org.apache.hadoop.yarn.server.resourcemanager.recovery.LeveldbRMStateStore: Starting full compaction cycle
2022-11-24 08:44:12,234 INFO org.apache.hadoop.yarn.server.resourcemanager.recovery.LeveldbRMStateStore: Full compaction cycle completed in 25 msec
2022-11-24 09:44:12,209 INFO org.apache.hadoop.yarn.server.resourcemanager.recovery.LeveldbRMStateStore: Starting full compaction cycle
2022-11-24 09:44:12,261 INFO org.apache.hadoop.yarn.server.resourcemanager.recovery.LeveldbRMStateStore: Full compaction cycle completed in 52 msec
2022-11-24 10:44:12,209 INFO org.apache.hadoop.yarn.server.resourcemanager.recovery.LeveldbRMStateStore: Starting full compaction cycle
2022-11-24 10:44:12,225 INFO org.apache.hadoop.yarn.server.resourcemanager.recovery.LeveldbRMStateStore: Full compaction cycle completed in 16 msec
2022-11-24 11:44:12,209 INFO org.apache.hadoop.yarn.server.resourcemanager.recovery.LeveldbRMStateStore: Starting full compaction cycle
2022-11-24 11:44:12,231 INFO org.apache.hadoop.yarn.server.resourcemanager.recovery.LeveldbRMStateStore: Full compaction cycle completed in 22 msec
2022-11-24 12:44:12,209 INFO org.apache.hadoop.yarn.server.resourcemanager.recovery.LeveldbRMStateStore: Starting full compaction cycle
2022-11-24 12:44:12,218 INFO org.apache.hadoop.yarn.server.resourcemanager.recovery.LeveldbRMStateStore: Full compaction cycle completed in 9 msec
2022-11-24 13:44:12,210 INFO org.apache.hadoop.yarn.server.resourcemanager.recovery.LeveldbRMStateStore: Starting full compaction cycle
2022-11-24 13:44:12,228 INFO org.apache.hadoop.yarn.server.resourcemanager.recovery.LeveldbRMStateStore: Full compaction cycle completed in 19 msec
2022-11-24 14:44:12,210 INFO org.apache.hadoop.yarn.server.resourcemanager.recovery.LeveldbRMStateStore: Starting full compaction cycle
2022-11-24 14:44:12,231 INFO org.apache.hadoop.yarn.server.resourcemanager.recovery.LeveldbRMStateStore: Full compaction cycle completed in 21 msec
2022-11-24 15:44:12,210 INFO org.apache.hadoop.yarn.server.resourcemanager.recovery.LeveldbRMStateStore: Starting full compaction cycle
2022-11-24 15:44:12,219 INFO org.apache.hadoop.yarn.server.resourcemanager.recovery.LeveldbRMStateStore: Full compaction cycle completed in 9 msec
2022-11-24 16:44:12,210 INFO org.apache.hadoop.yarn.server.resourcemanager.recovery.LeveldbRMStateStore: Starting full compaction cycle
2022-11-24 16:44:12,215 INFO org.apache.hadoop.yarn.server.resourcemanager.recovery.LeveldbRMStateStore: Full compaction cycle completed in 4 msec
2022-11-24 17:44:12,210 INFO org.apache.hadoop.yarn.server.resourcemanager.recovery.LeveldbRMStateStore: Starting full compaction cycle
2022-11-24 17:44:12,219 INFO org.apache.hadoop.yarn.server.resourcemanager.recovery.LeveldbRMStateStore: Full compaction cycle completed in 9 msec
2022-11-24 18:44:12,210 INFO org.apache.hadoop.yarn.server.resourcemanager.recovery.LeveldbRMStateStore: Starting full compaction cycle
2022-11-24 18:44:12,215 INFO org.apache.hadoop.yarn.server.resourcemanager.recovery.LeveldbRMStateStore: Full compaction cycle completed in 5 msec
2022-11-24 19:44:12,210 INFO org.apache.hadoop.yarn.server.resourcemanager.recovery.LeveldbRMStateStore: Starting full compaction cycle
2022-11-24 19:44:12,224 INFO org.apache.hadoop.yarn.server.resourcemanager.recovery.LeveldbRMStateStore: Full compaction cycle completed in 14 msec
2022-11-24 20:44:12,210 INFO org.apache.hadoop.yarn.server.resourcemanager.recovery.LeveldbRMStateStore: Starting full compaction cycle
2022-11-24 20:44:12,219 INFO org.apache.hadoop.yarn.server.resourcemanager.recovery.LeveldbRMStateStore: Full compaction cycle completed in 9 msec
2022-11-24 21:44:12,211 INFO org.apache.hadoop.yarn.server.resourcemanager.recovery.LeveldbRMStateStore: Starting full compaction cycle
2022-11-24 21:44:12,225 INFO org.apache.hadoop.yarn.server.resourcemanager.recovery.LeveldbRMStateStore: Full compaction cycle completed in 14 msec
2022-11-24 22:44:12,212 INFO org.apache.hadoop.yarn.server.resourcemanager.recovery.LeveldbRMStateStore: Starting full compaction cycle
2022-11-24 22:44:12,222 INFO org.apache.hadoop.yarn.server.resourcemanager.recovery.LeveldbRMStateStore: Full compaction cycle completed in 10 msec
2022-11-24 23:44:12,212 INFO org.apache.hadoop.yarn.server.resourcemanager.recovery.LeveldbRMStateStore: Starting full compaction cycle
2022-11-24 23:44:12,222 INFO org.apache.hadoop.yarn.server.resourcemanager.recovery.LeveldbRMStateStore: Full compaction cycle completed in 9 msec
2022-11-25 00:44:12,212 INFO org.apache.hadoop.yarn.server.resourcemanager.recovery.LeveldbRMStateStore: Starting full compaction cycle
2022-11-25 00:44:12,230 INFO org.apache.hadoop.yarn.server.resourcemanager.recovery.LeveldbRMStateStore: Full compaction cycle completed in 17 msec
2022-11-25 01:44:12,212 INFO org.apache.hadoop.yarn.server.resourcemanager.recovery.LeveldbRMStateStore: Starting full compaction cycle
2022-11-25 01:44:12,216 INFO org.apache.hadoop.yarn.server.resourcemanager.recovery.LeveldbRMStateStore: Full compaction cycle completed in 4 msec
2022-11-25 02:44:12,213 INFO org.apache.hadoop.yarn.server.resourcemanager.recovery.LeveldbRMStateStore: Starting full compaction cycle
2022-11-25 02:44:12,228 INFO org.apache.hadoop.yarn.server.resourcemanager.recovery.LeveldbRMStateStore: Full compaction cycle completed in 16 msec
2022-11-25 03:44:12,212 INFO org.apache.hadoop.yarn.server.resourcemanager.recovery.LeveldbRMStateStore: Starting full compaction cycle
2022-11-25 03:44:12,217 INFO org.apache.hadoop.yarn.server.resourcemanager.recovery.LeveldbRMStateStore: Full compaction cycle completed in 5 msec
2022-11-25 04:44:12,212 INFO org.apache.hadoop.yarn.server.resourcemanager.recovery.LeveldbRMStateStore: Starting full compaction cycle
2022-11-25 04:44:12,233 INFO org.apache.hadoop.yarn.server.resourcemanager.recovery.LeveldbRMStateStore: Full compaction cycle completed in 21 msec
2022-11-25 05:44:12,212 INFO org.apache.hadoop.yarn.server.resourcemanager.recovery.LeveldbRMStateStore: Starting full compaction cycle
2022-11-25 05:44:12,217 INFO org.apache.hadoop.yarn.server.resourcemanager.recovery.LeveldbRMStateStore: Full compaction cycle completed in 5 msec
2022-11-25 06:44:12,212 INFO org.apache.hadoop.yarn.server.resourcemanager.recovery.LeveldbRMStateStore: Starting full compaction cycle
2022-11-25 06:44:12,222 INFO org.apache.hadoop.yarn.server.resourcemanager.recovery.LeveldbRMStateStore: Full compaction cycle completed in 10 msec
2022-11-25 06:44:12,228 INFO org.apache.hadoop.yarn.server.resourcemanager.security.AMRMTokenSecretManager: Rolling master-key for amrm-tokens
2022-11-25 06:44:12,228 INFO org.apache.hadoop.yarn.server.resourcemanager.security.RMContainerTokenSecretManager: Rolling master-key for container-tokens
2022-11-25 06:44:12,228 INFO org.apache.hadoop.yarn.server.resourcemanager.recovery.RMStateStore: Updating AMRMToken
2022-11-25 06:44:12,228 INFO org.apache.hadoop.yarn.server.resourcemanager.security.NMTokenSecretManagerInRM: Rolling master-key for nm-tokens
2022-11-25 06:44:12,228 INFO org.apache.hadoop.yarn.server.resourcemanager.security.RMContainerTokenSecretManager: Going to activate master-key with key-id 702718028 in 900000ms
2022-11-25 06:44:12,228 INFO org.apache.hadoop.yarn.server.resourcemanager.security.NMTokenSecretManagerInRM: Going to activate master-key with key-id -1724748003 in 900000ms
2022-11-25 06:44:13,455 INFO org.apache.hadoop.security.token.delegation.AbstractDelegationTokenSecretManager: Updating the current master key for generating delegation tokens
2022-11-25 06:44:14,657 INFO org.apache.hadoop.security.token.delegation.AbstractDelegationTokenSecretManager: Updating the current master key for generating delegation tokens
2022-11-25 06:44:14,657 INFO org.apache.hadoop.yarn.server.resourcemanager.security.RMDelegationTokenSecretManager: storing master key with keyID 3
2022-11-25 06:44:14,657 INFO org.apache.hadoop.yarn.server.resourcemanager.recovery.RMStateStore: Storing RMDTMasterKey.
2022-11-25 06:59:12,229 INFO org.apache.hadoop.yarn.server.resourcemanager.security.RMContainerTokenSecretManager: Activating next master key with id: 702718028
2022-11-25 06:59:12,229 INFO org.apache.hadoop.yarn.server.resourcemanager.security.NMTokenSecretManagerInRM: Activating next master key with id: -1724748003
2022-11-25 06:59:12,229 INFO org.apache.hadoop.yarn.server.resourcemanager.security.AMRMTokenSecretManager: Activating next master key with id: 2079740288
2022-11-25 06:59:12,229 INFO org.apache.hadoop.yarn.server.resourcemanager.recovery.RMStateStore: Updating AMRMToken
2022-11-25 07:44:12,212 INFO org.apache.hadoop.yarn.server.resourcemanager.recovery.LeveldbRMStateStore: Starting full compaction cycle
2022-11-25 07:44:12,224 INFO org.apache.hadoop.yarn.server.resourcemanager.recovery.LeveldbRMStateStore: Full compaction cycle completed in 12 msec
2022-11-25 08:44:12,213 INFO org.apache.hadoop.yarn.server.resourcemanager.recovery.LeveldbRMStateStore: Starting full compaction cycle
2022-11-25 08:44:12,228 INFO org.apache.hadoop.yarn.server.resourcemanager.recovery.LeveldbRMStateStore: Full compaction cycle completed in 15 msec
2022-11-25 09:44:12,213 INFO org.apache.hadoop.yarn.server.resourcemanager.recovery.LeveldbRMStateStore: Starting full compaction cycle
2022-11-25 09:44:12,218 INFO org.apache.hadoop.yarn.server.resourcemanager.recovery.LeveldbRMStateStore: Full compaction cycle completed in 5 msec
2022-11-25 10:44:12,213 INFO org.apache.hadoop.yarn.server.resourcemanager.recovery.LeveldbRMStateStore: Starting full compaction cycle
2022-11-25 10:44:12,217 INFO org.apache.hadoop.yarn.server.resourcemanager.recovery.LeveldbRMStateStore: Full compaction cycle completed in 4 msec
2022-11-25 11:44:12,213 INFO org.apache.hadoop.yarn.server.resourcemanager.recovery.LeveldbRMStateStore: Starting full compaction cycle
2022-11-25 11:44:12,219 INFO org.apache.hadoop.yarn.server.resourcemanager.recovery.LeveldbRMStateStore: Full compaction cycle completed in 6 msec
2022-11-25 12:44:12,213 INFO org.apache.hadoop.yarn.server.resourcemanager.recovery.LeveldbRMStateStore: Starting full compaction cycle
2022-11-25 12:44:12,223 INFO org.apache.hadoop.yarn.server.resourcemanager.recovery.LeveldbRMStateStore: Full compaction cycle completed in 10 msec
2022-11-25 13:44:12,213 INFO org.apache.hadoop.yarn.server.resourcemanager.recovery.LeveldbRMStateStore: Starting full compaction cycle
2022-11-25 13:44:12,225 INFO org.apache.hadoop.yarn.server.resourcemanager.recovery.LeveldbRMStateStore: Full compaction cycle completed in 12 msec
2022-11-25 14:44:12,213 INFO org.apache.hadoop.yarn.server.resourcemanager.recovery.LeveldbRMStateStore: Starting full compaction cycle
2022-11-25 14:44:12,219 INFO org.apache.hadoop.yarn.server.resourcemanager.recovery.LeveldbRMStateStore: Full compaction cycle completed in 6 msec
2022-11-25 15:44:12,213 INFO org.apache.hadoop.yarn.server.resourcemanager.recovery.LeveldbRMStateStore: Starting full compaction cycle
2022-11-25 15:44:12,230 INFO org.apache.hadoop.yarn.server.resourcemanager.recovery.LeveldbRMStateStore: Full compaction cycle completed in 17 msec
2022-11-25 16:44:12,213 INFO org.apache.hadoop.yarn.server.resourcemanager.recovery.LeveldbRMStateStore: Starting full compaction cycle
2022-11-25 16:44:12,217 INFO org.apache.hadoop.yarn.server.resourcemanager.recovery.LeveldbRMStateStore: Full compaction cycle completed in 4 msec
2022-11-25 17:44:12,213 INFO org.apache.hadoop.yarn.server.resourcemanager.recovery.LeveldbRMStateStore: Starting full compaction cycle
2022-11-25 17:44:12,216 INFO org.apache.hadoop.yarn.server.resourcemanager.recovery.LeveldbRMStateStore: Full compaction cycle completed in 3 msec
2022-11-25 18:44:12,213 INFO org.apache.hadoop.yarn.server.resourcemanager.recovery.LeveldbRMStateStore: Starting full compaction cycle
2022-11-25 18:44:12,231 INFO org.apache.hadoop.yarn.server.resourcemanager.recovery.LeveldbRMStateStore: Full compaction cycle completed in 17 msec
2022-11-25 19:44:12,213 INFO org.apache.hadoop.yarn.server.resourcemanager.recovery.LeveldbRMStateStore: Starting full compaction cycle
2022-11-25 19:44:12,223 INFO org.apache.hadoop.yarn.server.resourcemanager.recovery.LeveldbRMStateStore: Full compaction cycle completed in 10 msec
2022-11-25 20:44:12,213 INFO org.apache.hadoop.yarn.server.resourcemanager.recovery.LeveldbRMStateStore: Starting full compaction cycle
2022-11-25 20:44:12,219 INFO org.apache.hadoop.yarn.server.resourcemanager.recovery.LeveldbRMStateStore: Full compaction cycle completed in 6 msec
2022-11-25 21:44:12,214 INFO org.apache.hadoop.yarn.server.resourcemanager.recovery.LeveldbRMStateStore: Starting full compaction cycle
2022-11-25 21:44:12,217 INFO org.apache.hadoop.yarn.server.resourcemanager.recovery.LeveldbRMStateStore: Full compaction cycle completed in 3 msec
2022-11-25 22:44:12,215 INFO org.apache.hadoop.yarn.server.resourcemanager.recovery.LeveldbRMStateStore: Starting full compaction cycle
2022-11-25 22:44:12,220 INFO org.apache.hadoop.yarn.server.resourcemanager.recovery.LeveldbRMStateStore: Full compaction cycle completed in 5 msec
2022-11-25 23:44:12,215 INFO org.apache.hadoop.yarn.server.resourcemanager.recovery.LeveldbRMStateStore: Starting full compaction cycle
2022-11-25 23:44:12,219 INFO org.apache.hadoop.yarn.server.resourcemanager.recovery.LeveldbRMStateStore: Full compaction cycle completed in 4 msec
2022-11-26 00:44:12,216 INFO org.apache.hadoop.yarn.server.resourcemanager.recovery.LeveldbRMStateStore: Starting full compaction cycle
2022-11-26 00:44:12,226 INFO org.apache.hadoop.yarn.server.resourcemanager.recovery.LeveldbRMStateStore: Full compaction cycle completed in 11 msec
2022-11-26 01:44:12,216 INFO org.apache.hadoop.yarn.server.resourcemanager.recovery.LeveldbRMStateStore: Starting full compaction cycle
2022-11-26 01:44:12,237 INFO org.apache.hadoop.yarn.server.resourcemanager.recovery.LeveldbRMStateStore: Full compaction cycle completed in 21 msec
2022-11-26 02:44:12,216 INFO org.apache.hadoop.yarn.server.resourcemanager.recovery.LeveldbRMStateStore: Starting full compaction cycle
2022-11-26 02:44:12,221 INFO org.apache.hadoop.yarn.server.resourcemanager.recovery.LeveldbRMStateStore: Full compaction cycle completed in 5 msec
2022-11-26 03:44:12,216 INFO org.apache.hadoop.yarn.server.resourcemanager.recovery.LeveldbRMStateStore: Starting full compaction cycle
2022-11-26 03:44:12,233 INFO org.apache.hadoop.yarn.server.resourcemanager.recovery.LeveldbRMStateStore: Full compaction cycle completed in 17 msec
2022-11-26 04:44:12,216 INFO org.apache.hadoop.yarn.server.resourcemanager.recovery.LeveldbRMStateStore: Starting full compaction cycle
2022-11-26 04:44:12,219 INFO org.apache.hadoop.yarn.server.resourcemanager.recovery.LeveldbRMStateStore: Full compaction cycle completed in 3 msec
2022-11-26 05:44:12,216 INFO org.apache.hadoop.yarn.server.resourcemanager.recovery.LeveldbRMStateStore: Starting full compaction cycle
2022-11-26 05:44:12,226 INFO org.apache.hadoop.yarn.server.resourcemanager.recovery.LeveldbRMStateStore: Full compaction cycle completed in 10 msec
2022-11-26 06:44:12,216 INFO org.apache.hadoop.yarn.server.resourcemanager.recovery.LeveldbRMStateStore: Starting full compaction cycle
2022-11-26 06:44:12,220 INFO org.apache.hadoop.yarn.server.resourcemanager.recovery.LeveldbRMStateStore: Full compaction cycle completed in 4 msec
2022-11-26 06:44:12,228 INFO org.apache.hadoop.yarn.server.resourcemanager.security.NMTokenSecretManagerInRM: Rolling master-key for nm-tokens
2022-11-26 06:44:12,228 INFO org.apache.hadoop.yarn.server.resourcemanager.security.RMContainerTokenSecretManager: Rolling master-key for container-tokens
2022-11-26 06:44:12,228 INFO org.apache.hadoop.yarn.server.resourcemanager.security.AMRMTokenSecretManager: Rolling master-key for amrm-tokens
2022-11-26 06:44:12,228 INFO org.apache.hadoop.yarn.server.resourcemanager.recovery.RMStateStore: Updating AMRMToken
2022-11-26 06:44:12,228 INFO org.apache.hadoop.yarn.server.resourcemanager.security.RMContainerTokenSecretManager: Going to activate master-key with key-id 702718029 in 900000ms
2022-11-26 06:44:12,228 INFO org.apache.hadoop.yarn.server.resourcemanager.security.NMTokenSecretManagerInRM: Going to activate master-key with key-id -1724748002 in 900000ms
2022-11-26 06:44:15,806 INFO org.apache.hadoop.security.token.delegation.AbstractDelegationTokenSecretManager: Updating the current master key for generating delegation tokens
2022-11-26 06:44:16,970 INFO org.apache.hadoop.security.token.delegation.AbstractDelegationTokenSecretManager: Updating the current master key for generating delegation tokens
2022-11-26 06:44:16,970 INFO org.apache.hadoop.yarn.server.resourcemanager.security.RMDelegationTokenSecretManager: storing master key with keyID 4
2022-11-26 06:44:16,970 INFO org.apache.hadoop.yarn.server.resourcemanager.recovery.RMStateStore: Storing RMDTMasterKey.
2022-11-26 06:59:12,228 INFO org.apache.hadoop.yarn.server.resourcemanager.security.NMTokenSecretManagerInRM: Activating next master key with id: -1724748002
2022-11-26 06:59:12,228 INFO org.apache.hadoop.yarn.server.resourcemanager.security.RMContainerTokenSecretManager: Activating next master key with id: 702718029
2022-11-26 06:59:12,229 INFO org.apache.hadoop.yarn.server.resourcemanager.security.AMRMTokenSecretManager: Activating next master key with id: 2079740289
2022-11-26 06:59:12,229 INFO org.apache.hadoop.yarn.server.resourcemanager.recovery.RMStateStore: Updating AMRMToken
2022-11-26 07:44:12,216 INFO org.apache.hadoop.yarn.server.resourcemanager.recovery.LeveldbRMStateStore: Starting full compaction cycle
2022-11-26 07:44:12,237 INFO org.apache.hadoop.yarn.server.resourcemanager.recovery.LeveldbRMStateStore: Full compaction cycle completed in 21 msec
2022-11-26 08:44:12,216 INFO org.apache.hadoop.yarn.server.resourcemanager.recovery.LeveldbRMStateStore: Starting full compaction cycle
2022-11-26 08:44:12,247 INFO org.apache.hadoop.yarn.server.resourcemanager.recovery.LeveldbRMStateStore: Full compaction cycle completed in 31 msec
2022-11-26 09:44:12,216 INFO org.apache.hadoop.yarn.server.resourcemanager.recovery.LeveldbRMStateStore: Starting full compaction cycle
2022-11-26 09:44:12,222 INFO org.apache.hadoop.yarn.server.resourcemanager.recovery.LeveldbRMStateStore: Full compaction cycle completed in 6 msec
2022-11-26 10:44:12,216 INFO org.apache.hadoop.yarn.server.resourcemanager.recovery.LeveldbRMStateStore: Starting full compaction cycle
2022-11-26 10:44:12,223 INFO org.apache.hadoop.yarn.server.resourcemanager.recovery.LeveldbRMStateStore: Full compaction cycle completed in 7 msec
2022-11-26 11:44:12,216 INFO org.apache.hadoop.yarn.server.resourcemanager.recovery.LeveldbRMStateStore: Starting full compaction cycle
2022-11-26 11:44:12,240 INFO org.apache.hadoop.yarn.server.resourcemanager.recovery.LeveldbRMStateStore: Full compaction cycle completed in 24 msec
2022-11-26 12:44:12,216 INFO org.apache.hadoop.yarn.server.resourcemanager.recovery.LeveldbRMStateStore: Starting full compaction cycle
2022-11-26 12:44:12,256 INFO org.apache.hadoop.yarn.server.resourcemanager.recovery.LeveldbRMStateStore: Full compaction cycle completed in 40 msec
2022-11-26 13:44:12,216 INFO org.apache.hadoop.yarn.server.resourcemanager.recovery.LeveldbRMStateStore: Starting full compaction cycle
2022-11-26 13:44:12,235 INFO org.apache.hadoop.yarn.server.resourcemanager.recovery.LeveldbRMStateStore: Full compaction cycle completed in 19 msec
2022-11-26 14:44:12,216 INFO org.apache.hadoop.yarn.server.resourcemanager.recovery.LeveldbRMStateStore: Starting full compaction cycle
2022-11-26 14:44:12,222 INFO org.apache.hadoop.yarn.server.resourcemanager.recovery.LeveldbRMStateStore: Full compaction cycle completed in 6 msec
2022-11-26 15:44:12,216 INFO org.apache.hadoop.yarn.server.resourcemanager.recovery.LeveldbRMStateStore: Starting full compaction cycle
2022-11-26 15:44:12,221 INFO org.apache.hadoop.yarn.server.resourcemanager.recovery.LeveldbRMStateStore: Full compaction cycle completed in 5 msec
2022-11-26 16:44:12,216 INFO org.apache.hadoop.yarn.server.resourcemanager.recovery.LeveldbRMStateStore: Starting full compaction cycle
2022-11-26 16:44:12,224 INFO org.apache.hadoop.yarn.server.resourcemanager.recovery.LeveldbRMStateStore: Full compaction cycle completed in 8 msec
2022-11-26 17:44:12,216 INFO org.apache.hadoop.yarn.server.resourcemanager.recovery.LeveldbRMStateStore: Starting full compaction cycle
2022-11-26 17:44:12,233 INFO org.apache.hadoop.yarn.server.resourcemanager.recovery.LeveldbRMStateStore: Full compaction cycle completed in 17 msec
2022-11-26 18:44:12,216 INFO org.apache.hadoop.yarn.server.resourcemanager.recovery.LeveldbRMStateStore: Starting full compaction cycle
2022-11-26 18:44:12,221 INFO org.apache.hadoop.yarn.server.resourcemanager.recovery.LeveldbRMStateStore: Full compaction cycle completed in 5 msec
2022-11-26 19:44:12,216 INFO org.apache.hadoop.yarn.server.resourcemanager.recovery.LeveldbRMStateStore: Starting full compaction cycle
2022-11-26 19:44:12,227 INFO org.apache.hadoop.yarn.server.resourcemanager.recovery.LeveldbRMStateStore: Full compaction cycle completed in 11 msec
2022-11-26 20:44:12,216 INFO org.apache.hadoop.yarn.server.resourcemanager.recovery.LeveldbRMStateStore: Starting full compaction cycle
2022-11-26 20:44:12,220 INFO org.apache.hadoop.yarn.server.resourcemanager.recovery.LeveldbRMStateStore: Full compaction cycle completed in 4 msec
2022-11-26 21:44:12,216 INFO org.apache.hadoop.yarn.server.resourcemanager.recovery.LeveldbRMStateStore: Starting full compaction cycle
2022-11-26 21:44:12,221 INFO org.apache.hadoop.yarn.server.resourcemanager.recovery.LeveldbRMStateStore: Full compaction cycle completed in 5 msec
2022-11-26 22:44:12,216 INFO org.apache.hadoop.yarn.server.resourcemanager.recovery.LeveldbRMStateStore: Starting full compaction cycle
2022-11-26 22:44:12,228 INFO org.apache.hadoop.yarn.server.resourcemanager.recovery.LeveldbRMStateStore: Full compaction cycle completed in 11 msec
2022-11-26 23:44:12,216 INFO org.apache.hadoop.yarn.server.resourcemanager.recovery.LeveldbRMStateStore: Starting full compaction cycle
2022-11-26 23:44:12,224 INFO org.apache.hadoop.yarn.server.resourcemanager.recovery.LeveldbRMStateStore: Full compaction cycle completed in 8 msec
2022-11-27 00:44:12,216 INFO org.apache.hadoop.yarn.server.resourcemanager.recovery.LeveldbRMStateStore: Starting full compaction cycle
2022-11-27 00:44:12,243 INFO org.apache.hadoop.yarn.server.resourcemanager.recovery.LeveldbRMStateStore: Full compaction cycle completed in 26 msec
2022-11-27 01:44:12,216 INFO org.apache.hadoop.yarn.server.resourcemanager.recovery.LeveldbRMStateStore: Starting full compaction cycle
2022-11-27 01:44:12,223 INFO org.apache.hadoop.yarn.server.resourcemanager.recovery.LeveldbRMStateStore: Full compaction cycle completed in 7 msec
2022-11-27 02:44:12,216 INFO org.apache.hadoop.yarn.server.resourcemanager.recovery.LeveldbRMStateStore: Starting full compaction cycle
2022-11-27 02:44:12,225 INFO org.apache.hadoop.yarn.server.resourcemanager.recovery.LeveldbRMStateStore: Full compaction cycle completed in 9 msec
2022-11-27 03:44:12,216 INFO org.apache.hadoop.yarn.server.resourcemanager.recovery.LeveldbRMStateStore: Starting full compaction cycle
2022-11-27 03:44:12,221 INFO org.apache.hadoop.yarn.server.resourcemanager.recovery.LeveldbRMStateStore: Full compaction cycle completed in 5 msec
2022-11-27 04:44:12,216 INFO org.apache.hadoop.yarn.server.resourcemanager.recovery.LeveldbRMStateStore: Starting full compaction cycle
2022-11-27 04:44:12,225 INFO org.apache.hadoop.yarn.server.resourcemanager.recovery.LeveldbRMStateStore: Full compaction cycle completed in 9 msec
2022-11-27 05:44:12,216 INFO org.apache.hadoop.yarn.server.resourcemanager.recovery.LeveldbRMStateStore: Starting full compaction cycle
2022-11-27 05:44:12,229 INFO org.apache.hadoop.yarn.server.resourcemanager.recovery.LeveldbRMStateStore: Full compaction cycle completed in 13 msec
2022-11-27 06:44:12,216 INFO org.apache.hadoop.yarn.server.resourcemanager.recovery.LeveldbRMStateStore: Starting full compaction cycle
2022-11-27 06:44:12,221 INFO org.apache.hadoop.yarn.server.resourcemanager.recovery.LeveldbRMStateStore: Full compaction cycle completed in 5 msec
2022-11-27 06:44:12,228 INFO org.apache.hadoop.yarn.server.resourcemanager.security.NMTokenSecretManagerInRM: Rolling master-key for nm-tokens
2022-11-27 06:44:12,228 INFO org.apache.hadoop.yarn.server.resourcemanager.security.RMContainerTokenSecretManager: Rolling master-key for container-tokens
2022-11-27 06:44:12,228 INFO org.apache.hadoop.yarn.server.resourcemanager.security.NMTokenSecretManagerInRM: Going to activate master-key with key-id -1724748001 in 900000ms
2022-11-27 06:44:12,228 INFO org.apache.hadoop.yarn.server.resourcemanager.security.RMContainerTokenSecretManager: Going to activate master-key with key-id 702718030 in 900000ms
2022-11-27 06:44:12,228 INFO org.apache.hadoop.yarn.server.resourcemanager.security.AMRMTokenSecretManager: Rolling master-key for amrm-tokens
2022-11-27 06:44:12,228 INFO org.apache.hadoop.yarn.server.resourcemanager.recovery.RMStateStore: Updating AMRMToken
2022-11-27 06:44:18,216 INFO org.apache.hadoop.security.token.delegation.AbstractDelegationTokenSecretManager: Updating the current master key for generating delegation tokens
2022-11-27 06:44:19,256 INFO org.apache.hadoop.security.token.delegation.AbstractDelegationTokenSecretManager: Updating the current master key for generating delegation tokens
2022-11-27 06:44:19,257 INFO org.apache.hadoop.yarn.server.resourcemanager.security.RMDelegationTokenSecretManager: storing master key with keyID 5
2022-11-27 06:44:19,257 INFO org.apache.hadoop.yarn.server.resourcemanager.recovery.RMStateStore: Storing RMDTMasterKey.
2022-11-27 06:59:12,228 INFO org.apache.hadoop.yarn.server.resourcemanager.security.NMTokenSecretManagerInRM: Activating next master key with id: -1724748001
2022-11-27 06:59:12,228 INFO org.apache.hadoop.yarn.server.resourcemanager.security.RMContainerTokenSecretManager: Activating next master key with id: 702718030
2022-11-27 06:59:12,228 INFO org.apache.hadoop.yarn.server.resourcemanager.security.AMRMTokenSecretManager: Activating next master key with id: 2079740290
2022-11-27 06:59:12,228 INFO org.apache.hadoop.yarn.server.resourcemanager.recovery.RMStateStore: Updating AMRMToken
2022-11-27 07:44:12,216 INFO org.apache.hadoop.yarn.server.resourcemanager.recovery.LeveldbRMStateStore: Starting full compaction cycle
2022-11-27 07:44:12,238 INFO org.apache.hadoop.yarn.server.resourcemanager.recovery.LeveldbRMStateStore: Full compaction cycle completed in 22 msec
2022-11-27 08:44:12,216 INFO org.apache.hadoop.yarn.server.resourcemanager.recovery.LeveldbRMStateStore: Starting full compaction cycle
2022-11-27 08:44:12,239 INFO org.apache.hadoop.yarn.server.resourcemanager.recovery.LeveldbRMStateStore: Full compaction cycle completed in 23 msec
2022-11-27 09:44:12,217 INFO org.apache.hadoop.yarn.server.resourcemanager.recovery.LeveldbRMStateStore: Starting full compaction cycle
2022-11-27 09:44:12,222 INFO org.apache.hadoop.yarn.server.resourcemanager.recovery.LeveldbRMStateStore: Full compaction cycle completed in 5 msec
2022-11-27 10:44:12,217 INFO org.apache.hadoop.yarn.server.resourcemanager.recovery.LeveldbRMStateStore: Starting full compaction cycle
2022-11-27 10:44:12,222 INFO org.apache.hadoop.yarn.server.resourcemanager.recovery.LeveldbRMStateStore: Full compaction cycle completed in 5 msec
